Workbook

Sheet 동진쌤_프로필
B2: 안녕하세요? 메루치 양식장 합정점 이동진입니다!🧑‍🌾
B4: "즐거운 운동이 삶의 질을 향상시킨다!"
B6: 📌이동진 트레이너 | C6: 트쌤소개🙋‍♂️ | D6: 경력사항🚩 | E6: 트쌤일지란?🧐
C7: 안녕하세요! 메루치 양식장 이동진입니다👨‍🌾 건강한 삶을 위해 운동을 시작하고 싶으신가요?🤔 하지만 어떤 트레이너를 선택해야 할지 고민이시죠? 혼자서 운동을 시작하기에는 막막하고, 그렇다고 아무에게나 PT를 등록할 수도 없으시죠? 트레이너의 유혹에 넘어가 무작정 PT를 등록하지 마세요!🙅‍♂️ 자신에게 맞는 트레이너인지, 원하는 목표를 확실하게 달성할 수 있는 트레이너인지 신중히 선택하는 것이 굉장히 중요합니다. 저는 운동을 정말 좋아하여 다니던 대기업을 그만두고 체육학 전공을 공부 중이며, 다양한 전문 자격증을 취득하였습니다.🏋️‍♀️ 제가 즐겁게 해온 운동을 회원님께 전달하고자 하며, 단순한 운동 지도가 아닌, 회원님의 전반적인 건강과 삶의 질을 향상시키는 것을 목표로 하고 있습니다.💪 1:1 개인 맞춤형 프로그램을 통해 회원님의 목표를 체계적으로 달성하도록 도와드리겠습니다.🔥 | D7: ✅ 피트니스온 서울시청점 마스터코치 ✅ (현) 메루치 양식장 시니어 트레이너 | E7: 트쌤일지는 회원님의 운동 여정에서 그 시작과 끝을 함께할 기록지예요. 1️⃣상담일지: 처음 등록할 때 마음가짐을 기억해요. 2️⃣수업일지: 뿌듯함에 쉽게 포기할 수 없을 거예요. 3️⃣인바디기록: 내 몸의 변화를 그래프로 확인해요. 수업이 다가 아니라, 회원님께서 노력한 과정과 변화를 두 눈으로 확인할 수 있다면 큰 보람을 느끼실 거예요! 저만 믿고 따라오세요.🔥
D16: 자격사항🎓 | E16: 헬짱일지란?😎
D17: ✅ NSCA-CPT 퍼스널트레이너 (미국체력관리학회) ✅ 피트니스 플러스 CFA과정 차석 수료 ✅ SPH EXERCISE BASIC 수료 ✅ 재활트레이닝 전문가과정 레벨1 과정 수료 ✅ 재활트레이닝 전문가과정 레벨 2 과정 수료 ✅ 재활트레이닝 전문가 고급자 자격증 ✅ MPSW 체형 관리 운동 지도자 ✅ 운동처방사 1급 ✅ 생활운동지도사 1급 ✅ 노인운동지도사 1급 ✅ 스포츠컨디셔닝지도사 1급 ✅ 체형관리사 1급 ✅ 헬스트레이너지도사 1급 ✅ 스포츠재활처방사 1급 ✅ 스포츠안전지도사 ✅ 2024 K-Classic 클래식 보디빌딩 3위 | E17: 헬짱일지는 웨이트 트레이닝 원리를 반영한 체계적인 운동일지 양식이에요! 우리 몸은 이전보다 강한 자극이 주어질 때 발달합니다. 따라서 원하는 몸을 만들기 위해서는 운동강도를 점차 높여가야 하는데, 기록을 하지 않으면 객관적이고 확실한 변화를 만들어내기 어렵습니다. 특히 체지방 감소와 근육량 증가를 위해서는 운동과 식단을 병행해야 하는데, ①'자극-회복-성장'이라는 근성장 원리에 따라 무게와 횟수를 점진적으로 늘리고, ②탄/단/지 영양소를 균형있게 섭취하는 것 또한 매우 중요합니다. 전체 칼로리 뿐만 아니라 내가 먹는 음식이 어떤 영양소로 이루어졌는지 인식할 필요가 있어요. 회원님께서 나만의 운동루틴을 만들고 건강한 식단에 적응하실 수 있도록 제가 기록을 도와드릴게요!
B31: 수업후기
B32: 20대 남성 회원님 실제후기👩 | C32: 20대 남성 회원님 실제후기👧 | D32: 30대 여성 회원님 실제후기👩‍🦰 | E32: 40대 남성 회원님 실제후기🧑

Sheet 월간 보고서
A1: OOO 1월 월간 보고서 | J1: 신체 변화
J4: 체중 | N4: 체지방률 | R4: 근육량
A5: 주요 변화 및 성장 포인트
A8: Before | E8: After
A10: ➀ | E10: ➡
A11: ➁ | E11: ➡
A12: ➂ | E12: ➡
A13: ➃ | E13: ➡
A14: ➄ | E14: ➡
A15: 성장 데이터 (숫자만 기입 해주세요)
A18: 변화 항목 | B18: 시작 전 | C18: 1달차 | E18: 2달차 | G18: 3달차 | J18: 운동 퍼포먼스
A20: 체중 | B20: ='상태 분석 및 목표치 설정'!H2 -> 71.3 | C20: 75.4 | E20: 75.9 | G20: 76.9
J21: 푸쉬업 | N21: 스쿼트 | R21: 랫풀다운
A22: 체지방률 | B22: ='상태 분석 및 목표치 설정'!F8 -> 18.6 | C22: 19.3 | E22: 19.7 | G22: 18.4
A24: 근육량 | B24: 32.6 | C24: 34.3 | E24: 34.4 | G24: 35.4
A26: 푸쉬업 (횟수)
A28: 스쿼트 (10RM)
A30: 랫풀다운 (10RM)
A32: 가슴 둘레 | B32: ='상태 분석 및 목표치 설정'!A36 -> 88 | C32: 91 | E32: 94 | G32: 96
A34: 어깨 너비 | B34: ='상태 분석 및 목표치 설정'!B36 -> 44 | C34: 45 | E34: 45.5 | G34: 46
A36: 상완 둘레 | B36: ='상태 분석 및 목표치 설정'!E36 -> 32 | C36: 33 | E36: 33.5 | G36: 33.5
A38: 허벅지 둘레 | B38: ='상태 분석 및 목표치 설정'!G36 -> 48 | C38: 51 | E38: 53 | G38: 54
J39: 부위별 변화
A40: 섭취 칼로리 | B40: ='식이 분석 및 가이드'!K51 -> 2000
A42: 운동횟수 | J42: 엉덩이 둘레 | M42: 어깨 너비 | P42: 상완 둘레 | S42: 허벅지 둘레
A44: 코칭 코멘트
A46: (회원님 운동 사진 첨부)
J59: 기타 변화
J62: 섭취 칼로리 | P62: 운동 횟수
A63: 다음 달 목표
A65: ✅
A66: ✅
A67: ✅
A68: ✅
A69: ✅
A84: OOO 2월 월간 보고서
A88: 주요 변화 및 성장 포인트
A91: Before | E91: After
A93: ➀ | E93: ➡
A94: ➁ | E94: ➡
...

Sheet 26.05 월간보고서
A1: OOO 1월 월간 보고서 | J1: 신체 변화
J4: 체중 | N4: 체지방률 | R4: 근육량
A5: 주요 변화 및 성장 포인트
A8: Before | E8: After
A10: ➀ | E10: ➡
A11: ➁ | E11: ➡
A12: ➂ | E12: ➡
A13: ➃ | E13: ➡
A14: ➄ | E14: ➡
A15: 성장 데이터 (숫자만 기입 해주세요)
A18: 변화 항목 | B18: 시작 전 | C18: 1달차 | E18: 2달차 | G18: 3달차 | J18: 운동 퍼포먼스
A20: 체중 | B20: ='상태 분석 및 목표치 설정'!H2 -> 71.3 | C20: 75.4 | E20: 76.5 | G20: 74.9
J21: 푸쉬업 | N21: 스쿼트 | R21: 랫풀다운
A22: 체지방률 | B22: ='상태 분석 및 목표치 설정'!F8 -> 18.6 | C22: 19.3 | E22: 0.184 | G22: 0.172
A24: 근육량 | B24: 32.6 | C24: 34.3 | E24: 35.3 | G24: 35.1
A26: 푸쉬업 (횟수)
A28: 스쿼트 (10RM)
A30: 랫풀다운 (10RM)
A32: 가슴 둘레 | B32: ='상태 분석 및 목표치 설정'!A36 -> 88 | C32: 91 | E32: 96 | G32: 96.5
A34: 어깨 너비 | B34: ='상태 분석 및 목표치 설정'!B36 -> 44 | C34: 47 | E34: 47 | G34: 47.5
A36: 상완 둘레 | B36: ='상태 분석 및 목표치 설정'!E36 -> 32 | C36: 34 | E36: 35 | G36: 35
A38: 허벅지 둘레 | B38: ='상태 분석 및 목표치 설정'!G36 -> 48 | C38: 54 | E38: 54 | G38: 54
J39: 부위별 변화
A40: 섭취 칼로리 | B40: ='식이 분석 및 가이드'!K51 -> 2000
A42: 운동횟수 | J42: 가슴 둘레 | M42: 어깨 너비 | P42: 상완 둘레 | S42: 허벅지 둘레
A44: 코칭 코멘트
A46: (회원님 운동 사진 첨부)
J59: 기타 변화
J62: 섭취 칼로리 | P62: 운동 횟수
A63: 다음 달 목표
A65: ✅
A66: ✅
A67: ✅
A68: ✅
A69: ✅
A84: OOO 2월 월간 보고서
A88: 주요 변화 및 성장 포인트
A91: Before | E91: After
A93: ➀ | E93: ➡
A94: ➁ | E94: ➡
...

Sheet 상태 분석 및 목표치 설정
E1: 이름 | G1: 키 | H1: 체중
E2: 김훈 | G2: 178 | H2: 71.3
E4: 직업군 | G4: 나이 | H4: 수면 시간
E5: 직장인 | G5: 만39 | H5: 6
E7: BMI | F7: 체지방률 | G7: 타입
E8: =IFERROR(ROUND(H2 / (G2/100)^2, 2), "") -> 22.5 | F8: 18.6
E10: 최고 체중(성인 이후) | G10: 최저 체중(성인 이후)
E11: 75 | G11: 62
E13: 운동경력
E14: 헬스장 PT 3개월 (1RM 기준 벤치 80kg, 데드 160kg, 스쿼트 120kg) * 25년 8월 정도 까지 운동량을 꽤 늘렸었고, 9월부터 업무와 어깨 통증으로 운동 볼륨 및 횟수가 많이 줄었습니다.
E17: 특이사항 및 병력
E18: 왼쪽어깨충돌증후군
E21: 섭취중인 영양제 및 복용중인 약물
E22: 비타민B,C, 오메가3, 마그네슘
E25: 운동 목적 및 방향
E26: 벌크업 | F26: FALSE | G26: 백호
E28: 린매스업 | F28: TRUE
E30: 커팅 | F30: FALSE
E32: 목표 체중(kg) | G32: 목표 주당 증량 체중(g)
E33: 76 | G33: =IF((E33-H2)=0, "", (E33-H2)/12*1000) -> 391.66667
A35: 가슴 둘레 | B35: 어깨 너비 | C35: 손목 둘레 | D35: 발목 둘레 | E35: 상완 둘레 | G35: 허벅지 둘레
A36: 88 | B36: 44 | E36: 32 | G36: 48
A38: 예상 상완 둘레(최대치) | C38: 예상 허벅지 둘레(최대치) | E38: 예상 전완 둘레(최대치)
A39: =1.2033*C36+0.1236*G2 -> 22.0008 | C39: =1.3868*D36+0.1805*G2 -> 32.129 | E39: =0.9626*C36+ 0.0989*G2 -> 17.6042
A42: 코칭에 꼭 반영되었으면 하는 점
A43: 예시) 운동 동작 코칭 시 디테일 하게 설명 부탁드립니다.

Sheet 식이 분석 및 가이드
B1: 섭취 음식 | D1: 칼로리
A2: 아침 | B2: 시간 : 0700 | D2: 400
B3: 빈도 : 주 5회 | H3: 메루치양식장
B4: 에그 샌드위치 | C4: 400
F10: 참고 및 주의사항
F11: 1. 칼로리가 높은 음식 위주로 카운팅 한다(밥, 육류, 튀김 등)
F12: 2. 즉, 칼로리가 매우 낮은 음식(김치, 나물, 채소 등)은 카운팅 하지 않는다
F13: 3. 식이기록을 진행한다고 해서, 더 먹거나 덜 먹지 않는다
A14: 점심 | B14: 시간 : 1200 | D14: 700 | F14: 4. 즉, 평소 식이대로 먹는다
B15: 빈도 : 매일 | F15: 간식/야식의 정의
B16: 백반(급식) | F16: 간식 | G16: 아침, 점심, 저녁 사이에 섭취하는 모든 음식
F17: 야식 | G17: 저녁 이후에 먹는 모든 음식
B18: 밥 1공기 + 육류 1주먹 | C18: 700 | G18: 술 또는 술자리 음식은 모두 여기에 카운팅
A26: 저녁 | B26: 시간 : 1900~2000 | D26: 750
B27: 빈도 : 매일
B28: 집밥
B30: 밥 1공기 + 육류 1주먹 | C30: 700
B32: 배달음식(여러 종류) | C32: 800
A38: 간식 | B38: 시간 : 1600 | D38: =350/7*3 -> 150
B39: 빈도 : 주 3회
B40: 단백질 1개 + 두유 | C40: 350 | F40: 식사를 얼마나 균등하고 있는지 나타내는 표
F43: 유형 | G43: 형태 | L43: 문제
F44: 폭식형 | G44: 한 끼니에 칼로리가 치중 되어 있음 | L44: 체지방 증가, 폭식으로 인한 다음 끼니 거름
F45: 아점형 | G45: 아침을 거르고 점심으로 때움 | L45: 1끼니의 칼로리(약 500-800)를 버리는 셈
F46: 1일 1식 | G46: 하루에 1끼니만 먹음 | L46: 칼로리 충당 힘듦, 폭식 가능성
F47: 야식형 | G47: 야식 칼로리 높음, 밤 늦게 끼니를 해결함 | L47: 취짐 전 섭취로 체지방 증가, 포만감 지속으로 아침 거름
A48: 야식 | B48: 시간 :
B49: 빈도 :
F50: 타이밍 | G50: 평균 칼로리 | I50: 신뢰도 높은 측정이 마무리 되어야 정확한 값이 나옴
F51: 아침 | G51: =D2 -> 400 | I51: 1일 소비열량 | K51: =D48+D38+D26+D14+D2 -> 2000
F52: 점심 | G52: =D14 -> 700
F53: 저녁 | G53: =D26 -> 750
F54: 간식 | G54: =D38 -> 150
F55: 야식 | G55: =D48
A59: 기상 시간 | B59: 600
A61: 취침 시간 | B61: 2400~0100 -> 2300~2400
A63: 특이 사항 | B63: 1️⃣
B64: 2️⃣
B65: 3️⃣
B66: 4️⃣
...

Sheet 26.07~체중변화 추이
A1: 날짜 | B1: 섭취칼로리 | C1: 체중 | D1: 주당 평균 체중 | E1: 체중 목표치 | F1: 메모
A2: 46204 | C2: 75.2 | D2: =IF(COUNTIF(C2:C8,">0")=0, "", ROUND(AVERAGEIF(C2:C8,">0"), 1)) -> 74.9 | E2: ='상태 분석 및 목표치 설정'!H2 -> 71.3
A3: 46205 | B3: 3165 | C3: 75.2 | E3: =E2 + ($E$92 - $E$2) / 90 -> 71.352222
A4: 46206 | C4: 75.1 | E4: =E3 + ($E$92 - $E$2) / 90 -> 71.404444
A5: 46207 | C5: 74.3 | E5: =E4 + ($E$92 - $E$2) / 90 -> 71.456667
A6: 46208 | C6: 75.1 | E6: =E5 + ($E$92 - $E$2) / 90 -> 71.508889
A7: 46209 | C7: 74.3 | E7: =E6 + ($E$92 - $E$2) / 90 -> 71.561111
A8: 46210 | C8: 75.2 | E8: =E7 + ($E$92 - $E$2) / 90 -> 71.613333 | H8: 목표 섭취 칼로리(kcal)
A9: 46211 | C9: 75.1 | D9: =IF(COUNTIF(C9:C15,">0")=0, "", ROUND(AVERAGEIF(C9:C15,">0"), 1)) -> 74.7 | E9: =E8 + ($E$92 - $E$2) / 90 -> 71.665556 | H9: ='식이 분석 및 가이드'!K100 -> 2383.3333
A10: 46212 | C10: 74.9 | E10: =E9 + ($E$92 - $E$2) / 90 -> 71.717778
A11: 46213 | C11: 74.4 | E11: =E10 + ($E$92 - $E$2) / 90 -> 71.77
A12: 46214 | C12: 74.8 | E12: =E11 + ($E$92 - $E$2) / 90 -> 71.822222
A13: 46215 | C13: 74.8 | E13: =E12 + ($E$92 - $E$2) / 90 -> 71.874444
A14: 46216 | C14: 74.6 | E14: =E13 + ($E$92 - $E$2) / 90 -> 71.926667
A15: 46217 | C15: 74.6 | E15: =E14 + ($E$92 - $E$2) / 90 -> 71.978889
A16: 46218 | C16: 74.6 | D16: =IF(COUNTIF(C16:C22,">0")=0, "", ROUND(AVERAGEIF(C16:C22,">0"), 1)) -> 74.8 | E16: =E15 + ($E$92 - $E$2) / 90 -> 72.031111
A17: 46219 | C17: 74.6 | E17: =E16 + ($E$92 - $E$2) / 90 -> 72.083333
A18: 46220 | C18: 75 | E18: =E17 + ($E$92 - $E$2) / 90 -> 72.135556
A19: 46221 | C19: 74 | E19: =E18 + ($E$92 - $E$2) / 90 -> 72.187778
A20: 46222 | C20: 75.4 | E20: =E19 + ($E$92 - $E$2) / 90 -> 72.24
A21: 46223 | C21: 75.1 | E21: =E20 + ($E$92 - $E$2) / 90 -> 72.292222
A22: 46224 | C22: 75.1 | E22: =E21 + ($E$92 - $E$2) / 90 -> 72.344444
A23: 46225 | C23: 75.3 | D23: =IF(COUNTIF(C23:C29,">0")=0, "", ROUND(AVERAGEIF(C23:C29,">0"), 1)) -> 75.1 | E23: =E22 + ($E$92 - $E$2) / 90 -> 72.396667
A24: 46226 | C24: 74.8 | E24: =E23 + ($E$92 - $E$2) / 90 -> 72.448889
A25: 46227 | E25: =E24 + ($E$92 - $E$2) / 90 -> 72.501111
A26: 46228 | E26: =E25 + ($E$92 - $E$2) / 90 -> 72.553333
A27: 46229 | E27: =E26 + ($E$92 - $E$2) / 90 -> 72.605556
A28: 46230 | E28: =E27 + ($E$92 - $E$2) / 90 -> 72.657778
A29: 46231 | E29: =E28 + ($E$92 - $E$2) / 90 -> 72.71
A30: 46232 | D30: =IF(COUNTIF(C30:C36,">0")=0, "", ROUND(AVERAGEIF(C30:C36,">0"), 1)) | E30: =E29 + ($E$92 - $E$2) / 90 -> 72.762222
A31: 46233 | E31: =E30 + ($E$92 - $E$2) / 90 -> 72.814444
A32: 46234 | E32: =E31 + ($E$92 - $E$2) / 90 -> 72.866667
A33: 46235 | E33: =E32 + ($E$92 - $E$2) / 90 -> 72.918889
A34: 46236 | E34: =E33 + ($E$92 - $E$2) / 90 -> 72.971111
A35: 46237 | E35: =E34 + ($E$92 - $E$2) / 90 -> 73.023333
A36: 46238 | E36: =E35 + ($E$92 - $E$2) / 90 -> 73.075556
A37: 46239 | D37: =IF(COUNTIF(C37:C43,">0")=0, "", ROUND(AVERAGEIF(C37:C43,">0"), 1)) | E37: =E36 + ($E$92 - $E$2) / 90 -> 73.127778
A38: 46240 | E38: =E37 + ($E$92 - $E$2) / 90 -> 73.18
A39: 46241 | E39: =E38 + ($E$92 - $E$2) / 90 -> 73.232222 | H39: <오른쪽 세로축 범위 조정 필요> 오른쪽 세로축 더블클릭 -> 최솟값, 최댓값 수정 최소값 현재 체중 -1kg, 최대값 목표 체중 +1kg로 수정하면 적절
A40: 46242 | E40: =E39 + ($E$92 - $E$2) / 90 -> 73.284444
...

Sheet 26.04~체중변화 추이
A1: 날짜 | B1: 섭취칼로리 | C1: 체중 | D1: 주당 평균 체중 | E1: 체중 목표치 | F1: 메모
A2: 46111 | D2: =IF(COUNTIF(C2:C8,">0")=0, "", ROUND(AVERAGEIF(C2:C8,">0"), 1)) -> 76.3 | E2: ='상태 분석 및 목표치 설정'!H2 -> 71.3
A3: 46112 | E3: =E2 + ($E$92 - $E$2) / 90 -> 71.352222
A4: 46113 | E4: =E3 + ($E$92 - $E$2) / 90 -> 71.404444
A5: 46114 | B5: 2319 | C5: 76.4 | E5: =E4 + ($E$92 - $E$2) / 90 -> 71.456667
A6: 46115 | C6: 76.2 | E6: =E5 + ($E$92 - $E$2) / 90 -> 71.508889
A7: 46116 | E7: =E6 + ($E$92 - $E$2) / 90 -> 71.561111
A8: 46117 | E8: =E7 + ($E$92 - $E$2) / 90 -> 71.613333 | H8: 목표 섭취 칼로리(kcal)
A9: 46118 | D9: =IF(COUNTIF(C9:C15,">0")=0, "", ROUND(AVERAGEIF(C9:C15,">0"), 1)) -> 76.5 | E9: =E8 + ($E$92 - $E$2) / 90 -> 71.665556 | H9: ='식이 분석 및 가이드'!K100 -> 2383.3333
A10: 46119 | B10: 2370 | C10: 76.6 | E10: =E9 + ($E$92 - $E$2) / 90 -> 71.717778
A11: 46120 | B11: 2230 | C11: 76.8 | E11: =E10 + ($E$92 - $E$2) / 90 -> 71.77
A12: 46121 | B12: 2474 | C12: 76.8 | E12: =E11 + ($E$92 - $E$2) / 90 -> 71.822222
A13: 46122 | C13: 76.3 | E13: =E12 + ($E$92 - $E$2) / 90 -> 71.874444
A14: 46123 | C14: 75.9 | E14: =E13 + ($E$92 - $E$2) / 90 -> 71.926667
A15: 46124 | E15: =E14 + ($E$92 - $E$2) / 90 -> 71.978889
A16: 46125 | C16: 75.9 | D16: =IF(COUNTIF(C16:C22,">0")=0, "", ROUND(AVERAGEIF(C16:C22,">0"), 1)) -> 76.7 | E16: =E15 + ($E$92 - $E$2) / 90 -> 72.031111
A17: 46126 | B17: 2301 | C17: 77 | E17: =E16 + ($E$92 - $E$2) / 90 -> 72.083333
A18: 46127 | B18: 1650 | C18: 77.1 | E18: =E17 + ($E$92 - $E$2) / 90 -> 72.135556
A19: 46128 | B19: 2578 | C19: 76.6 | E19: =E18 + ($E$92 - $E$2) / 90 -> 72.187778
A20: 46129 | C20: 76.8 | E20: =E19 + ($E$92 - $E$2) / 90 -> 72.24
A21: 46130 | E21: =E20 + ($E$92 - $E$2) / 90 -> 72.292222
A22: 46131 | E22: =E21 + ($E$92 - $E$2) / 90 -> 72.344444
A23: 46132 | B23: 2418 | D23: =IF(COUNTIF(C23:C29,">0")=0, "", ROUND(AVERAGEIF(C23:C29,">0"), 1)) -> 77 | E23: =E22 + ($E$92 - $E$2) / 90 -> 72.396667
A24: 46133 | C24: 76.8 | E24: =E23 + ($E$92 - $E$2) / 90 -> 72.448889
A25: 46134 | C25: 77.2 | E25: =E24 + ($E$92 - $E$2) / 90 -> 72.501111
A26: 46135 | E26: =E25 + ($E$92 - $E$2) / 90 -> 72.553333
A27: 46136 | E27: =E26 + ($E$92 - $E$2) / 90 -> 72.605556
A28: 46137 | E28: =E27 + ($E$92 - $E$2) / 90 -> 72.657778
A29: 46138 | E29: =E28 + ($E$92 - $E$2) / 90 -> 72.71
A30: 46139 | B30: 2189 | C30: 76 | D30: =IF(COUNTIF(C30:C36,">0")=0, "", ROUND(AVERAGEIF(C30:C36,">0"), 1)) -> 76.3 | E30: =E29 + ($E$92 - $E$2) / 90 -> 72.762222
A31: 46140 | B31: 1769 | C31: 76.1 | E31: =E30 + ($E$92 - $E$2) / 90 -> 72.814444
A32: 46141 | C32: 76.4 | E32: =E31 + ($E$92 - $E$2) / 90 -> 72.866667
A33: 46142 | C33: 76.5 | E33: =E32 + ($E$92 - $E$2) / 90 -> 72.918889
A34: 46143 | E34: =E33 + ($E$92 - $E$2) / 90 -> 72.971111
A35: 46144 | E35: =E34 + ($E$92 - $E$2) / 90 -> 73.023333
A36: 46145 | E36: =E35 + ($E$92 - $E$2) / 90 -> 73.075556
A37: 46146 | D37: =IF(COUNTIF(C37:C43,">0")=0, "", ROUND(AVERAGEIF(C37:C43,">0"), 1)) -> 76.1 | E37: =E36 + ($E$92 - $E$2) / 90 -> 73.127778
A38: 46147 | B38: 1585 | C38: 76.1 | E38: =E37 + ($E$92 - $E$2) / 90 -> 73.18
A39: 46148 | B39: 2100 | C39: 75.6 | E39: =E38 + ($E$92 - $E$2) / 90 -> 73.232222 | H39: <오른쪽 세로축 범위 조정 필요> 오른쪽 세로축 더블클릭 -> 최솟값, 최댓값 수정 최소값 현재 체중 -1kg, 최대값 목표 체중 +1kg로 수정하면 적절
A40: 46149 | B40: 2298 | C40: 76.3 | E40: =E39 + ($E$92 - $E$2) / 90 -> 73.284444
...

Sheet 체중변화 추이
A1: 날짜 | B1: 섭취칼로리 | C1: 체중 | D1: 주당 평균 체중 | E1: 체중 목표치 | F1: 메모
A2: 46020 | C2: 71.3 | D2: =IF(COUNTIF(C2:C8,">0")=0, "", ROUND(AVERAGEIF(C2:C8,">0"), 1)) -> 71.5 | E2: ='상태 분석 및 목표치 설정'!H2 -> 71.3
A3: 46021 | B3: 2153 | C3: 71.7 | E3: =E2 + ($E$92 - $E$2) / 90 -> 71.352222
A4: 46022 | B4: 2718 | C4: 71.7 | E4: =E3 + ($E$92 - $E$2) / 90 -> 71.404444
A5: 46023 | B5: 3095 | C5: 71.8 | E5: =E4 + ($E$92 - $E$2) / 90 -> 71.456667
A6: 46024 | B6: 2144 | C6: 71.3 | E6: =E5 + ($E$92 - $E$2) / 90 -> 71.508889
A7: 46025 | B7: 2869 | C7: 70.7 | E7: =E6 + ($E$92 - $E$2) / 90 -> 71.561111
A8: 46026 | B8: 1192 | C8: 72.3 | E8: =E7 + ($E$92 - $E$2) / 90 -> 71.613333 | H8: 목표 섭취 칼로리(kcal)
A9: 46027 | B9: 2323 | C9: 72.3 | D9: =IF(COUNTIF(C9:C15,">0")=0, "", ROUND(AVERAGEIF(C9:C15,">0"), 1)) -> 72.4 | E9: =E8 + ($E$92 - $E$2) / 90 -> 71.665556 | H9: ='식이 분석 및 가이드'!K100 -> 2383.3333
A10: 46028 | B10: 2346 | C10: 72.4 | E10: =E9 + ($E$92 - $E$2) / 90 -> 71.717778
A11: 46029 | B11: 2646 | C11: 73 | E11: =E10 + ($E$92 - $E$2) / 90 -> 71.77
A12: 46030 | B12: 1518 | C12: 72.5 | E12: =E11 + ($E$92 - $E$2) / 90 -> 71.822222
A13: 46031 | B13: 2744 | C13: 72.4 | E13: =E12 + ($E$92 - $E$2) / 90 -> 71.874444
A14: 46032 | B14: 2323 | C14: 72.4 | E14: =E13 + ($E$92 - $E$2) / 90 -> 71.926667
A15: 46033 | B15: 2340 | C15: 72.1 | E15: =E14 + ($E$92 - $E$2) / 90 -> 71.978889
A16: 46034 | C16: 72.5 | D16: =IF(COUNTIF(C16:C22,">0")=0, "", ROUND(AVERAGEIF(C16:C22,">0"), 1)) -> 72.6 | E16: =E15 + ($E$92 - $E$2) / 90 -> 72.031111
A17: 46035 | B17: 2486 | C17: 72.3 | E17: =E16 + ($E$92 - $E$2) / 90 -> 72.083333
A18: 46036 | B18: 2208 | C18: 72.7 | E18: =E17 + ($E$92 - $E$2) / 90 -> 72.135556
A19: 46037 | B19: 2129 | C19: 72.8 | E19: =E18 + ($E$92 - $E$2) / 90 -> 72.187778
A20: 46038 | B20: 2431 | C20: 72.4 | E20: =E19 + ($E$92 - $E$2) / 90 -> 72.24
A21: 46039 | C21: 73 | E21: =E20 + ($E$92 - $E$2) / 90 -> 72.292222
A22: 46040 | C22: 72.6 | E22: =E21 + ($E$92 - $E$2) / 90 -> 72.344444
A23: 46041 | B23: 3165 | C23: 73 | D23: =IF(COUNTIF(C23:C29,">0")=0, "", ROUND(AVERAGEIF(C23:C29,">0"), 1)) -> 73.1 | E23: =E22 + ($E$92 - $E$2) / 90 -> 72.396667
A24: 46042 | B24: 2638 | C24: 73.5 | E24: =E23 + ($E$92 - $E$2) / 90 -> 72.448889
A25: 46043 | B25: 1893 | C25: 72.8 | E25: =E24 + ($E$92 - $E$2) / 90 -> 72.501111
A26: 46044 | B26: 2345 | C26: 72.8 | E26: =E25 + ($E$92 - $E$2) / 90 -> 72.553333
A27: 46045 | C27: 73.3 | E27: =E26 + ($E$92 - $E$2) / 90 -> 72.605556
A28: 46046 | C28: 73.1 | E28: =E27 + ($E$92 - $E$2) / 90 -> 72.657778
A29: 46047 | C29: 73 | E29: =E28 + ($E$92 - $E$2) / 90 -> 72.71
A30: 46048 | B30: 2076 | C30: 73 | D30: =IF(COUNTIF(C30:C36,">0")=0, "", ROUND(AVERAGEIF(C30:C36,">0"), 1)) -> 73.6 | E30: =E29 + ($E$92 - $E$2) / 90 -> 72.762222
A31: 46049 | B31: 2438 | C31: 73.5 | E31: =E30 + ($E$92 - $E$2) / 90 -> 72.814444
A32: 46050 | B32: 2657 | C32: 73.3 | E32: =E31 + ($E$92 - $E$2) / 90 -> 72.866667
A33: 46051 | B33: 3033 | C33: 73.4 | E33: =E32 + ($E$92 - $E$2) / 90 -> 72.918889
A34: 46052 | C34: 73.4 | E34: =E33 + ($E$92 - $E$2) / 90 -> 72.971111
A35: 46053 | C35: 74.4 | E35: =E34 + ($E$92 - $E$2) / 90 -> 73.023333
A36: 46054 | C36: 74.2 | E36: =E35 + ($E$92 - $E$2) / 90 -> 73.075556
A37: 46055 | B37: 2443 | C37: 74.5 | D37: =IF(COUNTIF(C37:C43,">0")=0, "", ROUND(AVERAGEIF(C37:C43,">0"), 1)) -> 74.5 | E37: =E36 + ($E$92 - $E$2) / 90 -> 73.127778
A38: 46056 | B38: 2479 | C38: 74.8 | E38: =E37 + ($E$92 - $E$2) / 90 -> 73.18
A39: 46057 | B39: 2333 | C39: 74.4 | E39: =E38 + ($E$92 - $E$2) / 90 -> 73.232222 | H39: <오른쪽 세로축 범위 조정 필요> 오른쪽 세로축 더블클릭 -> 최솟값, 최댓값 수정 최소값 현재 체중 -1kg, 최대값 목표 체중 +1kg로 수정하면 적절
A40: 46058 | B40: 2129 | C40: 74.5 | E40: =E39 + ($E$92 - $E$2) / 90 -> 73.284444
...

Sheet TEST
A1: 테스트 날짜 | C1: 46022 | D1: TEST 프로그램 | J1: 솔루션
A2: 운동명 | C2: 세트 | D2: 중량(kg) | E2: 성공 횟수 | F2: 평균 횟수 | G2: RPE | H2: 문제점
A3: 벤치 | C3: 3세트 실패 지점 까지 진행 | F3: =(E5+E6+E7)/3 -> 8.6666667 | H3: 그립 너비 | I3: FALSE
H4: 척추 중립 | I4: FALSE | J4: 고관절 굴곡근 강화 훈련(레그레이즈, 플랭크)
C5: 1 | D5: 50 | E5: 10 | H5: 어깨 위치 | I5: FALSE | J5: 익상증후군 : 푸쉬업 플러스, 윌 슬라이드 | K5: 라운드 숄더 : 견갑골 후인근 강화/소흉근 스트레칭, 와이레이즈
C6: 2 | E6: 8 | H6: 가동범위 | I6: FALSE
C7: 3 | E7: 8 | H7: 속도 | I7: FALSE | J7: 속도 카운팅
A8: 메모
A10: 풀업 | C10: 3세트 실패 지점 까지 진행 | F10: =(E12+E13+E14)/3 -> 4.3333333 | H10: 그립 너비 | I10: FALSE
H11: 척추 중립 | I11: FALSE | J11: 고관절 굴곡근 강화 훈련(레그레이즈, 플랭크)
C12: 1 | D12: 0 | E12: 5 | H12: 팔꿈치 | I12: FALSE | J12: 팔
C13: 2 | E13: 5 | H13: 어깨 말림 | I13: FALSE | J13: 익상증후군, 라운드 숄더 교정
C14: 3 | E14: 3 | H14: 속도 | I14: FALSE | J14: 속도 카운팅
A15: 메모
A17: 스쿼트 | C17: 3세트 실패 지점 까지 진행 | F17: =(E19+E20+E21)/3 -> 7.6666667 | H17: 발 너비 | I17: FALSE
H18: 무릎 방향 | I18: FALSE | J18: 외반슬 : 내로우 스쿼트, 중둔근 강화 훈련
C19: 1 | D19: 80 | E19: 8 | H19: 무게 중심 | I19: FALSE | J19: 발 앞쪽 : 힙힌지 훈련, 발 뒤쪽 : 종아리 스트레칭, 역도화 활용
C20: 2 | E20: 8 | H20: 유연성(벗윙크) | I20: FALSE | J20: 내전근/장요근 스트레칭 (2:28 ~4:45) | K20: 척추기립근 강화 훈련
C21: 3 | E21: 7 | H21: 속도 | I21: FALSE | J21: 속도 카운팅
A22: 메모

Sheet 운동 전 스트레칭
B1: 스트레칭명 | D1: 세트 | E1: 시간 | F1: 목표 | G1: 진행 | H1: 특이사항
B2: 날짜 | C2: 44202 | D2: 컨디션/특이사항 | F2: (1~10점 중) + 특이사항
A3: 하체 운동 전 | B3: 프로그 (내전근) | D3: 1 | E3: 0 | F3: 1
D4: 2 | E4: =E3 -> 0 | F4: =F3 -> 1
D5: 3 | E5: =E3 -> 0 | F5: =F3 -> 1
B6: 고관절 모빌리티 | D6: 1 | E6: 0 | F6: 5
D7: 2 | E7: =E6 -> 0 | F7: =F6 -> 5
D8: 3 | E8: =E6 -> 0 | F8: =F6 -> 5
B9: 햄스트링 스트레칭 | D9: 1 | E9: 0 | F9: 1
D10: 2 | E10: =E9 -> 0 | F10: =F9 -> 1
D11: 3 | E11: =E9 -> 0 | F11: =F9 -> 1
D12: 1 | E12: 0 | F12: 0
D13: 2 | E13: =E12 -> 0 | F13: =F12 -> 0
D14: 3 | E14: =E12 -> 0 | F14: =F12 -> 0
A15: 상체 운동 전 | B15: 푸쉬업 플러스 (전거근) | D15: 1 | E15: 0 | F15: 1
D16: 2 | E16: =E15 -> 0 | F16: =F15 -> 1
D17: 3 | E17: =E15 -> 0 | F17: =F15 -> 1
B18: 윌 슬라이드 (전거근) | D18: 1 | E18: 0 | F18: 1
D19: 2 | E19: =E18 -> 0 | F19: =F18 -> 1
D20: 3 | E20: =E18 -> 0 | F20: =F18 -> 1
B21: 견갑골 모빌리티 | D21: 1 | E21: 0 | F21: 1
A24: 추가 스트레칭 | D24: 1 | E24: 0 | F24: 1
D25: 2 | E25: =E24 -> 0 | F25: =F24 -> 1
D26: 3 | E26: =E24 -> 0 | F26: =F24 -> 1
D27: 1 | E27: 0 | F27: 1
D28: 2 | E28: =E27 -> 0 | F28: =F27 -> 1
D29: 3 | E29: =E27 -> 0 | F29: =F27 -> 1
D30: 1 | E30: 0 | F30: 1
D31: 2 | E31: =E30 -> 0 | F31: =F30 -> 1
D32: 3 | E32: =E30 -> 0 | F32: =F30 -> 1
D33: 1 | E33: 0 | F33: 1
D34: 2 | E34: =E33 -> 0 | F34: =F33 -> 1
D35: 3 | E35: =E33 -> 0 | F35: =F33 -> 1

Sheet 무분할 프로그램(1~4주차)
A1: 무분할 프로그램 | C1: 특이사항 | E1: *작성 팁* 수업 전 체크해야할 회원님의 특이사항 / 해당 프로그램 사용 시 달성 목표를 기입
A2: 운동명/반복구간 | C2: 세트 | D2: 중량 | E2: 목표 | F2: 성공 | G2: RPE | H2: V/A | I2: 속도 | J2: 휴식 | K2: 체크리스트 | M2: 메모
A3: 날짜 | B3: 46027 | C3: 당일 컨디션 | E3: 최상 | F3: FALSE | G3: 상 | H3: FALSE | I3: 중 | J3: TRUE | K3: 하 | L3: FALSE | M3: 수업 | N3: TRUE | O3: 과제 | P3: FALSE
A4: 벤치프레스 | C4: 1 | D4: 40 | E4: =TEST!F3 -> 8.6666667 | F4: 12 | H4: =iferror(C6*D6*(F4+F5+F6),0) -> 4080 | I4: 2 | J4: 60 | K4: 자세 | L4: FALSE | M4: 줄 바꿈 = alt + enter
C5: 2 | D5: =D4 -> 40 | E5: =E4 -> 8.6666667 | F5: 12 | H5: =iferror(AVERAGE(F4:F6),0) -> 11.333333 | I5: 0 | K5: 속도 | L5: FALSE
A6: 0 | B6: 100 | C6: 3 | D6: =D4 -> 40 | E6: =E4 -> 8.6666667 | F6: 10 | I6: 1 | K6: ROM | L6: FALSE
A7: 스미스머신 벤치프레스 | C7: 1 | D7: 0 | E7: 0 | H7: =iferror(C9*D9*(F7+F8+F9),0) -> 0 | I7: 2 | J7: 60 | K7: 자세 | L7: FALSE
C8: 2 | D8: =D7 -> 0 | E8: =E7 -> 0 | H8: =iferror(AVERAGE(F7:F9),0) -> 0 | I8: 0 | K8: 속도 | L8: FALSE
A9: 8 | B9: 12 | C9: 3 | D9: =D7 -> 0 | E9: =E7 -> 0 | I9: 1 | K9: ROM | L9: FALSE
A10: 풀업 | C10: 1 | D10: 0 | E10: 0 | F10: 8 | H10: =iferror(C12*D12*(F10+F11+F12),0) -> 0 | I10: 2 | J10: 60 | K10: 자세 | L10: FALSE
C11: 2 | D11: =D10 -> 0 | E11: =E10 -> 0 | F11: 8 | H11: =iferror(AVERAGE(F10:F12),0) -> 8 | I11: 1 | K11: 속도 | L11: FALSE
A12: 8 | B12: 12 | C12: 3 | D12: =D10 -> 0 | E12: =E10 -> 0 | I12: 1 | K12: ROM | L12: FALSE
A13: 케이블로우 | C13: 1 | D13: 0 | E13: 0 | H13: =iferror(C15*D15*(F13+F14+F15),0) -> 0 | I13: 2 | J13: 60 | K13: 자세 | L13: FALSE
C14: 2 | D14: =D13 -> 0 | E14: =E13 -> 0 | H14: =iferror(AVERAGE(F13:F15),0) -> 0 | I14: 0 | K14: 속도 | L14: FALSE
A15: 8 | B15: 12 | C15: 3 | D15: =D13 -> 0 | E15: =E13 -> 0 | I15: 1 | K15: ROM | L15: FALSE
A16: 스쿼트 | C16: 1 | D16: 80 | E16: 0 | F16: 8 | H16: =iferror(C18*D18*(F16+F17+F18),0) -> 5760 | I16: 3 | J16: 90 | K16: 자세 | L16: FALSE
C17: 2 | D17: =D16 -> 80 | E17: =E16 -> 0 | F17: 8 | H17: =iferror(AVERAGE(F16:F18),0) -> 8 | I17: 1 | K17: 속도 | L17: FALSE
A18: 8 | B18: 12 | C18: 3 | D18: =D16 -> 80 | E18: =E16 -> 0 | F18: 8 | I18: 2 | K18: ROM | L18: FALSE
A19: 데드리프트 | C19: 1 | D19: 80 | E19: 0 | F19: 8 | H19: =iferror(C21*D21*(F19+F20+F21),0) -> 5280 | I19: 2 | J19: 60 | K19: 자세 | L19: FALSE
C20: 2 | D20: =D19 -> 80 | E20: =E19 -> 0 | F20: 8 | H20: =iferror(AVERAGE(F19:F21),0) -> 7.3333333 | I20: 0 | K20: 속도 | L20: FALSE
A21: 8 | B21: 12 | C21: 3 | D21: =D19 -> 80 | E21: =E19 -> 0 | F21: 6 | I21: 1 | K21: ROM | L21: FALSE
A22: 힙쓰러스트 | C22: 1 | D22: 0 | E22: 0 | H22: =iferror(C24*D24*(F22+F23+F24),0) -> 0 | I22: 2 | J22: 90 | K22: 자세 | L22: FALSE
C23: 2 | D23: =D22 -> 0 | E23: =E22 -> 0 | H23: =iferror(AVERAGE(F22:F24),0) -> 0 | I23: 0 | K23: 속도 | L23: FALSE
A24: 8 | B24: 12 | C24: 3 | D24: =D22 -> 0 | E24: =E22 -> 0 | I24: 1 | K24: ROM | L24: FALSE
A25: 힙익스텐션 | C25: 1 | D25: 0 | E25: 0 | H25: =iferror(C27*D27*(F25+F26+F27),0) -> 0 | I25: 2 | J25: 60 | K25: 자세 | L25: FALSE
C26: 2 | D26: =D25 -> 0 | E26: =E25 -> 0 | H26: =iferror(AVERAGE(F25:F27),0) -> 0 | I26: 0 | K26: 속도 | L26: FALSE
A27: 8 | B27: 12 | C27: 3 | D27: =D25 -> 0 | E27: =E25 -> 0 | I27: 1 | K27: ROM | L27: FALSE
A28: 덤벨컬 | C28: 1 | D28: 0 | E28: 0 | H28: =iferror(C30*D30*(F28+F29+F30),0) -> 0 | I28: 2 | J28: 60 | K28: 자세 | L28: FALSE
C29: 2 | D29: =D28 -> 0 | E29: =E28 -> 0 | H29: =iferror(AVERAGE(F28:F30),0) -> 0 | I29: 0 | K29: 속도 | L29: FALSE
A30: 8 | B30: 12 | C30: 3 | D30: =D28 -> 0 | E30: =E28 -> 0 | I30: 1 | K30: ROM | L30: FALSE
A31: 케이블 푸쉬다운 | C31: 1 | D31: 0 | E31: 0 | H31: =iferror(C33*D33*(F31+F32+F33),0) -> 0 | I31: 2 | J31: 60 | K31: 자세 | L31: FALSE
C32: 2 | D32: =D31 -> 0 | E32: =E31 -> 0 | H32: =iferror(AVERAGE(F31:F33),0) -> 0 | I32: 0 | K32: 속도 | L32: FALSE
A33: 8 | B33: 12 | C33: 3 | D33: =D31 -> 0 | E33: =E31 -> 0 | I33: 1 | K33: ROM | L33: FALSE
A34: 수업 코멘트
A38: 날짜 | B38: 46029 | C38: 당일 컨디션 | E38: 최상 | F38: FALSE | G38: 상 | H38: FALSE | I38: 중 | J38: TRUE | K38: 하 | L38: FALSE | M38: 수업 | N38: TRUE | O38: 과제 | P38: FALSE
A39: 벤치프레스 | C39: 1 | D39: 40 | E39: 10 | F39: 12 | H39: =iferror(C41*D41*(F39+F40+F41),0) -> 2640 | I39: 2 | J39: 60 | K39: 자세 | L39: FALSE | M39: 줄 바꿈 = alt + enter
C40: 2 | D40: =D39 -> 40 | E40: =E39 -> 10 | F40: 10 | H40: =iferror(AVERAGE(F39:F41),0) -> 11 | I40: 0 | K40: 속도 | L40: FALSE
A41: 0 | B41: 100 | C41: 3 | D41: =D39 -> 40 | E41: =E39 -> 10 | I41: 1 | K41: ROM | L41: FALSE
A42: 스미스머신 벤치프레스 | C42: 1 | D42: 0 | E42: 0 | H42: =iferror(C44*D44*(F42+F43+F44),0) -> 0 | I42: 2 | J42: 60 | K42: 자세 | L42: FALSE
C43: 2 | D43: =D42 -> 0 | E43: =E42 -> 0 | H43: =iferror(AVERAGE(F42:F44),0) -> 0 | I43: 0 | K43: 속도 | L43: FALSE
...

Sheet 2분할 프로그램(5~8주차)
A1: 2분할 상체 | C1: 특이사항 | E1: *작성 팁* 수업 전 체크해야할 회원님의 특이사항 / 해당 프로그램 사용 시 달성 목표를 기입 | R1: 2분할 하체 | T1: 특이사항 | V1: *작성 팁* 수업 전 체크해야할 회원님의 특이사항 / 해당 프로그램 사용 시 달성 목표를 기입
A2: 운동명/반복구간 | C2: 세트 | D2: 중량 | E2: 목표 | F2: 성공 | G2: RPE | H2: V/A | I2: 속도 | J2: 휴식 | K2: 체크리스트 | M2: 메모 | R2: 운동명/반복구간 | T2: 세트 | U2: 중량 | V2: 목표 | W2: 성공 | X2: RPE | Y2: V/A | Z2: 속도 | AA2: 휴식 | AB2: 체크리스트 | AD2: 메모
A3: 날짜 | B3: 46055 | C3: 당일 컨디션 | E3: 최상 | F3: FALSE | G3: 상 | H3: FALSE | I3: 중 | J3: FALSE | K3: 하 | L3: FALSE | M3: 수업 | N3: FALSE | O3: 과제 | P3: FALSE | R3: 날짜 | S3: 46057 | T3: 당일 컨디션 | V3: 최상 | W3: FALSE | X3: 상 | Y3: FALSE | Z3: 중 | AA3: FALSE | AB3: 하 | AC3: FALSE | AD3: 수업 | AE3: FALSE | AF3: 과제 | AG3: FALSE
A4: 벤치프레스 | C4: 1 | D4: 50 | E4: 0 | F4: 12 | H4: =iferror(C6*D6*(F4+F5+F6),0) -> 5250 | I4: 2 | J4: 60 | K4: 자세 | L4: FALSE | M4: 줄 바꿈 = alt + enter | R4: 스쿼트 | T4: 1 | U4: 80 | V4: 0 | W4: 10 | Y4: =iferror(T6*U6*(W4+W5+W6),0) -> 7200 | Z4: 2 | AA4: 90 | AB4: 자세 | AC4: FALSE | AD4: 줄 바꿈 = alt + enter
C5: 2 | D5: =D4 -> 50 | E5: =E4 -> 0 | F5: 12 | H5: =iferror(AVERAGE(F4:F6),0) -> 11.666667 | I5: 0 | K5: 속도 | L5: FALSE | T5: 2 | U5: =U4 -> 80 | V5: =V4 -> 0 | W5: 10 | Y5: =iferror(AVERAGE(W4:W6),0) -> 10 | Z5: 1 | AB5: 속도 | AC5: FALSE
A6: 8 | B6: 12 | C6: 3 | D6: =D4 -> 50 | E6: =E4 -> 0 | F6: 11 | I6: 1 | K6: ROM | L6: FALSE | R6: 6 | S6: 10 | T6: 3 | U6: =U4 -> 80 | V6: =V4 -> 0 | W6: 10 | Z6: 2 | AB6: ROM | AC6: FALSE
A7: 덤벨 인클 벤치 | C7: 1 | D7: 9 | E7: 0 | F7: 15 | H7: =iferror(C9*D9*(F7+F8+F9),0) -> 1215 | I7: 2 | J7: 60 | K7: 자세 | L7: FALSE | R7: 스미스머신 런지 | T7: 1 | U7: 0 | V7: 0 | Y7: =iferror(T9*U9*(W7+W8+W9),0) -> 0 | Z7: 2 | AA7: 60 | AB7: 자세 | AC7: FALSE
C8: 2 | D8: =D7 -> 9 | E8: =E7 -> 0 | F8: 15 | H8: =iferror(AVERAGE(F7:F9),0) -> 15 | I8: 0 | K8: 속도 | L8: FALSE | T8: 2 | U8: =U7 -> 0 | V8: =V7 -> 0 | Y8: =iferror(AVERAGE(W7:W9),0) -> 0 | Z8: 0 | AB8: 속도 | AC8: FALSE
A9: 0 | B9: 100 | C9: 3 | D9: =D7 -> 9 | E9: =E7 -> 0 | F9: 15 | I9: 1 | K9: ROM | L9: FALSE | R9: 8 | S9: 12 | T9: 3 | U9: =U7 -> 0 | V9: =V7 -> 0 | Z9: 1 | AB9: ROM | AC9: FALSE
A10: 케이블 크로스오버 | C10: 1 | D10: 0 | E10: 0 | H10: =iferror(C12*D12*(F10+F11+F12),0) -> 0 | I10: 2 | J10: 60 | K10: 자세 | L10: FALSE | R10: 레그프레스 | T10: 1 | U10: 40 | V10: 0 | W10: 15 | Y10: =iferror(T12*U12*(W10+W11+W12),0) -> 6600 | Z10: 2 | AA10: 60 | AB10: 자세 | AC10: FALSE
C11: 2 | D11: =D10 -> 0 | E11: =E10 -> 0 | H11: =iferror(AVERAGE(F10:F12),0) -> 0 | I11: 1 | K11: 속도 | L11: FALSE | T11: 2 | U11: =U10 -> 40 | V11: =V10 -> 0 | W11: 20 | Y11: =iferror(AVERAGE(W10:W12),0) -> 18.333333 | Z11: 0 | AB11: 속도 | AC11: FALSE
A12: 12 | B12: 20 | C12: 3 | D12: =D10 -> 0 | E12: =E10 -> 0 | I12: 1 | K12: ROM | L12: FALSE | R12: 8 | S12: 12 | T12: 3 | U12: =U10 -> 40 | V12: =V10 -> 0 | W12: 20 | Z12: 1 | AB12: ROM | AC12: FALSE
A13: 밴드 풀업 | C13: 1 | D13: 0 | E13: 0 | F13: 8 | H13: =iferror(C15*D15*(F13+F14+F15),0) -> 0 | I13: 2 | J13: 60 | K13: 자세 | L13: FALSE | R13: 루마니안 데드리프트 | T13: 1 | U13: 80 | V13: 0 | Y13: =iferror(T15*U15*(W13+W14+W15),0) -> 0 | Z13: 2 | AA13: 60 | AB13: 자세 | AC13: FALSE
C14: 2 | D14: =D13 -> 0 | E14: =E13 -> 0 | F14: 10 | H14: =iferror(AVERAGE(F13:F15),0) -> 9 | I14: 1 | K14: 속도 | L14: FALSE | T14: 2 | U14: =U13 -> 80 | V14: =V13 -> 0 | Y14: =iferror(AVERAGE(W13:W15),0) -> 0 | Z14: 1 | AB14: 속도 | AC14: FALSE
A15: 8 | B15: 12 | C15: 3 | D15: =D13 -> 0 | E15: =E13 -> 0 | I15: 1 | K15: ROM | L15: FALSE | R15: 8 | S15: 12 | T15: 3 | U15: =U13 -> 80 | V15: =V13 -> 0 | Z15: 1 | AB15: ROM | AC15: FALSE
A16: 바벨로우 | C16: 1 | D16: 50 | E16: 0 | F16: 10 | H16: =iferror(C18*D18*(F16+F17+F18),0) -> 4500 | I16: 2 | J16: 60 | K16: 자세 | L16: FALSE | R16: 레그 익스텐션 | T16: 1 | U16: 45 | V16: 0 | W16: 15 | Y16: =iferror(T18*U18*(W16+W17+W18),0) -> 6075 | Z16: 2 | AB16: 자세 | AC16: FALSE
C17: 2 | D17: =D16 -> 50 | E17: =E16 -> 0 | F17: 10 | H17: =iferror(AVERAGE(F16:F18),0) -> 10 | I17: 1 | K17: 속도 | L17: FALSE | T17: 2 | U17: =U16 -> 45 | V17: =V16 -> 0 | W17: 15 | Y17: =iferror(AVERAGE(W16:W18),0) -> 15 | Z17: 0 | AB17: 속도 | AC17: FALSE
A18: 8 | B18: 12 | C18: 3 | D18: =D16 -> 50 | E18: =E16 -> 0 | F18: 10 | I18: 1 | K18: ROM | L18: FALSE | R18: 10 | S18: 15 | T18: 3 | U18: =U16 -> 45 | V18: =V16 -> 0 | W18: 15 | Z18: 1 | AB18: ROM | AC18: FALSE
A19: 암풀다운 | C19: 1 | D19: 0 | E19: 0 | H19: =iferror(C21*D21*(F19+F20+F21),0) -> 0 | I19: 2 | J19: 60 | K19: 자세 | L19: FALSE | R19: 레그 컬 | T19: 1 | U19: 45 | V19: 0 | W19: 15 | Y19: =iferror(T21*U21*(W19+W20+W21),0) -> 4050 | AA19: 60 | AB19: 자세 | AC19: FALSE
C20: 2 | D20: =D19 -> 0 | E20: =E19 -> 0 | H20: =iferror(AVERAGE(F19:F21),0) -> 0 | I20: 1 | K20: 속도 | L20: FALSE | T20: 2 | U20: =U19 -> 45 | V20: =V19 -> 0 | W20: 15 | Y20: =iferror(AVERAGE(W19:W21),0) -> 15 | AB20: 속도 | AC20: FALSE
A21: 12 | B21: 20 | C21: 3 | D21: =D19 -> 0 | E21: =E19 -> 0 | I21: 1 | K21: ROM | L21: FALSE | R21: 10 | S21: 15 | T21: 3 | U21: =U19 -> 45 | V21: =V19 -> 0 | AB21: ROM | AC21: FALSE
A22: 덤벨 숄더 프레스 | C22: 1 | D22: 0 | E22: 0 | H22: =iferror(C24*D24*(F22+F23+F24),0) -> 0 | I22: 2 | J22: 60 | K22: 자세 | L22: FALSE | T22: 1 | U22: 0 | V22: 0 | Y22: =iferror(T24*U24*(W22+W23+W24),0) -> 0 | AB22: 자세 | AC22: FALSE
C23: 2 | D23: =D22 -> 0 | E23: =E22 -> 0 | H23: =iferror(AVERAGE(F22:F24),0) -> 0 | I23: 0 | K23: 속도 | L23: FALSE | T23: 2 | U23: =U22 -> 0 | V23: =V22 -> 0 | Y23: =iferror(AVERAGE(W22:W24),0) -> 0 | AB23: 속도 | AC23: FALSE
A24: 8 | B24: 12 | C24: 3 | D24: =D22 -> 0 | E24: =E22 -> 0 | I24: 1 | K24: ROM | L24: FALSE | R24: 8 | S24: 12 | T24: 3 | U24: =U22 -> 0 | V24: =V22 -> 0 | AB24: ROM | AC24: FALSE
A25: 레터럴 레이즈 | C25: 1 | D25: 0 | E25: 0 | H25: =iferror(C27*D27*(F25+F26+F27),0) -> 0 | I25: 2 | J25: 60 | K25: 자세 | L25: FALSE | T25: 1 | U25: 0 | V25: 0 | Y25: =iferror(T27*U27*(W25+W26+W27),0) -> 0 | AB25: 자세 | AC25: FALSE
C26: 2 | D26: =D25 -> 0 | E26: =E25 -> 0 | H26: =iferror(AVERAGE(F25:F27),0) -> 0 | I26: 0 | K26: 속도 | L26: FALSE | T26: 2 | U26: =U25 -> 0 | V26: =V25 -> 0 | Y26: =iferror(AVERAGE(W25:W27),0) -> 0 | AB26: 속도 | AC26: FALSE
A27: 12 | B27: 20 | C27: 3 | D27: =D25 -> 0 | E27: =E25 -> 0 | I27: 1 | K27: ROM | L27: FALSE | R27: 12 | S27: 20 | T27: 3 | U27: =U25 -> 0 | V27: =V25 -> 0 | AB27: ROM | AC27: FALSE
A28: 덤벨컬 | C28: 1 | D28: 0 | E28: 0 | H28: =iferror(C30*D30*(F28+F29+F30),0) -> 0 | I28: 2 | J28: 60 | K28: 자세 | L28: FALSE | T28: 1 | U28: 0 | V28: 0 | Y28: =iferror(T30*U30*(W28+W29+W30),0) -> 0 | AB28: 자세 | AC28: FALSE
C29: 2 | D29: =D28 -> 0 | E29: =E28 -> 0 | H29: =iferror(AVERAGE(F28:F30),0) -> 0 | I29: 0 | K29: 속도 | L29: FALSE | T29: 2 | U29: =U28 -> 0 | V29: =V28 -> 0 | Y29: =iferror(AVERAGE(W28:W30),0) -> 0 | AB29: 속도 | AC29: FALSE
A30: 8 | B30: 12 | C30: 3 | D30: =D28 -> 0 | E30: =E28 -> 0 | I30: 1 | K30: ROM | L30: FALSE | T30: 3 | U30: =U28 -> 0 | V30: =V28 -> 0 | AB30: ROM | AC30: FALSE
A31: 케이블 푸쉬 다운 | C31: 1 | D31: 0 | E31: 0 | H31: =iferror(C33*D33*(F31+F32+F33),0) -> 0 | I31: 2 | J31: 60 | K31: 자세 | L31: FALSE | T31: 1 | U31: 0 | V31: 0 | Y31: =iferror(T33*U33*(W31+W32+W33),0) -> 0 | AB31: 자세 | AC31: FALSE
C32: 2 | D32: =D31 -> 0 | E32: =E31 -> 0 | H32: =iferror(AVERAGE(F31:F33),0) -> 0 | I32: 0 | K32: 속도 | L32: FALSE | T32: 2 | U32: =U31 -> 0 | V32: =V31 -> 0 | Y32: =iferror(AVERAGE(W31:W33),0) -> 0 | AB32: 속도 | AC32: FALSE
A33: 8 | B33: 12 | C33: 3 | D33: =D31 -> 0 | E33: =E31 -> 0 | I33: 1 | K33: ROM | L33: FALSE | T33: 3 | U33: =U31 -> 0 | V33: =V31 -> 0 | AB33: ROM | AC33: FALSE
A34: 수업 코멘트 | R34: 수업 코멘트
A38: 날짜 | B38: 46062 | C38: 당일 컨디션 | E38: 최상 | F38: FALSE | G38: 상 | H38: FALSE | I38: 중 | J38: FALSE | K38: 하 | L38: FALSE | M38: 수업 | N38: FALSE | O38: 과제 | P38: FALSE | R38: 날짜 | S38: 46064 | T38: 당일 컨디션 | V38: 최상 | W38: FALSE | X38: 상 | Y38: FALSE | Z38: 중 | AA38: FALSE | AB38: 하 | AC38: FALSE | AD38: 수업 | AE38: FALSE | AF38: 과제 | AG38: FALSE
A39: 벤치프레스 | C39: 1 | D39: 60 | E39: 0 | F39: 8 | H39: =iferror(C41*D41*(F39+F40+F41),0) -> 4320 | I39: 2 | J39: 60 | K39: 자세 | L39: FALSE | M39: 1rm 80 | R39: 스쿼트 | T39: 1 | U39: 80 | V39: 0 | W39: 11 | Y39: =iferror(T41*U41*(W39+W40+W41),0) -> 7920 | Z39: 2 | AA39: 90 | AB39: 자세 | AC39: FALSE | AD39: 1rm 105
C40: 2 | D40: =D39 -> 60 | E40: =E39 -> 0 | F40: 8 | H40: =iferror(AVERAGE(F39:F41),0) -> 8 | I40: 0 | K40: 속도 | L40: FALSE | T40: 2 | U40: =U39 -> 80 | V40: =V39 -> 0 | W40: 11 | Y40: =iferror(AVERAGE(W39:W41),0) -> 11 | Z40: 1 | AB40: 속도 | AC40: FALSE
A41: 8 | B41: 12 | C41: 3 | D41: =D39 -> 60 | E41: =E39 -> 0 | F41: 8 | I41: 1 | K41: ROM | L41: FALSE | R41: 6 | S41: 10 | T41: 3 | U41: =U39 -> 80 | V41: =V39 -> 0 | W41: 11 | Z41: 2 | AB41: ROM | AC41: FALSE
A42: 딥스 | C42: 1 | D42: 9 | E42: 0 | F42: 8 | H42: =iferror(C44*D44*(F42+F43+F44),0) -> 1026 | I42: 2 | J42: 60 | K42: 자세 | L42: FALSE | M42: 밴드 | R42: 런지 | T42: 1 | U42: 15 | V42: 0 | W42: 10 | Y42: =iferror(T44*U44*(W42+W43+W44),0) -> 900 | Z42: 2 | AA42: 60 | AB42: 자세 | AC42: FALSE
C43: 2 | D43: =D42 -> 9 | E43: =E42 -> 0 | F43: 15 | H43: =iferror(AVERAGE(F42:F44),0) -> 12.666667 | I43: 0 | K43: 속도 | L43: FALSE | T43: 2 | U43: =U42 -> 15 | V43: =V42 -> 0 | W43: 10 | Y43: =iferror(AVERAGE(W42:W44),0) -> 10 | Z43: 0 | AB43: 속도 | AC43: FALSE
...

Sheet 2분할AB 프로그램(9~12주차) 상체
A1: 2분할 상체 A | C1: 특이사항 | E1: *작성 팁* 수업 전 체크해야할 회원님의 특이사항 / 해당 프로그램 사용 시 달성 목표를 기입 | R1: 2분할 상체 B | T1: 특이사항 | V1: *작성 팁* 수업 전 체크해야할 회원님의 특이사항 / 해당 프로그램 사용 시 달성 목표를 기입
A2: 운동명/반복구간 | C2: 세트 | D2: 중량 | E2: 목표 | F2: 성공 | G2: RPE | H2: V/A | I2: 속도 | J2: 휴식 | K2: 체크리스트 | M2: 메모 | R2: 운동명/반복구간 | T2: 세트 | U2: 중량 | V2: 목표 | W2: 성공 | X2: RPE | Y2: V/A | Z2: 속도 | AA2: 휴식 | AB2: 체크리스트 | AD2: 메모
A3: 날짜 | B3: 46120 | C3: 당일 컨디션 | E3: 최상 | F3: FALSE | G3: 상 | H3: FALSE | I3: 중 | J3: FALSE | K3: 하 | L3: FALSE | M3: 수업 | N3: FALSE | O3: 과제 | P3: FALSE | R3: 날짜 | S3: 46127 | T3: 당일 컨디션 | V3: 최상 | W3: FALSE | X3: 상 | Y3: FALSE | Z3: 중 | AA3: FALSE | AB3: 하 | AC3: FALSE | AD3: 수업 | AE3: FALSE | AF3: 과제 | AG3: FALSE
A4: 벤치프레스 | C4: 1 | D4: 60 | E4: 0 | F4: 9 | H4: =iferror(C6*D6*(F4+F5+F6),0) -> 4860 | I4: 2 | J4: 90 | K4: 자세 | L4: FALSE | M4: 줄 바꿈 = alt + enter | R4: 벤치프레스 | T4: 1 | U4: 60 | V4: 0 | W4: 10 | Y4: =iferror(T6*U6*(W4+W5+W6),0) -> 5400 | Z4: 2 | AA4: 60 | AB4: 자세 | AC4: FALSE | AD4: 줄 바꿈 = alt + enter
C5: 2 | D5: =D4 -> 60 | E5: =E4 -> 0 | F5: 9 | H5: =iferror(AVERAGE(F4:F6),0) -> 9 | I5: 0 | K5: 속도 | L5: FALSE | T5: 2 | U5: =U4 -> 60 | V5: =V4 -> 0 | W5: 10 | Y5: =iferror(AVERAGE(W4:W6),0) -> 10 | Z5: 0 | AB5: 속도 | AC5: FALSE
A6: 2 | B6: 5 | C6: 3 | D6: =D4 -> 60 | E6: =E4 -> 0 | F6: 9 | I6: 1 | K6: ROM | L6: FALSE | R6: 6 | S6: 10 | T6: 3 | U6: =U4 -> 60 | V6: =V4 -> 0 | W6: 10 | Z6: 1 | AB6: ROM | AC6: FALSE
A7: 딥스 | C7: 1 | D7: 0 | E7: 0 | H7: =iferror(C9*D9*(F7+F8+F9),0) -> 0 | I7: 2 | J7: 60 | K7: 자세 | L7: FALSE | R7: 덤벨프레스 | T7: 1 | U7: 0 | V7: 0 | Y7: =iferror(T9*U9*(W7+W8+W9),0) -> 0 | Z7: 2 | AA7: 60 | AB7: 자세 | AC7: FALSE
C8: 2 | D8: =D7 -> 0 | E8: =E7 -> 0 | H8: =iferror(AVERAGE(F7:F9),0) -> 0 | I8: 0 | K8: 속도 | L8: FALSE | T8: 2 | U8: =U7 -> 0 | V8: =V7 -> 0 | Y8: =iferror(AVERAGE(W7:W9),0) -> 0 | Z8: 0 | AB8: 속도 | AC8: FALSE
A9: 6 | B9: 10 | C9: 3 | D9: =D7 -> 0 | E9: =E7 -> 0 | I9: 1 | K9: ROM | L9: FALSE | R9: 8 | S9: 12 | T9: 3 | U9: =U7 -> 0 | V9: =V7 -> 0 | Z9: 1 | AB9: ROM | AC9: FALSE
A10: 스미스 머신 벤치프레스(체스트프레스) | C10: 1 | D10: 0 | E10: 0 | H10: =iferror(C12*D12*(F10+F11+F12),0) -> 0 | I10: 2 | J10: 60 | K10: 자세 | L10: FALSE | R10: 스미스 머신 벤치프레스(체스트프레스) | T10: 1 | U10: 0 | V10: 0 | Y10: =iferror(T12*U12*(W10+W11+W12),0) -> 0 | Z10: 2 | AA10: 60 | AB10: 자세 | AC10: FALSE
C11: 2 | D11: =D10 -> 0 | E11: =E10 -> 0 | H11: =iferror(AVERAGE(F10:F12),0) -> 0 | I11: 1 | K11: 속도 | L11: FALSE | T11: 2 | U11: =U10 -> 0 | V11: =V10 -> 0 | Y11: =iferror(AVERAGE(W10:W12),0) -> 0 | Z11: 1 | AB11: 속도 | AC11: FALSE
A12: 8 | B12: 12 | C12: 3 | D12: =D10 -> 0 | E12: =E10 -> 0 | I12: 1 | K12: ROM | L12: FALSE | R12: 8 | S12: 12 | T12: 3 | U12: =U10 -> 0 | V12: =V10 -> 0 | Z12: 1 | AB12: ROM | AC12: FALSE
A13: 덤벨 프레스 | C13: 1 | D13: 15 | E13: 0 | F13: 12 | H13: =iferror(C15*D15*(F13+F14+F15),0) -> 1755 | I13: 2 | J13: 60 | K13: 자세 | L13: FALSE | R13: 플라이 | T13: 1 | U13: 30 | V13: 0 | W13: 15 | Y13: =iferror(T15*U15*(W13+W14+W15),0) -> 4050 | Z13: 2 | AA13: 60 | AB13: 자세 | AC13: FALSE
C14: 2 | D14: =D13 -> 15 | E14: =E13 -> 0 | F14: 12 | H14: =iferror(AVERAGE(F13:F15),0) -> 13 | I14: 1 | K14: 속도 | L14: FALSE | T14: 2 | U14: =U13 -> 30 | V14: =V13 -> 0 | W14: 15 | Y14: =iferror(AVERAGE(W13:W15),0) -> 15 | Z14: 1 | AB14: 속도 | AC14: FALSE
A15: 10 | B15: 15 | C15: 3 | D15: =D13 -> 15 | E15: =E13 -> 0 | F15: 15 | I15: 1 | K15: ROM | L15: FALSE | R15: 12 | S15: 20 | T15: 3 | U15: =U13 -> 30 | V15: =V13 -> 0 | W15: 15 | Z15: 1 | AB15: ROM | AC15: FALSE
A16: 바벨로우 | C16: 1 | D16: 50 | E16: 0 | F16: 12 | H16: =iferror(C18*D18*(F16+F17+F18),0) -> 5400 | I16: 2 | J16: 60 | K16: 자세 | L16: FALSE | R16: 원암덤벨로우 | T16: 1 | U16: 0 | V16: 0 | Y16: =iferror(T18*U18*(W16+W17+W18),0) -> 0 | Z16: 2 | AA16: 60 | AB16: 자세 | AC16: FALSE
C17: 2 | D17: =D16 -> 50 | E17: =E16 -> 0 | F17: 12 | H17: =iferror(AVERAGE(F16:F18),0) -> 12 | I17: 1 | K17: 속도 | L17: FALSE | T17: 2 | U17: =U16 -> 0 | V17: =V16 -> 0 | Y17: =iferror(AVERAGE(W16:W18),0) -> 0 | Z17: 1 | AB17: 속도 | AC17: FALSE
A18: 6 | B18: 10 | C18: 3 | D18: =D16 -> 50 | E18: =E16 -> 0 | F18: 12 | I18: 1 | K18: ROM | L18: FALSE | R18: 8 | S18: 12 | T18: 3 | U18: =U16 -> 0 | V18: =V16 -> 0 | Z18: 1 | AB18: ROM | AC18: FALSE
A19: 랫풀다운 | C19: 1 | D19: 0 | E19: 0 | H19: =iferror(C21*D21*(F19+F20+F21),0) -> 0 | I19: 2 | J19: 60 | K19: 자세 | L19: FALSE | R19: 클로즈그립 랫풀다운 | T19: 1 | U19: 42 | V19: 0 | W19: 12 | Y19: =iferror(T21*U21*(W19+W20+W21),0) -> 4536 | Z19: 2 | AA19: 60 | AB19: 자세 | AC19: FALSE
C20: 2 | D20: =D19 -> 0 | E20: =E19 -> 0 | H20: =iferror(AVERAGE(F19:F21),0) -> 0 | I20: 1 | K20: 속도 | L20: FALSE | T20: 2 | U20: =U19 -> 42 | V20: =V19 -> 0 | W20: 12 | Y20: =iferror(AVERAGE(W19:W21),0) -> 12 | Z20: 1 | AB20: 속도 | AC20: FALSE
A21: 6 | B21: 10 | C21: 3 | D21: =D19 -> 0 | E21: =E19 -> 0 | I21: 1 | K21: ROM | L21: FALSE | R21: 8 | S21: 12 | T21: 3 | U21: =U19 -> 42 | V21: =V19 -> 0 | W21: 12 | Z21: 1 | AB21: ROM | AC21: FALSE
A22: 케이블로우 | C22: 1 | D22: 0 | E22: 0 | H22: =iferror(C24*D24*(F22+F23+F24),0) -> 0 | I22: 2 | J22: 60 | K22: 자세 | L22: FALSE | R22: 케이블 로우 | T22: 1 | U22: 72 | V22: 0 | W22: 12 | Y22: =iferror(T24*U24*(W22+W23+W24),0) -> 7776 | Z22: 2 | AA22: 60 | AB22: 자세 | AC22: FALSE
C23: 2 | D23: =D22 -> 0 | E23: =E22 -> 0 | H23: =iferror(AVERAGE(F22:F24),0) -> 0 | I23: 1 | K23: 속도 | L23: FALSE | T23: 2 | U23: =U22 -> 72 | V23: =V22 -> 0 | W23: 12 | Y23: =iferror(AVERAGE(W22:W24),0) -> 12 | Z23: 1 | AB23: 속도 | AC23: FALSE
A24: 8 | B24: 12 | C24: 3 | D24: =D22 -> 0 | E24: =E22 -> 0 | I24: 1 | K24: ROM | L24: FALSE | R24: 8 | S24: 12 | T24: 3 | U24: =U22 -> 72 | V24: =V22 -> 0 | W24: 12 | Z24: 1 | AB24: ROM | AC24: FALSE
A25: 암풀다운 | C25: 1 | D25: 30 | E25: 0 | F25: 15 | H25: =iferror(C27*D27*(F25+F26+F27),0) -> 2700 | I25: 2 | J25: 60 | K25: 자세 | L25: FALSE | R25: 암풀다운 | T25: 1 | U25: 0 | V25: 0 | Y25: =iferror(T27*U27*(W25+W26+W27),0) -> 0 | Z25: 2 | AA25: 60 | AB25: 자세 | AC25: FALSE
C26: 2 | D26: =D25 -> 30 | E26: =E25 -> 0 | F26: 15 | H26: =iferror(AVERAGE(F25:F27),0) -> 15 | I26: 0 | K26: 속도 | L26: FALSE | T26: 2 | U26: =U25 -> 0 | V26: =V25 -> 0 | Y26: =iferror(AVERAGE(W25:W27),0) -> 0 | Z26: 0 | AB26: 속도 | AC26: FALSE
A27: 10 | B27: 15 | C27: 3 | D27: =D25 -> 30 | E27: =E25 -> 0 | I27: 1 | K27: ROM | L27: FALSE | R27: 12 | S27: 20 | T27: 3 | U27: =U25 -> 0 | V27: =V25 -> 0 | Z27: 1 | AB27: ROM | AC27: FALSE
A28: 바벨컬 | C28: 1 | D28: 0 | E28: 0 | H28: =iferror(C30*D30*(F28+F29+F30),0) -> 0 | I28: 2 | J28: 60 | K28: 자세 | L28: FALSE | R28: 덤벨컬 | T28: 1 | U28: 0 | V28: 0 | Y28: =iferror(T30*U30*(W28+W29+W30),0) -> 0 | Z28: 2 | AA28: 60 | AB28: 자세 | AC28: FALSE
C29: 2 | D29: =D28 -> 0 | E29: =E28 -> 0 | H29: =iferror(AVERAGE(F28:F30),0) -> 0 | I29: 0 | K29: 속도 | L29: FALSE | T29: 2 | U29: =U28 -> 0 | V29: =V28 -> 0 | Y29: =iferror(AVERAGE(W28:W30),0) -> 0 | Z29: 0 | AB29: 속도 | AC29: FALSE
A30: 4 | B30: 8 | C30: 3 | D30: =D28 -> 0 | E30: =E28 -> 0 | I30: 1 | K30: ROM | L30: FALSE | R30: 10 | S30: 15 | T30: 3 | U30: =U28 -> 0 | V30: =V28 -> 0 | Z30: 1 | AB30: ROM | AC30: FALSE
A31: 라트익 | C31: 1 | D31: 0 | E31: 0 | H31: =iferror(C33*D33*(F31+F32+F33),0) -> 0 | I31: 2 | J31: 60 | K31: 자세 | L31: FALSE | R31: 케이블 푸쉬다운 | T31: 1 | U31: 0 | V31: 0 | Y31: =iferror(T33*U33*(W31+W32+W33),0) -> 0 | Z31: 2 | AA31: 60 | AB31: 자세 | AC31: FALSE
C32: 2 | D32: =D31 -> 0 | E32: =E31 -> 0 | H32: =iferror(AVERAGE(F31:F33),0) -> 0 | I32: 0 | K32: 속도 | L32: FALSE | T32: 2 | U32: =U31 -> 0 | V32: =V31 -> 0 | Y32: =iferror(AVERAGE(W31:W33),0) -> 0 | Z32: 0 | AB32: 속도 | AC32: FALSE
A33: 4 | B33: 8 | C33: 3 | D33: =D31 -> 0 | E33: =E31 -> 0 | I33: 1 | K33: ROM | L33: FALSE | R33: 10 | S33: 15 | T33: 3 | U33: =U31 -> 0 | V33: =V31 -> 0 | Z33: 1 | AB33: ROM | AC33: FALSE
A34: 추가 팔운동1 | C34: 1 | D34: 0 | E34: 0 | H34: =iferror(C36*D36*(F34+F35+F36),0) -> 0 | K34: 자세 | L34: FALSE | R34: 추가 팔운동1 | T34: 1 | U34: 0 | V34: 0 | Y34: =iferror(T36*U36*(W34+W35+W36),0) -> 0 | AB34: 자세 | AC34: FALSE
C35: 2 | D35: =D34 -> 0 | E35: =E34 -> 0 | H35: =iferror(AVERAGE(F34:F36),0) -> 0 | K35: 속도 | L35: FALSE | T35: 2 | U35: =U34 -> 0 | V35: =V34 -> 0 | Y35: =iferror(AVERAGE(W34:W36),0) -> 0 | AB35: 속도 | AC35: FALSE
A36: 4 | B36: 8 | C36: 3 | D36: =D34 -> 0 | E36: =E34 -> 0 | K36: ROM | L36: FALSE | R36: 10 | S36: 15 | T36: 3 | U36: =U34 -> 0 | V36: =V34 -> 0 | AB36: ROM | AC36: FALSE
A37: 추가 팔운동 2 | C37: 1 | D37: 0 | E37: 0 | H37: =iferror(C39*D39*(F37+F38+F39),0) -> 0 | K37: 자세 | L37: FALSE | R37: 추가 팔운동 2 | T37: 1 | U37: 0 | V37: 0 | Y37: =iferror(T39*U39*(W37+W38+W39),0) -> 0 | AB37: 자세 | AC37: FALSE
C38: 2 | D38: =D37 -> 0 | E38: =E37 -> 0 | H38: =iferror(AVERAGE(F37:F39),0) -> 0 | K38: 속도 | L38: FALSE | T38: 2 | U38: =U37 -> 0 | V38: =V37 -> 0 | Y38: =iferror(AVERAGE(W37:W39),0) -> 0 | AB38: 속도 | AC38: FALSE
A39: 4 | B39: 8 | C39: 3 | D39: =D37 -> 0 | E39: =E37 -> 0 | K39: ROM | L39: FALSE | R39: 10 | S39: 15 | T39: 3 | U39: =U37 -> 0 | V39: =V37 -> 0 | AB39: ROM | AC39: FALSE
A40: 수업 코멘트 | R40: 수업 코멘트
...

Sheet 2분할AB 프로그램(9~12주차) 하체
A1: 2분할 하체 A | C1: 특이사항 | E1: *작성 팁* 수업 전 체크해야할 회원님의 특이사항 / 해당 프로그램 사용 시 달성 목표를 기입 | R1: 2분할 하체 B | T1: 특이사항 | V1: *작성 팁* 수업 전 체크해야할 회원님의 특이사항 / 해당 프로그램 사용 시 달성 목표를 기입
A2: 운동명/반복구간 | C2: 세트 | D2: 중량 | E2: 목표 | F2: 성공 | G2: RPE | H2: V/A | I2: 속도 | J2: 휴식 | K2: 체크리스트 | M2: 메모 | R2: 운동명/반복구간 | T2: 세트 | U2: 중량 | V2: 목표 | W2: 성공 | X2: RPE | Y2: V/A | Z2: 속도 | AA2: 휴식 | AB2: 체크리스트 | AD2: 메모
A3: 날짜 | B3: 46118 | C3: 당일 컨디션 | E3: 최상 | F3: FALSE | G3: 상 | H3: FALSE | I3: 중 | J3: FALSE | K3: 하 | L3: FALSE | M3: 수업 | N3: FALSE | O3: 과제 | P3: FALSE | R3: 날짜 | S3: 46125 | T3: 당일 컨디션 | V3: 최상 | W3: FALSE | X3: 상 | Y3: FALSE | Z3: 중 | AA3: FALSE | AB3: 하 | AC3: FALSE | AD3: 수업 | AE3: FALSE | AF3: 과제 | AG3: FALSE
A4: 스쿼트 | C4: 1 | D4: 90 | E4: 0 | F4: 9 | H4: =iferror(C6*D6*(F4+F5+F6),0) -> 7290 | I4: 2 | J4: 120 | K4: 자세 | L4: FALSE | M4: 줄 바꿈 = alt + enter | R4: 스쿼트 | T4: 1 | U4: 90 | V4: 0 | W4: 10 | Y4: =iferror(T6*U6*(W4+W5+W6),0) -> 6750 | Z4: 2 | AA4: 90 | AB4: 자세 | AC4: FALSE | AD4: 줄 바꿈 = alt + enter
C5: 2 | D5: =D4 -> 90 | E5: =E4 -> 0 | F5: 9 | H5: =iferror(AVERAGE(F4:F6),0) -> 9 | I5: 1 | K5: 속도 | L5: FALSE | T5: 2 | U5: =U4 -> 90 | V5: =V4 -> 0 | W5: 7 | Y5: =iferror(AVERAGE(W4:W6),0) -> 8.3333333 | Z5: 1 | AB5: 속도 | AC5: FALSE
A6: 2 | B6: 5 | C6: 3 | D6: =D4 -> 90 | E6: =E4 -> 0 | F6: 9 | I6: 2 | K6: ROM | L6: FALSE | R6: 6 | S6: 10 | T6: 3 | U6: =U4 -> 90 | V6: =V4 -> 0 | W6: 8 | Z6: 2 | AB6: ROM | AC6: FALSE
A7: V-SQ | C7: 1 | D7: 60 | E7: 0 | F7: 15 | H7: =iferror(C9*D9*(F7+F8+F9),0) -> 4860 | I7: 2 | J7: 90 | K7: 자세 | L7: FALSE | R7: 레그 프레스 | T7: 1 | U7: 80 | V7: 0 | W7: 20 | Y7: =iferror(T9*U9*(W7+W8+W9),0) -> 14400 | Z7: 2 | AA7: 60 | AB7: 자세 | AC7: FALSE
C8: 2 | D8: =D7 -> 60 | E8: =E7 -> 0 | F8: 12 | H8: =iferror(AVERAGE(F7:F9),0) -> 13.5 | I8: 0 | K8: 속도 | L8: FALSE | T8: 2 | U8: =U7 -> 80 | V8: =V7 -> 0 | W8: 20 | Y8: =iferror(AVERAGE(W7:W9),0) -> 20 | Z8: 0 | AB8: 속도 | AC8: FALSE
A9: 6 | B9: 10 | C9: 3 | D9: =D7 -> 60 | E9: =E7 -> 0 | I9: 1 | K9: ROM | L9: FALSE | R9: 8 | S9: 12 | T9: 3 | U9: =U7 -> 80 | V9: =V7 -> 0 | W9: 20 | Z9: 1 | AB9: ROM | AC9: FALSE
A10: 레그 프레스 | C10: 1 | D10: 0 | E10: 0 | H10: =iferror(C12*D12*(F10+F11+F12),0) -> 0 | I10: 2 | J10: 60 | K10: 자세 | L10: FALSE | R10: 루마니안 데드리프트 | T10: 1 | U10: 0 | V10: 0 | Y10: =iferror(T12*U12*(W10+W11+W12),0) -> 0 | Z10: 2 | AA10: 60 | AB10: 자세 | AC10: FALSE
C11: 2 | D11: =D10 -> 0 | E11: =E10 -> 0 | H11: =iferror(AVERAGE(F10:F12),0) -> 0 | I11: 0 | K11: 속도 | L11: FALSE | T11: 2 | U11: =U10 -> 0 | V11: =V10 -> 0 | Y11: =iferror(AVERAGE(W10:W12),0) -> 0 | Z11: 0 | AB11: 속도 | AC11: FALSE
A12: 6 | B12: 10 | C12: 3 | D12: =D10 -> 0 | E12: =E10 -> 0 | I12: 1 | K12: ROM | L12: FALSE | R12: 8 | S12: 12 | T12: 3 | U12: =U10 -> 0 | V12: =V10 -> 0 | Z12: 1 | AB12: ROM | AC12: FALSE
A13: 레그 익스텐션 | C13: 1 | D13: 60 | E13: 0 | F13: 15 | H13: =iferror(C15*D15*(F13+F14+F15),0) -> 5400 | I13: 2 | J13: 60 | K13: 자세 | L13: FALSE | R13: 레그 익스텐션 | T13: 1 | U13: 0 | V13: 0 | Y13: =iferror(T15*U15*(W13+W14+W15),0) -> 0 | Z13: 2 | AA13: 60 | AB13: 자세 | AC13: FALSE
C14: 2 | D14: =D13 -> 60 | E14: =E13 -> 0 | F14: 15 | H14: =iferror(AVERAGE(F13:F15),0) -> 15 | I14: 1 | K14: 속도 | L14: FALSE | T14: 2 | U14: =U13 -> 0 | V14: =V13 -> 0 | Y14: =iferror(AVERAGE(W13:W15),0) -> 0 | Z14: 1 | AB14: 속도 | AC14: FALSE
A15: 10 | B15: 15 | C15: 3 | D15: =D13 -> 60 | E15: =E13 -> 0 | I15: 1 | K15: ROM | L15: FALSE | R15: 12 | S15: 20 | T15: 3 | U15: =U13 -> 0 | V15: =V13 -> 0 | Z15: 1 | AB15: ROM | AC15: FALSE
A16: 레그컬 | C16: 1 | D16: 60 | E16: 0 | F16: 15 | H16: =iferror(C18*D18*(F16+F17+F18),0) -> 5400 | I16: 2 | J16: 60 | K16: 자세 | L16: FALSE | R16: 레그컬 | T16: 1 | U16: 0 | V16: 0 | Y16: =iferror(T18*U18*(W16+W17+W18),0) -> 0 | Z16: 2 | AA16: 60 | AB16: 자세 | AC16: FALSE
C17: 2 | D17: =D16 -> 60 | E17: =E16 -> 0 | F17: 15 | H17: =iferror(AVERAGE(F16:F18),0) -> 15 | I17: 0 | K17: 속도 | L17: FALSE | T17: 2 | U17: =U16 -> 0 | V17: =V16 -> 0 | Y17: =iferror(AVERAGE(W16:W18),0) -> 0 | Z17: 0 | AB17: 속도 | AC17: FALSE
A18: 10 | B18: 15 | C18: 3 | D18: =D16 -> 60 | E18: =E16 -> 0 | I18: 1 | K18: ROM | L18: FALSE | R18: 12 | S18: 20 | T18: 3 | U18: =U16 -> 0 | V18: =V16 -> 0 | Z18: 1 | AB18: ROM | AC18: FALSE
C19: 1 | D19: 0 | E19: 0 | H19: =iferror(C21*D21*(F19+F20+F21),0) -> 0 | K19: 자세 | L19: FALSE | T19: 1 | U19: 0 | V19: 0 | Y19: =iferror(T21*U21*(W19+W20+W21),0) -> 0 | AB19: 자세 | AC19: FALSE
C20: 2 | D20: =D19 -> 0 | E20: =E19 -> 0 | H20: =iferror(AVERAGE(F19:F21),0) -> 0 | K20: 속도 | L20: FALSE | T20: 2 | U20: =U19 -> 0 | V20: =V19 -> 0 | Y20: =iferror(AVERAGE(W19:W21),0) -> 0 | AB20: 속도 | AC20: FALSE
C21: 3 | D21: =D19 -> 0 | E21: =E19 -> 0 | K21: ROM | L21: FALSE | T21: 3 | U21: =U19 -> 0 | V21: =V19 -> 0 | AB21: ROM | AC21: FALSE
A22: 밀리터리 프레스 | C22: 1 | D22: 0 | E22: 0 | H22: =iferror(C24*D24*(F22+F23+F24),0) -> 0 | I22: 2 | J22: 60 | K22: 자세 | L22: FALSE | R22: OHP | T22: 1 | U22: 20 | V22: 0 | W22: 10 | Y22: =iferror(T24*U24*(W22+W23+W24),0) -> 1800 | Z22: 2 | AA22: 60 | AB22: 자세 | AC22: FALSE
C23: 2 | D23: =D22 -> 0 | E23: =E22 -> 0 | H23: =iferror(AVERAGE(F22:F24),0) -> 0 | I23: 0 | K23: 속도 | L23: FALSE | T23: 2 | U23: =U22 -> 20 | V23: =V22 -> 0 | W23: 10 | Y23: =iferror(AVERAGE(W22:W24),0) -> 10 | Z23: 0 | AB23: 속도 | AC23: FALSE
A24: 2 | B24: 5 | C24: 3 | D24: =D22 -> 0 | E24: =E22 -> 0 | I24: 1 | K24: ROM | L24: FALSE | R24: 6 | S24: 10 | T24: 3 | U24: =U22 -> 20 | V24: =V22 -> 0 | W24: 10 | Z24: 1 | AB24: ROM | AC24: FALSE
A25: 레터럴 레이즈 | C25: 1 | D25: 0 | E25: 0 | H25: =iferror(C27*D27*(F25+F26+F27),0) -> 0 | I25: 2 | J25: 60 | K25: 자세 | L25: FALSE | R25: 원암레터럴 레이즈 | T25: 1 | U25: 0 | V25: 0 | Y25: =iferror(T27*U27*(W25+W26+W27),0) -> 0 | Z25: 2 | AA25: 60 | AB25: 자세 | AC25: FALSE
C26: 2 | D26: =D25 -> 0 | E26: =E25 -> 0 | H26: =iferror(AVERAGE(F25:F27),0) -> 0 | I26: 0 | K26: 속도 | L26: FALSE | T26: 2 | U26: =U25 -> 0 | V26: =V25 -> 0 | Y26: =iferror(AVERAGE(W25:W27),0) -> 0 | Z26: 0 | AB26: 속도 | AC26: FALSE
A27: 8 | B27: 12 | C27: 3 | D27: =D25 -> 0 | E27: =E25 -> 0 | I27: 1 | K27: ROM | L27: FALSE | R27: 12 | S27: 20 | T27: 3 | U27: =U25 -> 0 | V27: =V25 -> 0 | Z27: 1 | AB27: ROM | AC27: FALSE
A28: 벤트오버 레터럴 레이즈 | C28: 1 | D28: 0 | E28: 0 | H28: =iferror(C30*D30*(F28+F29+F30),0) -> 0 | I28: 2 | J28: 60 | K28: 자세 | L28: FALSE | R28: 벤트오버 레터럴 레이즈 | T28: 1 | U28: 0 | V28: 0 | Y28: =iferror(T30*U30*(W28+W29+W30),0) -> 0 | Z28: 2 | AA28: 60 | AB28: 자세 | AC28: FALSE
C29: 2 | D29: =D28 -> 0 | E29: =E28 -> 0 | H29: =iferror(AVERAGE(F28:F30),0) -> 0 | I29: 0 | K29: 속도 | L29: FALSE | T29: 2 | U29: =U28 -> 0 | V29: =V28 -> 0 | Y29: =iferror(AVERAGE(W28:W30),0) -> 0 | Z29: 0 | AB29: 속도 | AC29: FALSE
A30: 8 | B30: 12 | C30: 3 | D30: =D28 -> 0 | E30: =E28 -> 0 | I30: 1 | K30: ROM | L30: FALSE | R30: 12 | S30: 20 | T30: 3 | U30: =U28 -> 0 | V30: =V28 -> 0 | Z30: 1 | AB30: ROM | AC30: FALSE
C31: 1 | D31: 0 | E31: 0 | H31: =iferror(C33*D33*(F31+F32+F33),0) -> 0 | K31: 자세 | L31: FALSE | T31: 1 | U31: 0 | V31: 0 | Y31: =iferror(T33*U33*(W31+W32+W33),0) -> 0 | AB31: 자세 | AC31: FALSE
C32: 2 | D32: =D31 -> 0 | E32: =E31 -> 0 | H32: =iferror(AVERAGE(F31:F33),0) -> 0 | K32: 속도 | L32: FALSE | T32: 2 | U32: =U31 -> 0 | V32: =V31 -> 0 | Y32: =iferror(AVERAGE(W31:W33),0) -> 0 | AB32: 속도 | AC32: FALSE
C33: 3 | D33: =D31 -> 0 | E33: =E31 -> 0 | K33: ROM | L33: FALSE | T33: 3 | U33: =U31 -> 0 | V33: =V31 -> 0 | AB33: ROM | AC33: FALSE
C34: 1 | D34: 0 | E34: 0 | H34: =iferror(C36*D36*(F34+F35+F36),0) -> 0 | K34: 자세 | L34: FALSE | T34: 1 | U34: 0 | V34: 0 | Y34: =iferror(T36*U36*(W34+W35+W36),0) -> 0 | AB34: 자세 | AC34: FALSE
C35: 2 | D35: =D34 -> 0 | E35: =E34 -> 0 | H35: =iferror(AVERAGE(F34:F36),0) -> 0 | K35: 속도 | L35: FALSE | T35: 2 | U35: =U34 -> 0 | V35: =V34 -> 0 | Y35: =iferror(AVERAGE(W34:W36),0) -> 0 | AB35: 속도 | AC35: FALSE
C36: 3 | D36: =D34 -> 0 | E36: =E34 -> 0 | K36: ROM | L36: FALSE | T36: 3 | U36: =U34 -> 0 | V36: =V34 -> 0 | AB36: ROM | AC36: FALSE
C37: 1 | D37: 0 | E37: 0 | H37: =iferror(C39*D39*(F37+F38+F39),0) -> 0 | K37: 자세 | L37: FALSE | T37: 1 | U37: 0 | V37: 0 | Y37: =iferror(T39*U39*(W37+W38+W39),0) -> 0 | AB37: 자세 | AC37: FALSE
C38: 2 | D38: =D37 -> 0 | E38: =E37 -> 0 | H38: =iferror(AVERAGE(F37:F39),0) -> 0 | K38: 속도 | L38: FALSE | T38: 2 | U38: =U37 -> 0 | V38: =V37 -> 0 | Y38: =iferror(AVERAGE(W37:W39),0) -> 0 | AB38: 속도 | AC38: FALSE
C39: 3 | D39: =D37 -> 0 | E39: =E37 -> 0 | K39: ROM | L39: FALSE | T39: 3 | U39: =U37 -> 0 | V39: =V37 -> 0 | AB39: ROM | AC39: FALSE
A40: 수업 코멘트 | R40: 수업 코멘트
...
