Workbook

Sheet 000 트레이너
A1: 마른 사람의 마음을 가장 잘 아는 트레이너 'OOO' 입니다
A4: BEFORE ( 59 kg ) | B4: AFTER ( 90 kg ) | C4: 자기 소개
C6: 🏋️‍♂️ 본인을 잘 표현 할 수 있는 대표 1문장 서두에 넣기
C15: 경력 및 자격사항
C17: ✅
C18: ✅
C19: ✅
C20: ✅
C21: ✅
C22: ✅
C23: ✅
C24: ✅
C25: ✅
C26: ✅
C27: ✅
A28: 수업 후기
A30: OO기 회원님 실제후기 | B30: OO기 회원님 실제후기 | C30: OO기 회원님 실제후기

Sheet 성장 기록(주간 미션)의 사본
A1: 성장 기록 일지
A3: 1주차 | B3: 정면 | E3: 측면 | H3: 후면
A25: 2주차 | B25: 정면 | E25: 측면 | H25: 후면
B26: 1. 오른쪽 '+' 버튼 클릭 2. [이미지] 클릭 3. [샐 내 이미지] 클릭 4. 업로드 완료
A47: 3주차 | B47: 정면 | E47: 측면 | H47: 후면
B48: 1. 오른쪽 '+' 버튼 클릭 2. [이미지] 클릭 3. [샐 내 이미지] 클릭 4. 업로드 완료
A69: 4주차 | B69: 정면 | E69: 측면 | H69: 후면
B70: 1. 오른쪽 '+' 버튼 클릭 2. [이미지] 클릭 3. [샐 내 이미지] 클릭 4. 업로드 완료
A91: 5주차 | B91: 정면 | E91: 측면 | H91: 후면
B92: 1. 오른쪽 '+' 버튼 클릭 2. [이미지] 클릭 3. [샐 내 이미지] 클릭 4. 업로드 완료
A113: 6주차 | B113: 정면 | E113: 측면 | H113: 후면
B114: 1. 오른쪽 '+' 버튼 클릭 2. [이미지] 클릭 3. [샐 내 이미지] 클릭 4. 업로드 완료
A135: 7주차 | B135: 정면 | E135: 측면 | H135: 후면
B136: 1. 오른쪽 '+' 버튼 클릭 2. [이미지] 클릭 3. [샐 내 이미지] 클릭 4. 업로드 완료
A157: 8주차 | B157: 정면 | E157: 측면 | H157: 후면
B158: 1. 오른쪽 '+' 버튼 클릭 2. [이미지] 클릭 3. [샐 내 이미지] 클릭 4. 업로드 완료
A179: 9주차 | B179: 정면 | E179: 측면 | H179: 후면
B180: 1. 오른쪽 '+' 버튼 클릭 2. [이미지] 클릭 3. [샐 내 이미지] 클릭 4. 업로드 완료
A201: 10주차 | B201: 정면 | E201: 측면 | H201: 후면
B202: 1. 오른쪽 '+' 버튼 클릭 2. [이미지] 클릭 3. [샐 내 이미지] 클릭 4. 업로드 완료
A223: 11주차 | B223: 정면 | E223: 측면 | H223: 후면
B224: 1. 오른쪽 '+' 버튼 클릭 2. [이미지] 클릭 3. [샐 내 이미지] 클릭 4. 업로드 완료
A245: 12주차 | B245: 정면 | E245: 측면 | H245: 후면
B246: 1. 오른쪽 '+' 버튼 클릭 2. [이미지] 클릭 3. [샐 내 이미지] 클릭 4. 업로드 완료

Sheet 트레이너 소개 (예시)
A1: 마른 사람의 마음을 가장 잘 아는 트레이너 '손재민' 입니다
A4: BEFORE ( 59 kg ) | B4: AFTER ( 90 kg ) | C4: 자기 소개
C6: 🏋️‍♂️ 마른 사람의 마음을 가장 잘 아는 트레이너 과거 저는189cm에 59kg, 정말 말랐던 사람이었습니다. 먹어도 살이 안 오르고, 운동해도 변하지 않아 늘 고민이었죠. 그렇게 몇 년을 시행착오로 보내며 몸을 만들었고, 지금은 90kg이 되었습니다. 그 수많은 시행착오로 오랜 시간 공부하고 경험했습니다. 몇 년의 경험과 노하우를 몇 개월 만에 가르쳐 드리겠습니다.
C15: 경력 및 자격사항
C17: ✅ KACEP(대한운동사협회), KACEP(운동사)
C18: ✅ NASM(미국스포츠의학회), CES(교정운동전문가)
C19: ✅ 대한비만학회, 비만전문가 기초과정(수료)
C20: ✅ (현) 메루치양식장 부산점 대표
C21: ✅ (전) OOO GYM ㅁㅁ점 지점장
C22: ✅ (전) OO핏 ㅇㅇ점 헤드코치
C23: ✅ 마른 사람 200명 코칭
C24: ✅ 60kg >>> 89kg 총 29kg 증량
A28: 수업 후기
A30: 28기 회원님 실제후기 | B30: 24기 회원님 실제후기 | C30: 21기 회원님 실제후기

Sheet 트레이너 소개
A4: BEFORE ( kg ) | B4: AFTER ( kg ) | C4: 자기 소개
C15: 경력 및 자격사항
A28: 수업 후기
A30: OO기 회원님 실제후기 | B30: OO기 회원님 실제후기 | C30: OO기 회원님 실제후기

Sheet 월간 보고서의 (작성 예시)
A1: 홍길동 1월 월간 보고서 | J1: 신체 변화
J4: 체중 | N4: 체지방률 | R4: 근육량
A5: 주요 변화 및 성장 포인트
A8: Before | E8: After
A10: ➀하체 근력 매우 부족 | E10: ➡ 하체 운동 볼륨을 늘었다.
A11: ➁스쿼트 시 다리 안쪽으로 모임 현상 심각 | E11: ➡ 스쿼트 시 무릎이 살짝 안쪽으로 들어가던 부분이 개선되어 자세가 안정되었습니다.
A12: ➂오랜시간 유지 된 불규칙적 식사 습관 | E12: ➡ 아침 결식 빈도를 줄이고, 간식(볼크업) 섭취 타이밍을 일정하게 유지했습니다.
A13: ➃적고 불규칙적인 수면 시간 | E13: ➡ 수면 시간이 6시간 → 7.5시간으로 증가하여 회복력이 향상되었습니다.
A14: ➄등 운동 시 팔로만 자극이 전달 | E14: ➡ 렛풀다운 시 팔 대신 등으로 당기는 감각이 향상 + 등 근육 활성화를 위한 기능성 운동 진행
A15: 성장 데이터 (숫자만 기입 해주세요)
A18: 변화 항목 | B18: 시작 전 | C18: 1달차 | E18: 2달차 | G18: 3달차 | J18: 운동 퍼포먼스
A20: 체중 | B20: 45 | C20: 55 | E20: 65 | G20: 66
J21: 푸쉬업 | N21: 스쿼트 | R21: 랫풀다운
A22: 체지방률 | B22: 7 | C22: 12 | E22: 13 | G22: 13.5
A24: 근육량 | B24: 40 | C24: 41 | E24: 41.5 | G24: 42
A26: 푸쉬업 (횟수) | B26: 15 | C26: 35 | E26: 40 | G26: 41
A28: 스쿼트 (10RM) | B28: 50 | C28: 65 | E28: 75 | G28: 76
A30: 랫풀다운 (10RM) | B30: 40 | C30: 43 | E30: 49 | G30: 50
A32: 가슴 둘레 | B32: 98 | C32: 99 | E32: 102 | G32: 103
A34: 어깨 너비 | B34: 40 | C34: 42 | E34: 44 | G34: 46
A36: 상완 둘레 | B36: 25 | C36: 26 | E36: 27 | G36: 29
A38: 허벅지 둘레 | B38: 50 | C38: 55 | E38: 56 | G38: 57
J39: 부위별 변화
A40: 섭취 칼로리 | B40: 2000 | C40: 2100 | E40: 2300 | G40: 3000
A42: 운동 횟수 (개인운동 포함) | C42: 10 | E42: 20 | G42: 22 | J42: 가슴 둘레 | M42: 어깨 너비 | P42: 상완 둘레 | S42: 허벅지 둘레
A44: 코칭 코멘트
A46: (회원님 운동 사진 첨부) | E46: 이번 달은 회원님께서 벌크업 프로젝트를 시작한 이후, 몸의 반응이 점점 안정되고 성장 속도가 본격적으로 올라가기 시작한 시기였습니다. 다음 달 전체목표는 ‘근육량 +2kg’ 증가와 체형 밸런스 교정을 목표로 진행할 예정입니다. 이를 위해 운동 강도는 10% 정도 상향 조정하고, 식단에서는 단백질 섭취를 140g 수준으로 유지하도록 관리할 예정입니다. 한 달 동안 정말 수고 많으셨습니다. 회원님은 단순히 ‘몸무게를 올리는 것’이 아니라 ‘스스로를 관리하고 변화시키는 힘’을 만들어가고 있습니다. 이번 달의 성장은 그 증거이며, 다음 달엔 그 성장을 더 탄탄하게 쌓아올릴 차례입니다. 💪 다음 3월 달은 2월달 보다는 더 성장하는 재민씨가 됐음 하는 바램입니다!
J59: 기타 변화
J62: 섭취 칼로리 | P62: 운동 횟수
A63: 다음 달 목표
A65: ✅칼로리 추가 500kcal -> 총 2800kcal 섭취
A66: ✅ 운동 빈도수 4회 -> 5회로 늘리기
A67: ✅ 2.6kg 증량하여 누적 증량 총 8kg 달성하기
A68: ✅ 1rm 중량 올리기: 벤치프레스 100kg, 스쿼트 120kg, 데드리프트 150kg
A69: ✅ 평균 수면 시간 8시간 지키기
A71: 000트레이너와, 월간 보고서 '작성 예시'는 확인 후 실사용시에는 삭제해주시기 바랍니다. (아래 탭 오른쪽 클릭-> 삭제 클릭)

Sheet 월간보고서 (예시)
B2: ="📋 "&'월간보고서 (예시)'!Z6&"월 월간 보고서" -> 📋 7월 월간 보고서
V3: 📊 데이터 입력 란
B4: 핵심 변화와 성장 흐름을 한눈에 확인할 수 있는 리포트
B5: 🏋️‍♂️ 핵심 지표 변화 | N5: 📈 섭취 칼로리 | V5: 기본 정보
N6: 시작 전 | O6: 1달차 | P6: 2달차 | Q6: 3달차 | V6: 이름 | W6: 홍길동 | Y6: 보고 월 | Z6: 7
N7: =W25 -> 2100 | O7: =X25 -> 2450 | P7: =Y25 -> 2500 | Q7: =Z25 -> 2790 | V7: 1. 체성분 변화
V8: 항목 | W8: 시작 전 | X8: 1달차 | Y8: 2달차 | Z8: 3달차
N9: 🏆 코칭 코멘트 | V9: 체중 (kg) | W9: 55 | X9: 56 | Y9: 59 | Z9: 63
N10: =W27&" "&W28&" "&W29&" "&W30 -> 이번 달은 전반적으로 체지방 감량과 근육량 증가가 동시에 일어나는 긍정적인 변화를 보였습니다. 식단 관리와 꾸준한 운동이 좋은 결과를 만들어냈습니다. 다음 달에는 하체 근력 향상에 조금 더 집중해 보겠습니다. 화이팅! 섭취 칼로리도 향샹되어 전반적인 변화폭이 컸습니다. | V10: 체지방률 (%) | W10: 0.11 | X10: 0.12 | Y10: 0.15 | Z10: 0.17
V11: 근육량 (kg) | W11: 32 | X11: 35 | Y11: 36 | Z11: 39
V12: 2. 운동 퍼포먼스
V13: 항목 | W13: 시작 전 | X13: 1달차 | Y13: 2달차 | Z13: 3달차
V14: 스쿼트 (kg) | W14: 40 | X14: 45 | Y14: 50 | Z14: 55
V15: 푸쉬업 (횟수) | W15: 10 | X15: 15 | Y15: 20 | Z15: 33
V16: 랫풀다운 (kg) | W16: 30 | X16: 35 | Y16: 42 | Z16: 45.5
V17: 3. 신체 변화 (둘레)
V18: 항목 | W18: 시작 전 | X18: 1달차 | Y18: 2달차 | Z18: 3달차
V19: 가슴 둘레 (cm) | W19: 95 | X19: 96 | Y19: 97 | Z19: 98
V20: 어깨 너비 (cm) | W20: 45 | X20: 46.5 | Y20: 47 | Z20: 49
V21: 상완 둘레 (cm) | W21: 30 | X21: 32 | Y21: 33 | Z21: 35
V22: 허벅지 둘레 (cm) | W22: 55 | X22: 56 | Y22: 57 | Z22: 59
V23: 4. 섭취 칼로리
V24: 항목 | W24: 시작 전 | X24: 1달차 | Y24: 2달차 | Z24: 3달차
V25: 칼로리 (Kcal) | W25: 2100 | X25: 2450 | Y25: 2500 | Z25: 2790
V26: 코칭 코멘트
V27: 1 | W27: 이번 달은 전반적으로 체지방 감량과 근육량 증가가 동시에 일어나는 긍정적인 변화를 보였습니다.
N28: 🎯 다음 달 목표 | V28: 2 | W28: 식단 관리와 꾸준한 운동이 좋은 결과를 만들어냈습니다.
N29: ="🟠 "&'월간보고서 (예시)'!W32 -> 🟠 체지방률 20% 진입 | V29: 3 | W29: 다음 달에는 하체 근력 향상에 조금 더 집중해 보겠습니다. 화이팅!
N30: ="🟠 "&'월간보고서 (예시)'!W33 -> 🟠 스쿼트 65kg 달성 | V30: 4 | W30: 섭취 칼로리도 향샹되어 전반적인 변화폭이 컸습니다.
N31: ="🟠 "&'월간보고서 (예시)'!W34 -> 🟠 주 4회 이상 개인 운동 참석 | V31: 다음 달 목표
N32: ="🟠 "&'월간보고서 (예시)'!W35 -> 🟠 식단 단백질 섭취량 100g 유지 | V32: 1 | W32: 체지방률 20% 진입
N33: ="🟠 "&'월간보고서 (예시)'!W36 -> 🟠 아침 먹기 월 20회 이상 성공하기 | V33: 2 | W33: 스쿼트 65kg 달성
V34: 3 | W34: 주 4회 이상 개인 운동 참석
V35: 4 | W35: 식단 단백질 섭취량 100g 유지
V36: 5 | W36: 아침 먹기 월 20회 이상 성공하기

Sheet 월간 보고서
B2: ="📋 "&'월간 보고서'!Z6&"월 월간 보고서" -> 📋 7월 월간 보고서
V3: 📊 데이터 입력 란
B4: 핵심 변화와 성장 흐름을 한눈에 확인할 수 있는 리포트
B5: 🏋️‍♂️ 핵심 지표 변화 | N5: 📈 섭취 칼로리 | V5: 기본 정보
N6: 시작 전 | O6: 1달차 | P6: 2달차 | Q6: 3달차 | V6: 이름 | W6: 홍길동 | Y6: 보고 월 | Z6: 7
N7: =W25 -> 0 | O7: =X25 -> 0 | P7: =Y25 -> 0 | Q7: =Z25 -> 0 | V7: 1. 체성분 변화
V8: 항목 | W8: 시작 전 | X8: 1달차 | Y8: 2달차 | Z8: 3달차
N9: 🏆 코칭 코멘트 | V9: 체중 (kg) | W9: 0 | X9: 0 | Y9: 0 | Z9: 0
N10: =W27&" "&W28&" "&W29&" "&W30 -> 입력 - - - | V10: 체지방률 (%) | W10: 0 | X10: 0 | Y10: 0 | Z10: 0
V11: 근육량 (kg) | W11: 0 | X11: 0 | Y11: 0 | Z11: 0
V12: 2. 운동 퍼포먼스
V13: 항목 | W13: 시작 전 | X13: 1달차 | Y13: 2달차 | Z13: 3달차
V14: 스쿼트 (kg) | W14: 0 | X14: 0 | Y14: 0 | Z14: 0
V15: 푸쉬업 (횟수) | W15: 0 | X15: 0 | Y15: 0 | Z15: 0
V16: 랫풀다운 (kg) | W16: 0 | X16: 0 | Y16: 0 | Z16: 0
V17: 3. 신체 변화 (둘레)
V18: 항목 | W18: 시작 전 | X18: 1달차 | Y18: 2달차 | Z18: 3달차
V19: 가슴 둘레 (cm) | W19: 0 | X19: 0 | Y19: 0 | Z19: 0
V20: 어깨 너비 (cm) | W20: 0 | X20: 0 | Y20: 0 | Z20: 0
V21: 상완 둘레 (cm) | W21: 0 | X21: 0 | Y21: 0 | Z21: 0
V22: 허벅지 둘레 (cm) | W22: 0 | X22: 0 | Y22: 0 | Z22: 0
V23: 4. 섭취 칼로리
V24: 항목 | W24: 시작 전 | X24: 1달차 | Y24: 2달차 | Z24: 3달차
V25: 칼로리 (Kcal) | W25: 0 | X25: 0 | Y25: 0 | Z25: 0
V26: 코칭 코멘트
V27: 1 | W27: 입력
N28: 🎯 다음 달 목표 | V28: 2 | W28: -
N29: ="🟠 "&'월간 보고서'!W32 -> 🟠 - | V29: 3 | W29: -
N30: ="🟠 "&'월간 보고서'!W33 -> 🟠 - | V30: 4 | W30: -
N31: ="🟠 "&'월간 보고서'!W34 -> 🟠 - | V31: 다음 달 목표
N32: ="🟠 "&'월간 보고서'!W35 -> 🟠 - | V32: 1 | W32: -
N33: ="🟠 "&'월간 보고서'!W36 -> 🟠 - | V33: 2 | W33: -
V34: 3 | W34: -
V35: 4 | W35: -
V36: 5 | W36: -

Sheet 월간 보고서의 사본
B2: ="📋 "&'월간 보고서의 사본'!Z6&"월 월간 보고서" -> 📋 7월 월간 보고서
V3: 📊 데이터 입력 란
B4: 핵심 변화와 성장 흐름을 한눈에 확인할 수 있는 리포트
B5: 🏋️‍♂️ 핵심 지표 변화 | N5: 📈 섭취 칼로리 | V5: 기본 정보
N6: 시작 전 | O6: 1달차 | P6: 2달차 | Q6: 3달차 | V6: 이름 | W6: 홍길동 | Y6: 보고 월 | Z6: 7
N7: =W25 -> 0 | O7: =X25 -> 0 | P7: =Y25 -> 0 | Q7: =Z25 -> 0 | V7: 1. 체성분 변화
V8: 항목 | W8: 시작 전 | X8: 1달차 | Y8: 2달차 | Z8: 3달차
N9: 🏆 코칭 코멘트 | V9: 체중 (kg) | W9: 0 | X9: 0 | Y9: 0 | Z9: 0
N10: =W27&" "&W28&" "&W29&" "&W30 -> 입력 - - - | V10: 체지방률 (%) | W10: 0 | X10: 0 | Y10: 0 | Z10: 0
V11: 근육량 (kg) | W11: 0 | X11: 0 | Y11: 0 | Z11: 0
V12: 2. 운동 퍼포먼스
V13: 항목 | W13: 시작 전 | X13: 1달차 | Y13: 2달차 | Z13: 3달차
V14: 스쿼트 (kg) | W14: 0 | X14: 0 | Y14: 0 | Z14: 0
V15: 푸쉬업 (횟수) | W15: 0 | X15: 0 | Y15: 0 | Z15: 0
V16: 랫풀다운 (kg) | W16: 0 | X16: 0 | Y16: 0 | Z16: 0
V17: 3. 신체 변화 (둘레)
V18: 항목 | W18: 시작 전 | X18: 1달차 | Y18: 2달차 | Z18: 3달차
V19: 가슴 둘레 (cm) | W19: 0 | X19: 0 | Y19: 0 | Z19: 0
V20: 어깨 너비 (cm) | W20: 0 | X20: 0 | Y20: 0 | Z20: 0
V21: 상완 둘레 (cm) | W21: 0 | X21: 0 | Y21: 0 | Z21: 0
V22: 허벅지 둘레 (cm) | W22: 0 | X22: 0 | Y22: 0 | Z22: 0
V23: 4. 섭취 칼로리
V24: 항목 | W24: 시작 전 | X24: 1달차 | Y24: 2달차 | Z24: 3달차
V25: 칼로리 (Kcal) | W25: 0 | X25: 0 | Y25: 0 | Z25: 0
V26: 코칭 코멘트
V27: 1 | W27: 입력
N28: 🎯 다음 달 목표 | V28: 2 | W28: -
N29: ="🟠 "&'월간 보고서의 사본'!W32 -> 🟠 - | V29: 3 | W29: -
N30: ="🟠 "&'월간 보고서의 사본'!W33 -> 🟠 - | V30: 4 | W30: -
N31: ="🟠 "&'월간 보고서의 사본'!W34 -> 🟠 - | V31: 다음 달 목표
N32: ="🟠 "&'월간 보고서의 사본'!W35 -> 🟠 - | V32: 1 | W32: -
N33: ="🟠 "&'월간 보고서의 사본'!W36 -> 🟠 - | V33: 2 | W33: -
V34: 3 | W34: -
V35: 4 | W35: -
V36: 5 | W36: -

Sheet 상태분석 및 목표치 설정(예시)
E1: 이름 | G1: 키 | H1: 체중
E2: 홍길동 | G2: 180 | H2: 60
E4: 직업군 | G4: 나이 | H4: 수면 시간
E5: 사무직 | G5: 27 | H5: 7시간
E7: BMI | F7: 체지방률 | G7: 타입
E8: =ROUND(H2 / (G2/100)^2, 2) -> 18.52 | F8: 11 | G8: B2
E10: 최고 체중(성인 이후) | G10: 최저 체중(성인 이후)
E11: 63 | G11: 50
E13: 운동경력
E14: 웨이트 경력 1년 축구 꾸준히 5년
E17: 특이사항 및 병력
E18: 데드할 때 허리가 불편 스쿼트 할 떄는 무릎 안쪽 통증 위장이 많이 예민함
E21: 섭취중인 영양제 및 복용중인 약물
E22: 크레아틴 4개월 탈모약 1년
E25: 운동 목적 및 방향
E26: 벌크업 | F26: TRUE | G26: 김우빈 같은 몸
E28: 린매스업 | F28: FALSE
E30: 커팅 | F30: FALSE
E32: 목표 체중(kg) | G32: 목표 주당 증량 체중(g)
E33: 70 | G33: =(E33-H2)/12 -> 0.83333333
A35: 가슴 둘레 | B35: 어깨 너비 | C35: 손목 둘레 | D35: 발목 둘레 | E35: 상완 둘레 | G35: 허벅지 둘레
A36: 98 | B36: 40 | C36: 11 | D36: 15 | E36: 30 | G36: 50
A38: 예상 가슴 둘레(최대치) | C38: 예상 전완 둘레(최대치) | E38: 예상 상완 둘레(최대치) | G38: 예상 허벅지 둘레(최대치)
A39: =1.6817*C36+1.3759*D36+0.3314*G2 -> 98.7892 | C39: =0.9626*C36+ 0.0989*G2 -> 28.3906 | E39: =1.2033*C36+0.1236*G2 -> 35.4843 | G39: =1.3868*D36+0.1805*G2 -> 53.292
A42: 코칭에 꼭 반영되었으면 하는 점
A43: 운동 동작 코칭 시 디테일 하게 설명 부탁드립니다.

Sheet 상태 분석 및 목표치 설정
E1: 이름 | G1: 키 | H1: 체중
E4: 직업군 | G4: 나이 | H4: 수면 시간
E7: BMI | F7: 체지방률 | G7: 타입
E8: =IF(OR(G2="", H2=""), "", ROUND(H2 / (G2/100)^2, 2))
E10: 최고 체중(성인 이후) | G10: 최저 체중(성인 이후)
E13: 운동경력
E17: 특이사항 및 병력
E21: 섭취중인 영양제 및 복용중인 약물
E25: 운동 목적 및 방향
E26: 벌크업 | F26: FALSE | G26: 예시)김우빈 같이 어깨가 넓은 몸
E28: 린매스업 | F28: FALSE
E30: 커팅 | F30: FALSE
E32: 목표 체중(kg) | G32: 목표 주당 증량 체중(g)
G33: =IF((E33-H2)=0, "", (E33-H2)/12*1000)
A35: 가슴 둘레 | B35: 어깨 너비 | C35: 손목 둘레 | D35: 발목 둘레 | E35: 상완 둘레 | G35: 허벅지 둘레
A38: 예상 상완 둘레(최대치) | C38: 예상 허벅지 둘레(최대치) | E38: 예상 가슴 둘레(최대치) | G38: 예상 전완 둘레(최대치)
A39: =1.2033*C36+0.1236*G2 -> 0 | C39: =1.3868*D36+0.1805*G2 -> 0 | E39: =1.6817*C36+1.3759*D36+0.3314*G2 -> 0 | G39: =0.9626*C36+ 0.0989*G2 -> 0
A42: 코칭에 꼭 반영되었으면 하는 점
A43: 예시) 운동 동작 코칭 시 디테일 하게 설명 부탁드립니다.

Sheet 상태분석 및 목표치 설정 (예시)
E1: 이름 | G1: 키 | H1: 체중
E2: 홍길동 | G2: 189 | H2: 60
E4: 직업군 | G4: 나이 | H4: 수면 시간
E5: 사무직 | G5: 27 | H5: 8
E7: BMI | F7: 체지방률 | G7: 타입
E8: =IF(OR(G2="", H2=""), "", ROUND(H2 / (G2/100)^2, 2)) -> 16.8 | F8: 12 | G8: B2
E10: 최고 체중(성인 이후) | G10: 최저 체중(성인 이후)
E11: 63 | G11: 50
E13: 운동경력
E14: 웨이트 경력 1년 축구 꾸준히 5년
E17: 특이사항 및 병력
E18: 데드할 때 허리가 불편 스쿼트 할 떄는 무릎 안쪽 통증 위장이 많이 예민함
E21: 섭취중인 영양제 및 복용중인 약물
E22: 크레아틴 4개월 탈모약 1년
E25: 운동 목적 및 방향
E26: 벌크업 | F26: TRUE | G26: 김우빈 같은 몸
K27: 000트레이너, 월간 보고서, 상태 분석 '작성 예시'는 확인 후 실사용시에는 삭제해주시기 바랍니다. (아래 탭 오른쪽 클릭-> 삭제 클릭)
E28: 린매스업 | F28: FALSE
E30: 커팅 | F30: FALSE
E32: 목표 체중(kg) | G32: 목표 주당 증량 체중(g)
E33: 70 | G33: =(E33-H2)/12 -> 0.83333333
A35: 가슴 둘레 | B35: 어깨 너비 | C35: 손목 둘레 | D35: 발목 둘레 | E35: 상완 둘레 | G35: 허벅지 둘레
A36: 95 | B36: 43 | C36: 17 | D36: 22 | E36: 30 | G36: 48
A38: 예상 가슴 둘레(최대치) | C38: 예상 전완 둘레(최대치) | E38: 예상 상완 둘레(최대치) | G38: 예상 허벅지 둘레(최대치)
A39: =1.6817*C36+1.3759*D36+0.3314*G2 -> 121.4933 | C39: =0.9626*C36+ 0.0989*G2 -> 35.0563 | E39: =1.2033*C36+0.1236*G2 -> 43.8165 | G39: =1.3868*D36+0.1805*G2 -> 64.6241
A42: 코칭에 꼭 반영되었으면 하는 점
A43: 운동 동작 코칭 시 디테일 하게 설명 부탁드립니다.

Sheet 식이 분석 및 가이드
B1: 섭취 음식 | D1: 칼로리
A2: 아침 | B2: 시간 :
B3: 빈도 : | H3: 메루치양식장
F10: 참고 및 주의사항
F11: 1. 칼로리가 높은 음식 위주로 카운팅 한다(밥, 육류, 튀김 등)
F12: 2. 즉, 칼로리가 매우 낮은 음식(김치, 나물, 채소 등)은 카운팅 하지 않는다
F13: 3. 식이기록을 진행한다고 해서, 더 먹거나 덜 먹지 않는다
A14: 점심 | B14: 시간 : | F14: 4. 즉, 평소 식이대로 먹는다
B15: 빈도 : | F15: 간식/야식의 정의
F16: 간식 | G16: 아침, 점심, 저녁 사이에 섭취하는 모든 음식
F17: 야식 | G17: 저녁 이후에 먹는 모든 음식
G18: 술 또는 술자리 음식은 모두 여기에 카운팅
A26: 저녁 | B26: 시간 :
B27: 빈도 :
A38: 간식 | B38: 시간 :
B39: 빈도 :
F40: 식사를 얼마나 균등하고 있는지 나타내는 표
F43: 유형 | G43: 형태 | L43: 문제
F44: 폭식형 | G44: 한 끼니에 칼로리가 치중 되어 있음 | L44: 체지방 증가, 폭식으로 인한 다음 끼니 거름
F45: 아점형 | G45: 아침을 거르고 점심으로 때움 | L45: 1끼니의 칼로리(약 500-800)를 버리는 셈
F46: 1일 1식 | G46: 하루에 1끼니만 먹음 | L46: 칼로리 충당 힘듦, 폭식 가능성
F47: 야식형 | G47: 야식 칼로리 높음, 밤 늦게 끼니를 해결함 | L47: 취짐 전 섭취로 체지방 증가, 포만감 지속으로 아침 거름
A48: 야식 | B48: 시간 :
B49: 빈도 :
F50: 타이밍 | G50: 평균 칼로리 | I50: 신뢰도 높은 측정이 마무리 되어야 정확한 값이 나옴
F51: 아침 | G51: =D2 | I51: 1일 소비열량 | K51: =D48+D38+D26+D14+D2 -> 0
F52: 점심 | G52: =D14
F53: 저녁 | G53: =D26
F54: 간식 | G54: =D38
F55: 야식 | G55: =D48
A59: 기상 시간 | B59: -
A61: 취침 시간 | B61: -
A63: 특이 사항 | B63: 1️⃣
B64: 2️⃣
B65: 3️⃣
B66: 4️⃣
B67: 5️⃣
B69: 섭취 음식 | D69: 칼로리
A70: 아침 | B70: 시간 : | D70: 500 | F70: 권장 소비열량 | H70: =K51+500 -> 500
B71: 빈도 :
...

Sheet 체중변화 추이
A1: 날짜 | B1: 섭취칼로리 | C1: 체중 | D1: 주당 평균 체중 | E1: 체중 목표치 | F1: 메모
A2: 46085 | D2: =IF(COUNTIF(C2:C8,">0")=0, "", ROUND(AVERAGEIF(C2:C8,">0"), 1)) | E2: ='상태 분석 및 목표치 설정'!H2
A3: 46086 | E3: =E2 + ($E$92 - $E$2) / 90 -> 0
A4: 46087 | E4: =E3 + ($E$92 - $E$2) / 90 -> 0
A5: 46088 | E5: =E4 + ($E$92 - $E$2) / 90 -> 0
A6: 46089 | E6: =E5 + ($E$92 - $E$2) / 90 -> 0
A7: 46090 | E7: =E6 + ($E$92 - $E$2) / 90 -> 0
A8: 46091 | E8: =E7 + ($E$92 - $E$2) / 90 -> 0 | H8: 목표 섭취 칼로리(kcal)
A9: 46092 | D9: =IF(COUNTIF(C9:C15,">0")=0, "", ROUND(AVERAGEIF(C9:C15,">0"), 1)) | E9: =E8 + ($E$92 - $E$2) / 90 -> 0 | H9: ='식이 분석 및 가이드'!K100 -> 2500
A10: 46093 | E10: =E9 + ($E$92 - $E$2) / 90 -> 0
A11: 46094 | E11: =E10 + ($E$92 - $E$2) / 90 -> 0
A12: 46095 | E12: =E11 + ($E$92 - $E$2) / 90 -> 0
A13: 46096 | E13: =E12 + ($E$92 - $E$2) / 90 -> 0
A14: 46097 | E14: =E13 + ($E$92 - $E$2) / 90 -> 0
A15: 46098 | E15: =E14 + ($E$92 - $E$2) / 90 -> 0
A16: 46099 | D16: =IF(COUNTIF(C16:C22,">0")=0, "", ROUND(AVERAGEIF(C16:C22,">0"), 1)) | E16: =E15 + ($E$92 - $E$2) / 90 -> 0
A17: 46100 | E17: =E16 + ($E$92 - $E$2) / 90 -> 0
A18: 46101 | E18: =E17 + ($E$92 - $E$2) / 90 -> 0
A19: 46102 | E19: =E18 + ($E$92 - $E$2) / 90 -> 0
A20: 46103 | E20: =E19 + ($E$92 - $E$2) / 90 -> 0
A21: 46104 | E21: =E20 + ($E$92 - $E$2) / 90 -> 0
A22: 46105 | E22: =E21 + ($E$92 - $E$2) / 90 -> 0
A23: 46106 | D23: =IF(COUNTIF(C23:C29,">0")=0, "", ROUND(AVERAGEIF(C23:C29,">0"), 1)) | E23: =E22 + ($E$92 - $E$2) / 90 -> 0
A24: 46107 | E24: =E23 + ($E$92 - $E$2) / 90 -> 0
A25: 46108 | E25: =E24 + ($E$92 - $E$2) / 90 -> 0
A26: 46109 | E26: =E25 + ($E$92 - $E$2) / 90 -> 0
A27: 46110 | E27: =E26 + ($E$92 - $E$2) / 90 -> 0
A28: 46111 | E28: =E27 + ($E$92 - $E$2) / 90 -> 0
A29: 46112 | E29: =E28 + ($E$92 - $E$2) / 90 -> 0
A30: 46113 | D30: =IF(COUNTIF(C30:C36,">0")=0, "", ROUND(AVERAGEIF(C30:C36,">0"), 1)) | E30: =E29 + ($E$92 - $E$2) / 90 -> 0
A31: 46114 | E31: =E30 + ($E$92 - $E$2) / 90 -> 0
A32: 46115 | E32: =E31 + ($E$92 - $E$2) / 90 -> 0
A33: 46116 | E33: =E32 + ($E$92 - $E$2) / 90 -> 0
A34: 46117 | E34: =E33 + ($E$92 - $E$2) / 90 -> 0
A35: 46118 | E35: =E34 + ($E$92 - $E$2) / 90 -> 0
A36: 46119 | E36: =E35 + ($E$92 - $E$2) / 90 -> 0
A37: 46120 | D37: =IF(COUNTIF(C37:C43,">0")=0, "", ROUND(AVERAGEIF(C37:C43,">0"), 1)) | E37: =E36 + ($E$92 - $E$2) / 90 -> 0
A38: 46121 | E38: =E37 + ($E$92 - $E$2) / 90 -> 0
A39: 46122 | E39: =E38 + ($E$92 - $E$2) / 90 -> 0 | H39: <오른쪽 세로축 범위 조정 필요> 오른쪽 세로축 더블클릭 -> 최솟값, 최댓값 수정 최소값 현재 체중 -1kg, 최대값 목표 체중 +1kg로 수정하면 적절
A40: 46123 | E40: =E39 + ($E$92 - $E$2) / 90 -> 0
...

Sheet TEST
A1: 테스트 날짜 | C1: 46027 | D1: TEST 프로그램 | J1: 솔루션
A2: 운동명 | C2: 세트 | D2: 중량(kg) | E2: 성공 횟수 | F2: 평균 횟수 | G2: RPE | H2: 문제점
A3: 푸쉬업 | C3: 3세트 실패 지점 까지 진행 | F3: =(E5+E6+E7)/3 -> 0 | H3: 그립 너비 | I3: FALSE
H4: 척추 중립 | I4: FALSE | J4: 고관절 굴곡근 강화 훈련(레그레이즈, 플랭크)
C5: 1 | D5: 0 | E5: 0 | H5: 어깨 위치 | I5: FALSE | J5: 익상증후군 : 푸쉬업 플러스, 윌 슬라이드 | K5: 라운드 숄더 : 견갑골 후인근 강화/소흉근 스트레칭, 와이레이즈
C6: 2 | H6: 가동범위 | I6: FALSE
C7: 3 | H7: 속도 | I7: FALSE | J7: 속도 카운팅
A8: 메모
A10: 랫풀다운 | C10: 3세트 실패 지점 까지 진행 | F10: =(E12+E13+E14)/3 -> 0 | H10: 그립 너비 | I10: FALSE
H11: 척추 중립 | I11: FALSE | J11: 고관절 굴곡근 강화 훈련(레그레이즈, 플랭크)
C12: 1 | D12: 0 | E12: 0 | H12: 팔꿈치 | I12: FALSE | J12: 팔
C13: 2 | H13: 어깨 말림 | I13: FALSE | J13: 익상증후군, 라운드 숄더 교정
C14: 3 | H14: 속도 | I14: FALSE | J14: 속도 카운팅
A15: 메모
A17: 스쿼트 | C17: 3세트 실패 지점 까지 진행 | F17: =(E19+E20+E21)/3 -> 0 | H17: 발 너비 | I17: FALSE
H18: 무릎 방향 | I18: FALSE | J18: 외반슬 : 내로우 스쿼트, 중둔근 강화 훈련
C19: 1 | D19: 0 | E19: 0 | H19: 무게 중심 | I19: FALSE | J19: 발 앞쪽 : 힙힌지 훈련, 발 뒤쪽 : 종아리 스트레칭, 역도화 활용
C20: 2 | H20: 유연성(벗윙크) | I20: FALSE | J20: 내전근/장요근 스트레칭 (2:28 ~4:45) | K20: 척추기립근 강화 훈련
C21: 3 | H21: 속도 | I21: FALSE | J21: 속도 카운팅
A22: 메모

Sheet 운동 전 스트레칭
B1: 스트레칭명 | D1: 세트 | E1: 시간 | F1: 목표 | G1: 진행 | H1: 특이사항
A2: 날짜 | C2: 44202 | D2: 컨디션/특이사항 | F2: (1~10점 중) + 특이사항
A3: 하체 운동 전 | B3: 프로그 (내전근) | D3: 1 | E3: 0 | F3: 1
D4: 2 | E4: =E3 -> 0 | F4: =F3 -> 1
D5: 3 | E5: =E3 -> 0 | F5: =F3 -> 1
B6: 고관절 모빌리티 | D6: 1 | E6: 0 | F6: 5
D7: 2 | E7: =E6 -> 0 | F7: =F6 -> 5
D8: 3 | E8: =E6 -> 0 | F8: =F6 -> 5
B9: 햄스트링 스트레칭 | D9: 1 | E9: 0 | F9: 1
D10: 2 | E10: =E9 -> 0 | F10: =F9 -> 1
D11: 3 | E11: =E9 -> 0 | F11: =F9 -> 1
D12: 1 | E12: 0 | F12: 0
D13: 2 | E13: =E12 -> 0 | F13: =F12 -> 0
D14: 3 | E14: =E12 -> 0 | F14: =F12 -> 0
A15: 상체 운동 전 | B15: 푸쉬업 플러스 (전거근) | D15: 1 | E15: 0 | F15: 1
D16: 2 | E16: =E15 -> 0 | F16: =F15 -> 1
D17: 3 | E17: =E15 -> 0 | F17: =F15 -> 1
B18: 윌 슬라이드 (전거근) | D18: 1 | E18: 0 | F18: 1
D19: 2 | E19: =E18 -> 0 | F19: =F18 -> 1
D20: 3 | E20: =E18 -> 0 | F20: =F18 -> 1
B21: 견갑골 모빌리티 | D21: 1 | E21: 0 | F21: 1
A24: 추가 스트레칭 | D24: 1 | E24: 0 | F24: 1
D25: 2 | E25: =E24 -> 0 | F25: =F24 -> 1
D26: 3 | E26: =E24 -> 0 | F26: =F24 -> 1
D27: 1 | E27: 0 | F27: 1
D28: 2 | E28: =E27 -> 0 | F28: =F27 -> 1
D29: 3 | E29: =E27 -> 0 | F29: =F27 -> 1
D30: 1 | E30: 0 | F30: 1
D31: 2 | E31: =E30 -> 0 | F31: =F30 -> 1
D32: 3 | E32: =E30 -> 0 | F32: =F30 -> 1
D33: 1 | E33: 0 | F33: 1
D34: 2 | E34: =E33 -> 0 | F34: =F33 -> 1
D35: 3 | E35: =E33 -> 0 | F35: =F33 -> 1

Sheet 무분할 프로그램(1~4주차)
A1: 무분할 프로그램 | C1: 특이사항 | E1: *작성 팁* 수업 전 체크해야할 회원님의 특이사항 / 해당 프로그램 사용 시 달성 목표를 기입
A2: 운동명/반복구간 | C2: 세트 | D2: 중량 | E2: 목표 | F2: 성공 | G2: RPE | H2: V/A | I2: 속도 | J2: 휴식 | K2: 체크리스트 | M2: 메모
A3: 날짜 | B3: 46027 | C3: 당일 컨디션 | E3: 최상 | F3: FALSE | G3: 상 | H3: FALSE | I3: 중 | J3: FALSE | K3: 하 | L3: FALSE | M3: 수업 | N3: FALSE | O3: 과제 | P3: FALSE
A4: 푸쉬업 | C4: 1 | D4: 0 | E4: =TEST!F3 -> 0 | H4: =iferror(C6*D6*(F4+F5+F6),0) -> 0 | I4: 2 | J4: 60 | K4: 자세 | L4: FALSE
C5: 2 | D5: =D4 -> 0 | E5: =E4 -> 0 | H5: =iferror(AVERAGE(F4:F6),0) -> 0 | I5: 0 | K5: 속도 | L5: FALSE
A6: 0 | B6: 100 | C6: 3 | D6: =D4 -> 0 | E6: =E4 -> 0 | I6: 1 | K6: ROM | L6: FALSE
A7: 스미스머신 벤치프레스 | C7: 1 | D7: 0 | E7: 0 | H7: =iferror(C9*D9*(F7+F8+F9),0) -> 0 | I7: 2 | J7: 60 | K7: 자세 | L7: FALSE
C8: 2 | D8: =D7 -> 0 | E8: =E7 -> 0 | H8: =iferror(AVERAGE(F7:F9),0) -> 0 | I8: 0 | K8: 속도 | L8: FALSE
A9: 8 | B9: 12 | C9: 3 | D9: =D7 -> 0 | E9: =E7 -> 0 | I9: 1 | K9: ROM | L9: FALSE
A10: 랫풀다운 | C10: 1 | D10: 0 | E10: 0 | H10: =iferror(C12*D12*(F10+F11+F12),0) -> 0 | I10: 2 | J10: 60 | K10: 자세 | L10: FALSE
C11: 2 | D11: =D10 -> 0 | E11: =E10 -> 0 | H11: =iferror(AVERAGE(F10:F12),0) -> 0 | I11: 1 | K11: 속도 | L11: FALSE
A12: 8 | B12: 12 | C12: 3 | D12: =D10 -> 0 | E12: =E10 -> 0 | I12: 1 | K12: ROM | L12: FALSE
A13: 케이블로우 | C13: 1 | D13: 0 | E13: 0 | H13: =iferror(C15*D15*(F13+F14+F15),0) -> 0 | I13: 2 | J13: 60 | K13: 자세 | L13: FALSE
C14: 2 | D14: =D13 -> 0 | E14: =E13 -> 0 | H14: =iferror(AVERAGE(F13:F15),0) -> 0 | I14: 0 | K14: 속도 | L14: FALSE
A15: 8 | B15: 12 | C15: 3 | D15: =D13 -> 0 | E15: =E13 -> 0 | I15: 1 | K15: ROM | L15: FALSE
A16: 스쿼트 | C16: 1 | D16: 0 | E16: 0 | H16: =iferror(C18*D18*(F16+F17+F18),0) -> 0 | I16: 3 | J16: 90 | K16: 자세 | L16: FALSE
C17: 2 | D17: =D16 -> 0 | E17: =E16 -> 0 | H17: =iferror(AVERAGE(F16:F18),0) -> 0 | I17: 1 | K17: 속도 | L17: FALSE
A18: 8 | B18: 12 | C18: 3 | D18: =D16 -> 0 | E18: =E16 -> 0 | I18: 2 | K18: ROM | L18: FALSE
A19: 런지 | C19: 1 | D19: 0 | E19: 0 | H19: =iferror(C21*D21*(F19+F20+F21),0) -> 0 | I19: 2 | J19: 60 | K19: 자세 | L19: FALSE
C20: 2 | D20: =D19 -> 0 | E20: =E19 -> 0 | H20: =iferror(AVERAGE(F19:F21),0) -> 0 | I20: 0 | K20: 속도 | L20: FALSE
A21: 8 | B21: 12 | C21: 3 | D21: =D19 -> 0 | E21: =E19 -> 0 | I21: 1 | K21: ROM | L21: FALSE
A22: 힙쓰러스트 | C22: 1 | D22: 0 | E22: 0 | H22: =iferror(C24*D24*(F22+F23+F24),0) -> 0 | I22: 2 | J22: 90 | K22: 자세 | L22: FALSE
C23: 2 | D23: =D22 -> 0 | E23: =E22 -> 0 | H23: =iferror(AVERAGE(F22:F24),0) -> 0 | I23: 0 | K23: 속도 | L23: FALSE
A24: 8 | B24: 12 | C24: 3 | D24: =D22 -> 0 | E24: =E22 -> 0 | I24: 1 | K24: ROM | L24: FALSE
A25: 힙익스텐션 | C25: 1 | D25: 0 | E25: 0 | H25: =iferror(C27*D27*(F25+F26+F27),0) -> 0 | I25: 2 | J25: 60 | K25: 자세 | L25: FALSE
C26: 2 | D26: =D25 -> 0 | E26: =E25 -> 0 | H26: =iferror(AVERAGE(F25:F27),0) -> 0 | I26: 0 | K26: 속도 | L26: FALSE
A27: 8 | B27: 12 | C27: 3 | D27: =D25 -> 0 | E27: =E25 -> 0 | I27: 1 | K27: ROM | L27: FALSE
A28: 덤벨컬 | C28: 1 | D28: 0 | E28: 0 | H28: =iferror(C30*D30*(F28+F29+F30),0) -> 0 | I28: 2 | J28: 60 | K28: 자세 | L28: FALSE
C29: 2 | D29: =D28 -> 0 | E29: =E28 -> 0 | H29: =iferror(AVERAGE(F28:F30),0) -> 0 | I29: 0 | K29: 속도 | L29: FALSE
A30: 8 | B30: 12 | C30: 3 | D30: =D28 -> 0 | E30: =E28 -> 0 | I30: 1 | K30: ROM | L30: FALSE
A31: 케이블 푸쉬다운 | C31: 1 | D31: 0 | E31: 0 | H31: =iferror(C33*D33*(F31+F32+F33),0) -> 0 | I31: 2 | J31: 60 | K31: 자세 | L31: FALSE
C32: 2 | D32: =D31 -> 0 | E32: =E31 -> 0 | H32: =iferror(AVERAGE(F31:F33),0) -> 0 | I32: 0 | K32: 속도 | L32: FALSE
A33: 8 | B33: 12 | C33: 3 | D33: =D31 -> 0 | E33: =E31 -> 0 | I33: 1 | K33: ROM | L33: FALSE
A34: 수업 코멘트

Sheet 2분할 프로그램(5~8주차)
A1: 2분할 상체 | C1: 특이사항 | E1: *작성 팁* 수업 전 체크해야할 회원님의 특이사항 / 해당 프로그램 사용 시 달성 목표를 기입 | R1: 2분할 하체 | T1: 특이사항 | V1: *작성 팁* 수업 전 체크해야할 회원님의 특이사항 / 해당 프로그램 사용 시 달성 목표를 기입
A2: 운동명/반복구간 | C2: 세트 | D2: 중량 | E2: 목표 | F2: 성공 | G2: RPE | H2: V/A | I2: 속도 | J2: 휴식 | K2: 체크리스트 | M2: 메모 | R2: 운동명/반복구간 | T2: 세트 | U2: 중량 | V2: 목표 | W2: 성공 | X2: RPE | Y2: V/A | Z2: 속도 | AA2: 휴식 | AB2: 체크리스트 | AD2: 메모
A3: 날짜 | B3: 46027 | C3: 당일 컨디션 | E3: 최상 | F3: FALSE | G3: 상 | H3: FALSE | I3: 중 | J3: FALSE | K3: 하 | L3: FALSE | M3: 수업 | N3: FALSE | O3: 과제 | P3: FALSE | R3: 날짜 | S3: 46027 | T3: 당일 컨디션 | V3: 최상 | W3: FALSE | X3: 상 | Y3: FALSE | Z3: 중 | AA3: FALSE | AB3: 하 | AC3: FALSE | AD3: 수업 | AE3: FALSE | AF3: 과제 | AG3: FALSE
A4: 스미스머신 벤치프레스 | C4: 1 | D4: 0 | E4: 0 | H4: =iferror(C6*D6*(F4+F5+F6),0) -> 0 | I4: 2 | J4: 60 | K4: 자세 | L4: FALSE | M4: 줄 바꿈 = alt + enter | R4: 스쿼트 | T4: 1 | U4: 0 | V4: 0 | Y4: =iferror(T6*U6*(W4+W5+W6),0) -> 0 | Z4: 2 | AA4: 90 | AB4: 자세 | AC4: FALSE | AD4: 줄 바꿈 = alt + enter
C5: 2 | D5: =D4 -> 0 | E5: =E4 -> 0 | H5: =iferror(AVERAGE(F4:F6),0) -> 0 | I5: 0 | K5: 속도 | L5: FALSE | T5: 2 | U5: =U4 -> 0 | V5: =V4 -> 0 | Y5: =iferror(AVERAGE(W4:W6),0) -> 0 | Z5: 1 | AB5: 속도 | AC5: FALSE
A6: 8 | B6: 12 | C6: 3 | D6: =D4 -> 0 | E6: =E4 -> 0 | I6: 1 | K6: ROM | L6: FALSE | R6: 6 | S6: 10 | T6: 3 | U6: =U4 -> 0 | V6: =V4 -> 0 | Z6: 2 | AB6: ROM | AC6: FALSE
A7: 푸쉬업 | C7: 1 | D7: 0 | E7: 0 | H7: =iferror(C9*D9*(F7+F8+F9),0) -> 0 | I7: 2 | J7: 60 | K7: 자세 | L7: FALSE | R7: 스미스머신 런지 | T7: 1 | U7: 0 | V7: 0 | Y7: =iferror(T9*U9*(W7+W8+W9),0) -> 0 | Z7: 2 | AA7: 60 | AB7: 자세 | AC7: FALSE
C8: 2 | D8: =D7 -> 0 | E8: =E7 -> 0 | H8: =iferror(AVERAGE(F7:F9),0) -> 0 | I8: 0 | K8: 속도 | L8: FALSE | T8: 2 | U8: =U7 -> 0 | V8: =V7 -> 0 | Y8: =iferror(AVERAGE(W7:W9),0) -> 0 | Z8: 0 | AB8: 속도 | AC8: FALSE
A9: 0 | B9: 100 | C9: 3 | D9: =D7 -> 0 | E9: =E7 -> 0 | I9: 1 | K9: ROM | L9: FALSE | R9: 8 | S9: 12 | T9: 3 | U9: =U7 -> 0 | V9: =V7 -> 0 | Z9: 1 | AB9: ROM | AC9: FALSE
A10: 케이블 크로스오버 | C10: 1 | D10: 0 | E10: 0 | H10: =iferror(C12*D12*(F10+F11+F12),0) -> 0 | I10: 2 | J10: 60 | K10: 자세 | L10: FALSE | R10: 루마니안 데드리프트 | T10: 1 | U10: 0 | V10: 0 | Y10: =iferror(T12*U12*(W10+W11+W12),0) -> 0 | Z10: 2 | AA10: 60 | AB10: 자세 | AC10: FALSE
C11: 2 | D11: =D10 -> 0 | E11: =E10 -> 0 | H11: =iferror(AVERAGE(F10:F12),0) -> 0 | I11: 1 | K11: 속도 | L11: FALSE | T11: 2 | U11: =U10 -> 0 | V11: =V10 -> 0 | Y11: =iferror(AVERAGE(W10:W12),0) -> 0 | Z11: 0 | AB11: 속도 | AC11: FALSE
A12: 12 | B12: 20 | C12: 3 | D12: =D10 -> 0 | E12: =E10 -> 0 | I12: 1 | K12: ROM | L12: FALSE | R12: 8 | S12: 12 | T12: 3 | U12: =U10 -> 0 | V12: =V10 -> 0 | Z12: 1 | AB12: ROM | AC12: FALSE
A13: 랫풀다운 | C13: 1 | D13: 0 | E13: 0 | H13: =iferror(C15*D15*(F13+F14+F15),0) -> 0 | I13: 2 | J13: 60 | K13: 자세 | L13: FALSE | R13: 레그 익스텐션 | T13: 1 | U13: 0 | V13: 0 | Y13: =iferror(T15*U15*(W13+W14+W15),0) -> 0 | Z13: 2 | AA13: 60 | AB13: 자세 | AC13: FALSE
C14: 2 | D14: =D13 -> 0 | E14: =E13 -> 0 | H14: =iferror(AVERAGE(F13:F15),0) -> 0 | I14: 1 | K14: 속도 | L14: FALSE | T14: 2 | U14: =U13 -> 0 | V14: =V13 -> 0 | Y14: =iferror(AVERAGE(W13:W15),0) -> 0 | Z14: 1 | AB14: 속도 | AC14: FALSE
A15: 8 | B15: 12 | C15: 3 | D15: =D13 -> 0 | E15: =E13 -> 0 | I15: 1 | K15: ROM | L15: FALSE | R15: 10 | S15: 15 | T15: 3 | U15: =U13 -> 0 | V15: =V13 -> 0 | Z15: 1 | AB15: ROM | AC15: FALSE
A16: 케이블로우 | C16: 1 | D16: 0 | E16: 0 | H16: =iferror(C18*D18*(F16+F17+F18),0) -> 0 | I16: 2 | J16: 60 | K16: 자세 | L16: FALSE | R16: 레그컬 | T16: 1 | U16: 0 | V16: 0 | Y16: =iferror(T18*U18*(W16+W17+W18),0) -> 0 | Z16: 2 | AA16: 60 | AB16: 자세 | AC16: FALSE
C17: 2 | D17: =D16 -> 0 | E17: =E16 -> 0 | H17: =iferror(AVERAGE(F16:F18),0) -> 0 | I17: 1 | K17: 속도 | L17: FALSE | T17: 2 | U17: =U16 -> 0 | V17: =V16 -> 0 | Y17: =iferror(AVERAGE(W16:W18),0) -> 0 | Z17: 0 | AB17: 속도 | AC17: FALSE
A18: 8 | B18: 12 | C18: 3 | D18: =D16 -> 0 | E18: =E16 -> 0 | I18: 1 | K18: ROM | L18: FALSE | R18: 10 | S18: 15 | T18: 3 | U18: =U16 -> 0 | V18: =V16 -> 0 | Z18: 1 | AB18: ROM | AC18: FALSE
A19: 암풀다운 | C19: 1 | D19: 0 | E19: 0 | H19: =iferror(C21*D21*(F19+F20+F21),0) -> 0 | I19: 2 | J19: 60 | K19: 자세 | L19: FALSE | T19: 1 | U19: 0 | V19: 0 | Y19: =iferror(T21*U21*(W19+W20+W21),0) -> 0 | AA19: 60 | AB19: 자세 | AC19: FALSE
C20: 2 | D20: =D19 -> 0 | E20: =E19 -> 0 | H20: =iferror(AVERAGE(F19:F21),0) -> 0 | I20: 1 | K20: 속도 | L20: FALSE | T20: 2 | U20: =U19 -> 0 | V20: =V19 -> 0 | Y20: =iferror(AVERAGE(W19:W21),0) -> 0 | AB20: 속도 | AC20: FALSE
A21: 12 | B21: 20 | C21: 3 | D21: =D19 -> 0 | E21: =E19 -> 0 | I21: 1 | K21: ROM | L21: FALSE | T21: 3 | U21: =U19 -> 0 | V21: =V19 -> 0 | AB21: ROM | AC21: FALSE
A22: 바벨컬 | C22: 1 | D22: 0 | E22: 0 | H22: =iferror(C24*D24*(F22+F23+F24),0) -> 0 | I22: 2 | J22: 60 | K22: 자세 | L22: FALSE | R22: 덤벨 숄더 프레스 | T22: 1 | U22: 0 | V22: 0 | Y22: =iferror(T24*U24*(W22+W23+W24),0) -> 0 | Z22: 2 | AA22: 60 | AB22: 자세 | AC22: FALSE
C23: 2 | D23: =D22 -> 0 | E23: =E22 -> 0 | H23: =iferror(AVERAGE(F22:F24),0) -> 0 | I23: 0 | K23: 속도 | L23: FALSE | T23: 2 | U23: =U22 -> 0 | V23: =V22 -> 0 | Y23: =iferror(AVERAGE(W22:W24),0) -> 0 | Z23: 0 | AB23: 속도 | AC23: FALSE
A24: 8 | B24: 12 | C24: 3 | D24: =D22 -> 0 | E24: =E22 -> 0 | I24: 1 | K24: ROM | L24: FALSE | R24: 8 | S24: 12 | T24: 3 | U24: =U22 -> 0 | V24: =V22 -> 0 | Z24: 1 | AB24: ROM | AC24: FALSE
A25: 라트익 | C25: 1 | D25: 0 | E25: 0 | H25: =iferror(C27*D27*(F25+F26+F27),0) -> 0 | I25: 2 | J25: 60 | K25: 자세 | L25: FALSE | R25: 레터럴 레이즈 | T25: 1 | U25: 0 | V25: 0 | Y25: =iferror(T27*U27*(W25+W26+W27),0) -> 0 | Z25: 2 | AA25: 60 | AB25: 자세 | AC25: FALSE
C26: 2 | D26: =D25 -> 0 | E26: =E25 -> 0 | H26: =iferror(AVERAGE(F25:F27),0) -> 0 | I26: 0 | K26: 속도 | L26: FALSE | T26: 2 | U26: =U25 -> 0 | V26: =V25 -> 0 | Y26: =iferror(AVERAGE(W25:W27),0) -> 0 | Z26: 0 | AB26: 속도 | AC26: FALSE
A27: 8 | B27: 12 | C27: 3 | D27: =D25 -> 0 | E27: =E25 -> 0 | I27: 1 | K27: ROM | L27: FALSE | R27: 12 | S27: 20 | T27: 3 | U27: =U25 -> 0 | V27: =V25 -> 0 | Z27: 1 | AB27: ROM | AC27: FALSE
A28: 추가 팔운동1 | C28: 1 | D28: 0 | E28: 0 | H28: =iferror(C30*D30*(F28+F29+F30),0) -> 0 | K28: 자세 | L28: FALSE | R28: 벤트오버 레터럴레이즈 | T28: 1 | U28: 0 | V28: 0 | Y28: =iferror(T30*U30*(W28+W29+W30),0) -> 0 | Z28: 2 | AA28: 60 | AB28: 자세 | AC28: FALSE
C29: 2 | D29: =D28 -> 0 | E29: =E28 -> 0 | H29: =iferror(AVERAGE(F28:F30),0) -> 0 | K29: 속도 | L29: FALSE | T29: 2 | U29: =U28 -> 0 | V29: =V28 -> 0 | Y29: =iferror(AVERAGE(W28:W30),0) -> 0 | Z29: 0 | AB29: 속도 | AC29: FALSE
A30: 8 | B30: 12 | C30: 3 | D30: =D28 -> 0 | E30: =E28 -> 0 | K30: ROM | L30: FALSE | T30: 3 | U30: =U28 -> 0 | V30: =V28 -> 0 | Z30: 1 | AB30: ROM | AC30: FALSE
A31: 추가 팔운동2 | C31: 1 | D31: 0 | E31: 0 | H31: =iferror(C33*D33*(F31+F32+F33),0) -> 0 | K31: 자세 | L31: FALSE | T31: 1 | U31: 0 | V31: 0 | Y31: =iferror(T33*U33*(W31+W32+W33),0) -> 0 | AB31: 자세 | AC31: FALSE
C32: 2 | D32: =D31 -> 0 | E32: =E31 -> 0 | H32: =iferror(AVERAGE(F31:F33),0) -> 0 | K32: 속도 | L32: FALSE | T32: 2 | U32: =U31 -> 0 | V32: =V31 -> 0 | Y32: =iferror(AVERAGE(W31:W33),0) -> 0 | AB32: 속도 | AC32: FALSE
A33: 8 | B33: 12 | C33: 3 | D33: =D31 -> 0 | E33: =E31 -> 0 | K33: ROM | L33: FALSE | T33: 3 | U33: =U31 -> 0 | V33: =V31 -> 0 | AB33: ROM | AC33: FALSE
A34: 수업 코멘트 | R34: 수업 코멘트

Sheet 2분할AB 프로그램(9~12주차) 상체
A1: 2분할 상체 A | C1: 특이사항 | E1: *작성 팁* 수업 전 체크해야할 회원님의 특이사항 / 해당 프로그램 사용 시 달성 목표를 기입 | R1: 2분할 상체 B | T1: 특이사항 | V1: *작성 팁* 수업 전 체크해야할 회원님의 특이사항 / 해당 프로그램 사용 시 달성 목표를 기입
A2: 운동명/반복구간 | C2: 세트 | D2: 중량 | E2: 목표 | F2: 성공 | G2: RPE | H2: V/A | I2: 속도 | J2: 휴식 | K2: 체크리스트 | M2: 메모 | R2: 운동명/반복구간 | T2: 세트 | U2: 중량 | V2: 목표 | W2: 성공 | X2: RPE | Y2: V/A | Z2: 속도 | AA2: 휴식 | AB2: 체크리스트 | AD2: 메모
A3: 날짜 | B3: 46027 | C3: 당일 컨디션 | E3: 최상 | F3: FALSE | G3: 상 | H3: FALSE | I3: 중 | J3: FALSE | K3: 하 | L3: FALSE | M3: 수업 | N3: FALSE | O3: 과제 | P3: FALSE | R3: 날짜 | S3: 46027 | T3: 당일 컨디션 | V3: 최상 | W3: FALSE | X3: 상 | Y3: FALSE | Z3: 중 | AA3: FALSE | AB3: 하 | AC3: FALSE | AD3: 수업 | AE3: FALSE | AF3: 과제 | AG3: FALSE
A4: 벤치프레스 | C4: 1 | D4: 0 | E4: 0 | H4: =iferror(C6*D6*(F4+F5+F6),0) -> 0 | I4: 2 | J4: 90 | K4: 자세 | L4: FALSE | M4: 줄 바꿈 = alt + enter | R4: 인클라인 벤치프레스 | T4: 1 | U4: 0 | V4: 0 | Y4: =iferror(T6*U6*(W4+W5+W6),0) -> 0 | Z4: 2 | AA4: 60 | AB4: 자세 | AC4: FALSE | AD4: 줄 바꿈 = alt + enter
C5: 2 | D5: =D4 -> 0 | E5: =E4 -> 0 | H5: =iferror(AVERAGE(F4:F6),0) -> 0 | I5: 0 | K5: 속도 | L5: FALSE | T5: 2 | U5: =U4 -> 0 | V5: =V4 -> 0 | Y5: =iferror(AVERAGE(W4:W6),0) -> 0 | Z5: 0 | AB5: 속도 | AC5: FALSE
A6: 2 | B6: 5 | C6: 3 | D6: =D4 -> 0 | E6: =E4 -> 0 | I6: 1 | K6: ROM | L6: FALSE | R6: 6 | S6: 10 | T6: 3 | U6: =U4 -> 0 | V6: =V4 -> 0 | Z6: 1 | AB6: ROM | AC6: FALSE
A7: 딥스 | C7: 1 | D7: 0 | E7: 0 | H7: =iferror(C9*D9*(F7+F8+F9),0) -> 0 | I7: 2 | J7: 60 | K7: 자세 | L7: FALSE | R7: 덤벨프레스 | T7: 1 | U7: 0 | V7: 0 | Y7: =iferror(T9*U9*(W7+W8+W9),0) -> 0 | Z7: 2 | AA7: 60 | AB7: 자세 | AC7: FALSE
C8: 2 | D8: =D7 -> 0 | E8: =E7 -> 0 | H8: =iferror(AVERAGE(F7:F9),0) -> 0 | I8: 0 | K8: 속도 | L8: FALSE | T8: 2 | U8: =U7 -> 0 | V8: =V7 -> 0 | Y8: =iferror(AVERAGE(W7:W9),0) -> 0 | Z8: 0 | AB8: 속도 | AC8: FALSE
A9: 6 | B9: 10 | C9: 3 | D9: =D7 -> 0 | E9: =E7 -> 0 | I9: 1 | K9: ROM | L9: FALSE | R9: 8 | S9: 12 | T9: 3 | U9: =U7 -> 0 | V9: =V7 -> 0 | Z9: 1 | AB9: ROM | AC9: FALSE
A10: 스미스 머신 벤치프레스(체스트프레스) | C10: 1 | D10: 0 | E10: 0 | H10: =iferror(C12*D12*(F10+F11+F12),0) -> 0 | I10: 2 | J10: 60 | K10: 자세 | L10: FALSE | R10: 스미스 머신 벤치프레스(체스트프레스) | T10: 1 | U10: 0 | V10: 0 | Y10: =iferror(T12*U12*(W10+W11+W12),0) -> 0 | Z10: 2 | AA10: 60 | AB10: 자세 | AC10: FALSE
C11: 2 | D11: =D10 -> 0 | E11: =E10 -> 0 | H11: =iferror(AVERAGE(F10:F12),0) -> 0 | I11: 1 | K11: 속도 | L11: FALSE | T11: 2 | U11: =U10 -> 0 | V11: =V10 -> 0 | Y11: =iferror(AVERAGE(W10:W12),0) -> 0 | Z11: 1 | AB11: 속도 | AC11: FALSE
A12: 8 | B12: 12 | C12: 3 | D12: =D10 -> 0 | E12: =E10 -> 0 | I12: 1 | K12: ROM | L12: FALSE | R12: 8 | S12: 12 | T12: 3 | U12: =U10 -> 0 | V12: =V10 -> 0 | Z12: 1 | AB12: ROM | AC12: FALSE
A13: 덤벨 플라이 | C13: 1 | D13: 0 | E13: 0 | H13: =iferror(C15*D15*(F13+F14+F15),0) -> 0 | I13: 2 | J13: 60 | K13: 자세 | L13: FALSE | R13: 케이블 크로스 오버 | T13: 1 | U13: 0 | V13: 0 | Y13: =iferror(T15*U15*(W13+W14+W15),0) -> 0 | Z13: 2 | AA13: 60 | AB13: 자세 | AC13: FALSE
C14: 2 | D14: =D13 -> 0 | E14: =E13 -> 0 | H14: =iferror(AVERAGE(F13:F15),0) -> 0 | I14: 1 | K14: 속도 | L14: FALSE | T14: 2 | U14: =U13 -> 0 | V14: =V13 -> 0 | Y14: =iferror(AVERAGE(W13:W15),0) -> 0 | Z14: 1 | AB14: 속도 | AC14: FALSE
A15: 10 | B15: 15 | C15: 3 | D15: =D13 -> 0 | E15: =E13 -> 0 | I15: 1 | K15: ROM | L15: FALSE | R15: 12 | S15: 20 | T15: 3 | U15: =U13 -> 0 | V15: =V13 -> 0 | Z15: 1 | AB15: ROM | AC15: FALSE
A16: 바벨로우 | C16: 1 | D16: 0 | E16: 0 | H16: =iferror(C18*D18*(F16+F17+F18),0) -> 0 | I16: 2 | J16: 60 | K16: 자세 | L16: FALSE | R16: 원암덤벨로우 | T16: 1 | U16: 0 | V16: 0 | Y16: =iferror(T18*U18*(W16+W17+W18),0) -> 0 | Z16: 2 | AA16: 60 | AB16: 자세 | AC16: FALSE
C17: 2 | D17: =D16 -> 0 | E17: =E16 -> 0 | H17: =iferror(AVERAGE(F16:F18),0) -> 0 | I17: 1 | K17: 속도 | L17: FALSE | T17: 2 | U17: =U16 -> 0 | V17: =V16 -> 0 | Y17: =iferror(AVERAGE(W16:W18),0) -> 0 | Z17: 1 | AB17: 속도 | AC17: FALSE
A18: 6 | B18: 10 | C18: 3 | D18: =D16 -> 0 | E18: =E16 -> 0 | I18: 1 | K18: ROM | L18: FALSE | R18: 8 | S18: 12 | T18: 3 | U18: =U16 -> 0 | V18: =V16 -> 0 | Z18: 1 | AB18: ROM | AC18: FALSE
A19: 랫풀다운 | C19: 1 | D19: 0 | E19: 0 | H19: =iferror(C21*D21*(F19+F20+F21),0) -> 0 | I19: 2 | J19: 60 | K19: 자세 | L19: FALSE | R19: 언더그립 랫풀다운 | T19: 1 | U19: 0 | V19: 0 | Y19: =iferror(T21*U21*(W19+W20+W21),0) -> 0 | Z19: 2 | AA19: 60 | AB19: 자세 | AC19: FALSE
C20: 2 | D20: =D19 -> 0 | E20: =E19 -> 0 | H20: =iferror(AVERAGE(F19:F21),0) -> 0 | I20: 1 | K20: 속도 | L20: FALSE | T20: 2 | U20: =U19 -> 0 | V20: =V19 -> 0 | Y20: =iferror(AVERAGE(W19:W21),0) -> 0 | Z20: 1 | AB20: 속도 | AC20: FALSE
A21: 6 | B21: 10 | C21: 3 | D21: =D19 -> 0 | E21: =E19 -> 0 | I21: 1 | K21: ROM | L21: FALSE | R21: 8 | S21: 12 | T21: 3 | U21: =U19 -> 0 | V21: =V19 -> 0 | Z21: 1 | AB21: ROM | AC21: FALSE
A22: 케이블로우 | C22: 1 | D22: 0 | E22: 0 | H22: =iferror(C24*D24*(F22+F23+F24),0) -> 0 | I22: 2 | J22: 60 | K22: 자세 | L22: FALSE | R22: 케이블 로우 | T22: 1 | U22: 0 | V22: 0 | Y22: =iferror(T24*U24*(W22+W23+W24),0) -> 0 | Z22: 2 | AA22: 60 | AB22: 자세 | AC22: FALSE
C23: 2 | D23: =D22 -> 0 | E23: =E22 -> 0 | H23: =iferror(AVERAGE(F22:F24),0) -> 0 | I23: 1 | K23: 속도 | L23: FALSE | T23: 2 | U23: =U22 -> 0 | V23: =V22 -> 0 | Y23: =iferror(AVERAGE(W22:W24),0) -> 0 | Z23: 1 | AB23: 속도 | AC23: FALSE
A24: 8 | B24: 12 | C24: 3 | D24: =D22 -> 0 | E24: =E22 -> 0 | I24: 1 | K24: ROM | L24: FALSE | R24: 8 | S24: 12 | T24: 3 | U24: =U22 -> 0 | V24: =V22 -> 0 | Z24: 1 | AB24: ROM | AC24: FALSE
A25: 암풀다운 | C25: 1 | D25: 0 | E25: 0 | H25: =iferror(C27*D27*(F25+F26+F27),0) -> 0 | I25: 2 | J25: 60 | K25: 자세 | L25: FALSE | R25: 암풀다운 | T25: 1 | U25: 0 | V25: 0 | Y25: =iferror(T27*U27*(W25+W26+W27),0) -> 0 | Z25: 2 | AA25: 60 | AB25: 자세 | AC25: FALSE
C26: 2 | D26: =D25 -> 0 | E26: =E25 -> 0 | H26: =iferror(AVERAGE(F25:F27),0) -> 0 | I26: 0 | K26: 속도 | L26: FALSE | T26: 2 | U26: =U25 -> 0 | V26: =V25 -> 0 | Y26: =iferror(AVERAGE(W25:W27),0) -> 0 | Z26: 0 | AB26: 속도 | AC26: FALSE
A27: 10 | B27: 15 | C27: 3 | D27: =D25 -> 0 | E27: =E25 -> 0 | I27: 1 | K27: ROM | L27: FALSE | R27: 12 | S27: 20 | T27: 3 | U27: =U25 -> 0 | V27: =V25 -> 0 | Z27: 1 | AB27: ROM | AC27: FALSE
A28: 바벨컬 | C28: 1 | D28: 0 | E28: 0 | H28: =iferror(C30*D30*(F28+F29+F30),0) -> 0 | I28: 2 | J28: 60 | K28: 자세 | L28: FALSE | R28: 덤벨컬 | T28: 1 | U28: 0 | V28: 0 | Y28: =iferror(T30*U30*(W28+W29+W30),0) -> 0 | Z28: 2 | AA28: 60 | AB28: 자세 | AC28: FALSE
C29: 2 | D29: =D28 -> 0 | E29: =E28 -> 0 | H29: =iferror(AVERAGE(F28:F30),0) -> 0 | I29: 0 | K29: 속도 | L29: FALSE | T29: 2 | U29: =U28 -> 0 | V29: =V28 -> 0 | Y29: =iferror(AVERAGE(W28:W30),0) -> 0 | Z29: 0 | AB29: 속도 | AC29: FALSE
A30: 4 | B30: 8 | C30: 3 | D30: =D28 -> 0 | E30: =E28 -> 0 | I30: 1 | K30: ROM | L30: FALSE | R30: 10 | S30: 15 | T30: 3 | U30: =U28 -> 0 | V30: =V28 -> 0 | Z30: 1 | AB30: ROM | AC30: FALSE
A31: 라트익 | C31: 1 | D31: 0 | E31: 0 | H31: =iferror(C33*D33*(F31+F32+F33),0) -> 0 | I31: 2 | J31: 60 | K31: 자세 | L31: FALSE | R31: 케이블 푸쉬다운 | T31: 1 | U31: 0 | V31: 0 | Y31: =iferror(T33*U33*(W31+W32+W33),0) -> 0 | Z31: 2 | AA31: 60 | AB31: 자세 | AC31: FALSE
C32: 2 | D32: =D31 -> 0 | E32: =E31 -> 0 | H32: =iferror(AVERAGE(F31:F33),0) -> 0 | I32: 0 | K32: 속도 | L32: FALSE | T32: 2 | U32: =U31 -> 0 | V32: =V31 -> 0 | Y32: =iferror(AVERAGE(W31:W33),0) -> 0 | Z32: 0 | AB32: 속도 | AC32: FALSE
A33: 4 | B33: 8 | C33: 3 | D33: =D31 -> 0 | E33: =E31 -> 0 | I33: 1 | K33: ROM | L33: FALSE | R33: 10 | S33: 15 | T33: 3 | U33: =U31 -> 0 | V33: =V31 -> 0 | Z33: 1 | AB33: ROM | AC33: FALSE
A34: 추가 팔운동1 | C34: 1 | D34: 0 | E34: 0 | H34: =iferror(C36*D36*(F34+F35+F36),0) -> 0 | I34: 2 | J34: 60 | K34: 자세 | L34: FALSE | R34: 추가 팔운동1 | T34: 1 | U34: 0 | V34: 0 | Y34: =iferror(T36*U36*(W34+W35+W36),0) -> 0 | Z34: 2 | AA34: 60 | AB34: 자세 | AC34: FALSE
C35: 2 | D35: =D34 -> 0 | E35: =E34 -> 0 | H35: =iferror(AVERAGE(F34:F36),0) -> 0 | I35: 0 | K35: 속도 | L35: FALSE | T35: 2 | U35: =U34 -> 0 | V35: =V34 -> 0 | Y35: =iferror(AVERAGE(W34:W36),0) -> 0 | Z35: 0 | AB35: 속도 | AC35: FALSE
A36: 4 | B36: 8 | C36: 3 | D36: =D34 -> 0 | E36: =E34 -> 0 | I36: 1 | K36: ROM | L36: FALSE | R36: 10 | S36: 15 | T36: 3 | U36: =U34 -> 0 | V36: =V34 -> 0 | Z36: 1 | AB36: ROM | AC36: FALSE
A37: 추가 팔운동 2 | C37: 1 | D37: 0 | E37: 0 | H37: =iferror(C39*D39*(F37+F38+F39),0) -> 0 | I37: 2 | J37: 60 | K37: 자세 | L37: FALSE | R37: 추가 팔운동 2 | T37: 1 | U37: 0 | V37: 0 | Y37: =iferror(T39*U39*(W37+W38+W39),0) -> 0 | Z37: 2 | AA37: 60 | AB37: 자세 | AC37: FALSE
C38: 2 | D38: =D37 -> 0 | E38: =E37 -> 0 | H38: =iferror(AVERAGE(F37:F39),0) -> 0 | I38: 0 | K38: 속도 | L38: FALSE | T38: 2 | U38: =U37 -> 0 | V38: =V37 -> 0 | Y38: =iferror(AVERAGE(W37:W39),0) -> 0 | Z38: 0 | AB38: 속도 | AC38: FALSE
A39: 4 | B39: 8 | C39: 3 | D39: =D37 -> 0 | E39: =E37 -> 0 | I39: 1 | K39: ROM | L39: FALSE | R39: 10 | S39: 15 | T39: 3 | U39: =U37 -> 0 | V39: =V37 -> 0 | Z39: 1 | AB39: ROM | AC39: FALSE
A40: 수업 코멘트 | R40: 수업 코멘트

Sheet 2분할AB 프로그램(9~12주차) 하체
A1: 2분할 하체 A | C1: 특이사항 | E1: *작성 팁* 수업 전 체크해야할 회원님의 특이사항 / 해당 프로그램 사용 시 달성 목표를 기입 | R1: 2분할 하체 B | T1: 특이사항 | V1: *작성 팁* 수업 전 체크해야할 회원님의 특이사항 / 해당 프로그램 사용 시 달성 목표를 기입
A2: 운동명/반복구간 | C2: 세트 | D2: 중량 | E2: 목표 | F2: 성공 | G2: RPE | H2: V/A | I2: 속도 | J2: 휴식 | K2: 체크리스트 | M2: 메모 | R2: 운동명/반복구간 | T2: 세트 | U2: 중량 | V2: 목표 | W2: 성공 | X2: RPE | Y2: V/A | Z2: 속도 | AA2: 휴식 | AB2: 체크리스트 | AD2: 메모
A3: 날짜 | B3: 46027 | C3: 당일 컨디션 | E3: 최상 | F3: FALSE | G3: 상 | H3: FALSE | I3: 중 | J3: FALSE | K3: 하 | L3: FALSE | M3: 수업 | N3: FALSE | O3: 과제 | P3: FALSE | R3: 날짜 | S3: 46027 | T3: 당일 컨디션 | V3: 최상 | W3: FALSE | X3: 상 | Y3: FALSE | Z3: 중 | AA3: FALSE | AB3: 하 | AC3: FALSE | AD3: 수업 | AE3: FALSE | AF3: 과제 | AG3: FALSE
A4: 스쿼트 | C4: 1 | D4: 0 | E4: 0 | H4: =iferror(C6*D6*(F4+F5+F6),0) -> 0 | I4: 2 | J4: 120 | K4: 자세 | L4: FALSE | M4: 줄 바꿈 = alt + enter | R4: 스쿼트 | T4: 1 | U4: 0 | V4: 0 | Y4: =iferror(T6*U6*(W4+W5+W6),0) -> 0 | Z4: 2 | AA4: 90 | AB4: 자세 | AC4: FALSE | AD4: 줄 바꿈 = alt + enter
C5: 2 | D5: =D4 -> 0 | E5: =E4 -> 0 | H5: =iferror(AVERAGE(F4:F6),0) -> 0 | I5: 1 | K5: 속도 | L5: FALSE | T5: 2 | U5: =U4 -> 0 | V5: =V4 -> 0 | Y5: =iferror(AVERAGE(W4:W6),0) -> 0 | Z5: 1 | AB5: 속도 | AC5: FALSE
A6: 2 | B6: 5 | C6: 3 | D6: =D4 -> 0 | E6: =E4 -> 0 | I6: 2 | K6: ROM | L6: FALSE | R6: 6 | S6: 10 | T6: 3 | U6: =U4 -> 0 | V6: =V4 -> 0 | Z6: 2 | AB6: ROM | AC6: FALSE
A7: 스미스머신 런지 | C7: 1 | D7: 0 | E7: 0 | H7: =iferror(C9*D9*(F7+F8+F9),0) -> 0 | I7: 2 | J7: 90 | K7: 자세 | L7: FALSE | R7: 레그 프레스 | T7: 1 | U7: 0 | V7: 0 | Y7: =iferror(T9*U9*(W7+W8+W9),0) -> 0 | Z7: 2 | AA7: 60 | AB7: 자세 | AC7: FALSE
C8: 2 | D8: =D7 -> 0 | E8: =E7 -> 0 | H8: =iferror(AVERAGE(F7:F9),0) -> 0 | I8: 0 | K8: 속도 | L8: FALSE | T8: 2 | U8: =U7 -> 0 | V8: =V7 -> 0 | Y8: =iferror(AVERAGE(W7:W9),0) -> 0 | Z8: 0 | AB8: 속도 | AC8: FALSE
A9: 6 | B9: 10 | C9: 3 | D9: =D7 -> 0 | E9: =E7 -> 0 | I9: 1 | K9: ROM | L9: FALSE | R9: 8 | S9: 12 | T9: 3 | U9: =U7 -> 0 | V9: =V7 -> 0 | Z9: 1 | AB9: ROM | AC9: FALSE
A10: 레그 프레스 | C10: 1 | D10: 0 | E10: 0 | H10: =iferror(C12*D12*(F10+F11+F12),0) -> 0 | I10: 2 | J10: 60 | K10: 자세 | L10: FALSE | R10: 루마니안 데드리프트 | T10: 1 | U10: 0 | V10: 0 | Y10: =iferror(T12*U12*(W10+W11+W12),0) -> 0 | Z10: 2 | AA10: 60 | AB10: 자세 | AC10: FALSE
C11: 2 | D11: =D10 -> 0 | E11: =E10 -> 0 | H11: =iferror(AVERAGE(F10:F12),0) -> 0 | I11: 0 | K11: 속도 | L11: FALSE | T11: 2 | U11: =U10 -> 0 | V11: =V10 -> 0 | Y11: =iferror(AVERAGE(W10:W12),0) -> 0 | Z11: 0 | AB11: 속도 | AC11: FALSE
A12: 6 | B12: 10 | C12: 3 | D12: =D10 -> 0 | E12: =E10 -> 0 | I12: 1 | K12: ROM | L12: FALSE | R12: 8 | S12: 12 | T12: 3 | U12: =U10 -> 0 | V12: =V10 -> 0 | Z12: 1 | AB12: ROM | AC12: FALSE
A13: 레그 익스텐션 | C13: 1 | D13: 0 | E13: 0 | H13: =iferror(C15*D15*(F13+F14+F15),0) -> 0 | I13: 2 | J13: 60 | K13: 자세 | L13: FALSE | R13: 레그 익스텐션 | T13: 1 | U13: 0 | V13: 0 | Y13: =iferror(T15*U15*(W13+W14+W15),0) -> 0 | Z13: 2 | AA13: 60 | AB13: 자세 | AC13: FALSE
C14: 2 | D14: =D13 -> 0 | E14: =E13 -> 0 | H14: =iferror(AVERAGE(F13:F15),0) -> 0 | I14: 1 | K14: 속도 | L14: FALSE | T14: 2 | U14: =U13 -> 0 | V14: =V13 -> 0 | Y14: =iferror(AVERAGE(W13:W15),0) -> 0 | Z14: 1 | AB14: 속도 | AC14: FALSE
A15: 10 | B15: 15 | C15: 3 | D15: =D13 -> 0 | E15: =E13 -> 0 | I15: 1 | K15: ROM | L15: FALSE | R15: 12 | S15: 20 | T15: 3 | U15: =U13 -> 0 | V15: =V13 -> 0 | Z15: 1 | AB15: ROM | AC15: FALSE
A16: 레그컬 | C16: 1 | D16: 0 | E16: 0 | H16: =iferror(C18*D18*(F16+F17+F18),0) -> 0 | I16: 2 | J16: 60 | K16: 자세 | L16: FALSE | R16: 레그컬 | T16: 1 | U16: 0 | V16: 0 | Y16: =iferror(T18*U18*(W16+W17+W18),0) -> 0 | Z16: 2 | AA16: 60 | AB16: 자세 | AC16: FALSE
C17: 2 | D17: =D16 -> 0 | E17: =E16 -> 0 | H17: =iferror(AVERAGE(F16:F18),0) -> 0 | I17: 0 | K17: 속도 | L17: FALSE | T17: 2 | U17: =U16 -> 0 | V17: =V16 -> 0 | Y17: =iferror(AVERAGE(W16:W18),0) -> 0 | Z17: 0 | AB17: 속도 | AC17: FALSE
A18: 10 | B18: 15 | C18: 3 | D18: =D16 -> 0 | E18: =E16 -> 0 | I18: 1 | K18: ROM | L18: FALSE | R18: 12 | S18: 20 | T18: 3 | U18: =U16 -> 0 | V18: =V16 -> 0 | Z18: 1 | AB18: ROM | AC18: FALSE
C19: 1 | D19: 0 | E19: 0 | H19: =iferror(C21*D21*(F19+F20+F21),0) -> 0 | K19: 자세 | L19: FALSE | T19: 1 | U19: 0 | V19: 0 | Y19: =iferror(T21*U21*(W19+W20+W21),0) -> 0 | AB19: 자세 | AC19: FALSE
C20: 2 | D20: =D19 -> 0 | E20: =E19 -> 0 | H20: =iferror(AVERAGE(F19:F21),0) -> 0 | K20: 속도 | L20: FALSE | T20: 2 | U20: =U19 -> 0 | V20: =V19 -> 0 | Y20: =iferror(AVERAGE(W19:W21),0) -> 0 | AB20: 속도 | AC20: FALSE
C21: 3 | D21: =D19 -> 0 | E21: =E19 -> 0 | K21: ROM | L21: FALSE | T21: 3 | U21: =U19 -> 0 | V21: =V19 -> 0 | AB21: ROM | AC21: FALSE
A22: 밀리터리 프레스 | C22: 1 | D22: 0 | E22: 0 | H22: =iferror(C24*D24*(F22+F23+F24),0) -> 0 | I22: 2 | J22: 60 | K22: 자세 | L22: FALSE | R22: 덤벨 숄더 프레스 | T22: 1 | U22: 0 | V22: 0 | Y22: =iferror(T24*U24*(W22+W23+W24),0) -> 0 | Z22: 2 | AA22: 60 | AB22: 자세 | AC22: FALSE
C23: 2 | D23: =D22 -> 0 | E23: =E22 -> 0 | H23: =iferror(AVERAGE(F22:F24),0) -> 0 | I23: 0 | K23: 속도 | L23: FALSE | T23: 2 | U23: =U22 -> 0 | V23: =V22 -> 0 | Y23: =iferror(AVERAGE(W22:W24),0) -> 0 | Z23: 0 | AB23: 속도 | AC23: FALSE
A24: 2 | B24: 5 | C24: 3 | D24: =D22 -> 0 | E24: =E22 -> 0 | I24: 1 | K24: ROM | L24: FALSE | R24: 6 | S24: 10 | T24: 3 | U24: =U22 -> 0 | V24: =V22 -> 0 | Z24: 1 | AB24: ROM | AC24: FALSE
A25: 레터럴 레이즈 | C25: 1 | D25: 0 | E25: 0 | H25: =iferror(C27*D27*(F25+F26+F27),0) -> 0 | I25: 2 | J25: 60 | K25: 자세 | L25: FALSE | R25: 원암레터럴 레이즈 | T25: 1 | U25: 0 | V25: 0 | Y25: =iferror(T27*U27*(W25+W26+W27),0) -> 0 | Z25: 2 | AA25: 60 | AB25: 자세 | AC25: FALSE
C26: 2 | D26: =D25 -> 0 | E26: =E25 -> 0 | H26: =iferror(AVERAGE(F25:F27),0) -> 0 | I26: 0 | K26: 속도 | L26: FALSE | T26: 2 | U26: =U25 -> 0 | V26: =V25 -> 0 | Y26: =iferror(AVERAGE(W25:W27),0) -> 0 | Z26: 0 | AB26: 속도 | AC26: FALSE
A27: 8 | B27: 12 | C27: 3 | D27: =D25 -> 0 | E27: =E25 -> 0 | I27: 1 | K27: ROM | L27: FALSE | R27: 12 | S27: 20 | T27: 3 | U27: =U25 -> 0 | V27: =V25 -> 0 | Z27: 1 | AB27: ROM | AC27: FALSE
A28: 벤트오버 레터럴 레이즈 | C28: 1 | D28: 0 | E28: 0 | H28: =iferror(C30*D30*(F28+F29+F30),0) -> 0 | I28: 2 | J28: 60 | K28: 자세 | L28: FALSE | R28: 벤트오버 레터럴 레이즈 | T28: 1 | U28: 0 | V28: 0 | Y28: =iferror(T30*U30*(W28+W29+W30),0) -> 0 | Z28: 2 | AA28: 60 | AB28: 자세 | AC28: FALSE
C29: 2 | D29: =D28 -> 0 | E29: =E28 -> 0 | H29: =iferror(AVERAGE(F28:F30),0) -> 0 | I29: 0 | K29: 속도 | L29: FALSE | T29: 2 | U29: =U28 -> 0 | V29: =V28 -> 0 | Y29: =iferror(AVERAGE(W28:W30),0) -> 0 | Z29: 0 | AB29: 속도 | AC29: FALSE
A30: 8 | B30: 12 | C30: 3 | D30: =D28 -> 0 | E30: =E28 -> 0 | I30: 1 | K30: ROM | L30: FALSE | R30: 12 | S30: 20 | T30: 3 | U30: =U28 -> 0 | V30: =V28 -> 0 | Z30: 1 | AB30: ROM | AC30: FALSE
C31: 1 | D31: 0 | E31: 0 | H31: =iferror(C33*D33*(F31+F32+F33),0) -> 0 | K31: 자세 | L31: FALSE | T31: 1 | U31: 0 | V31: 0 | Y31: =iferror(T33*U33*(W31+W32+W33),0) -> 0 | AB31: 자세 | AC31: FALSE
C32: 2 | D32: =D31 -> 0 | E32: =E31 -> 0 | H32: =iferror(AVERAGE(F31:F33),0) -> 0 | K32: 속도 | L32: FALSE | T32: 2 | U32: =U31 -> 0 | V32: =V31 -> 0 | Y32: =iferror(AVERAGE(W31:W33),0) -> 0 | AB32: 속도 | AC32: FALSE
C33: 3 | D33: =D31 -> 0 | E33: =E31 -> 0 | K33: ROM | L33: FALSE | T33: 3 | U33: =U31 -> 0 | V33: =V31 -> 0 | AB33: ROM | AC33: FALSE
C34: 1 | D34: 0 | E34: 0 | H34: =iferror(C36*D36*(F34+F35+F36),0) -> 0 | K34: 자세 | L34: FALSE | T34: 1 | U34: 0 | V34: 0 | Y34: =iferror(T36*U36*(W34+W35+W36),0) -> 0 | AB34: 자세 | AC34: FALSE
C35: 2 | D35: =D34 -> 0 | E35: =E34 -> 0 | H35: =iferror(AVERAGE(F34:F36),0) -> 0 | K35: 속도 | L35: FALSE | T35: 2 | U35: =U34 -> 0 | V35: =V34 -> 0 | Y35: =iferror(AVERAGE(W34:W36),0) -> 0 | AB35: 속도 | AC35: FALSE
C36: 3 | D36: =D34 -> 0 | E36: =E34 -> 0 | K36: ROM | L36: FALSE | T36: 3 | U36: =U34 -> 0 | V36: =V34 -> 0 | AB36: ROM | AC36: FALSE
C37: 1 | D37: 0 | E37: 0 | H37: =iferror(C39*D39*(F37+F38+F39),0) -> 0 | K37: 자세 | L37: FALSE | T37: 1 | U37: 0 | V37: 0 | Y37: =iferror(T39*U39*(W37+W38+W39),0) -> 0 | AB37: 자세 | AC37: FALSE
C38: 2 | D38: =D37 -> 0 | E38: =E37 -> 0 | H38: =iferror(AVERAGE(F37:F39),0) -> 0 | K38: 속도 | L38: FALSE | T38: 2 | U38: =U37 -> 0 | V38: =V37 -> 0 | Y38: =iferror(AVERAGE(W37:W39),0) -> 0 | AB38: 속도 | AC38: FALSE
C39: 3 | D39: =D37 -> 0 | E39: =E37 -> 0 | K39: ROM | L39: FALSE | T39: 3 | U39: =U37 -> 0 | V39: =V37 -> 0 | AB39: ROM | AC39: FALSE
A40: 수업 코멘트 | R40: 수업 코멘트

Sheet 3분할 프로그램(밀기)
A1: 3분할 밀기 A | C1: 특이사항 | E1: *작성 팁* 수업 전 체크해야할 회원님의 특이사항 / 해당 프로그램 사용 시 달성 목표를 기입 | R1: 3분할 밀기 B | T1: 특이사항 | V1: *작성 팁* 수업 전 체크해야할 회원님의 특이사항 / 해당 프로그램 사용 시 달성 목표를 기입
A2: 운동명/반복구간 | C2: 세트 | D2: 중량 | E2: 목표 | F2: 성공 | G2: RPE | H2: V/A | I2: 속도 | J2: 휴식 | K2: 체크리스트 | M2: 메모 | R2: 운동명/반복구간 | T2: 세트 | U2: 중량 | V2: 목표 | W2: 성공 | X2: RPE | Y2: V/A | Z2: 속도 | AA2: 휴식 | AB2: 체크리스트 | AD2: 메모
A3: 날짜 | B3: 46027 | C3: 당일 컨디션 | E3: 최상 | F3: FALSE | G3: 상 | H3: FALSE | I3: 중 | J3: FALSE | K3: 하 | L3: FALSE | M3: 수업 | N3: FALSE | O3: 과제 | P3: FALSE | R3: 날짜 | S3: 46027 | T3: 당일 컨디션 | V3: 최상 | W3: FALSE | X3: 상 | Y3: FALSE | Z3: 중 | AA3: FALSE | AB3: 하 | AC3: FALSE | AD3: 수업 | AE3: FALSE | AF3: 과제 | AG3: FALSE
A4: 벤치프레스 | C4: 1 | D4: 0 | E4: 0 | H4: =iferror(C6*D6*(F4+F5+F6),0) -> 0 | I4: 2 | J4: 90 | K4: 자세 | L4: FALSE | M4: 줄 바꿈 = alt + enter | R4: 인클라인 벤치프레스 | T4: 1 | U4: 0 | V4: 0 | Y4: =iferror(T6*U6*(W4+W5+W6),0) -> 0 | Z4: 2 | AA4: 60 | AB4: 자세 | AC4: FALSE | AD4: 줄 바꿈 = alt + enter
C5: 2 | D5: =D4 -> 0 | E5: =E4 -> 0 | H5: =iferror(AVERAGE(F4:F6),0) -> 0 | I5: 0 | K5: 속도 | L5: FALSE | T5: 2 | U5: =U4 -> 0 | V5: =V4 -> 0 | Y5: =iferror(AVERAGE(W4:W6),0) -> 0 | Z5: 0 | AB5: 속도 | AC5: FALSE
A6: 2 | B6: 5 | C6: 3 | D6: =D4 -> 0 | E6: =E4 -> 0 | I6: 1 | K6: ROM | L6: FALSE | R6: 6 | S6: 10 | T6: 3 | U6: =U4 -> 0 | V6: =V4 -> 0 | Z6: 1 | AB6: ROM | AC6: FALSE
A7: 딥스 | C7: 1 | D7: 0 | E7: 0 | H7: =iferror(C9*D9*(F7+F8+F9),0) -> 0 | I7: 2 | J7: 60 | K7: 자세 | L7: FALSE | R7: 덤벨프레스 | T7: 1 | U7: 0 | V7: 0 | Y7: =iferror(T9*U9*(W7+W8+W9),0) -> 0 | Z7: 2 | AA7: 60 | AB7: 자세 | AC7: FALSE
C8: 2 | D8: =D7 -> 0 | E8: =E7 -> 0 | H8: =iferror(AVERAGE(F7:F9),0) -> 0 | I8: 0 | K8: 속도 | L8: FALSE | T8: 2 | U8: =U7 -> 0 | V8: =V7 -> 0 | Y8: =iferror(AVERAGE(W7:W9),0) -> 0 | Z8: 0 | AB8: 속도 | AC8: FALSE
A9: 6 | B9: 10 | C9: 3 | D9: =D7 -> 0 | E9: =E7 -> 0 | I9: 1 | K9: ROM | L9: FALSE | R9: 8 | S9: 12 | T9: 3 | U9: =U7 -> 0 | V9: =V7 -> 0 | Z9: 1 | AB9: ROM | AC9: FALSE
A10: 스미스 머신 벤치프레스(체스트프레스) | C10: 1 | D10: 0 | E10: 0 | H10: =iferror(C12*D12*(F10+F11+F12),0) -> 0 | I10: 2 | J10: 60 | K10: 자세 | L10: FALSE | R10: 스미스 머신 벤치프레스(체스트프레스) | T10: 1 | U10: 0 | V10: 0 | Y10: =iferror(T12*U12*(W10+W11+W12),0) -> 0 | Z10: 2 | AA10: 60 | AB10: 자세 | AC10: FALSE
C11: 2 | D11: =D10 -> 0 | E11: =E10 -> 0 | H11: =iferror(AVERAGE(F10:F12),0) -> 0 | I11: 1 | K11: 속도 | L11: FALSE | T11: 2 | U11: =U10 -> 0 | V11: =V10 -> 0 | Y11: =iferror(AVERAGE(W10:W12),0) -> 0 | Z11: 1 | AB11: 속도 | AC11: FALSE
A12: 8 | B12: 12 | C12: 3 | D12: =D10 -> 0 | E12: =E10 -> 0 | I12: 1 | K12: ROM | L12: FALSE | R12: 8 | S12: 12 | T12: 3 | U12: =U10 -> 0 | V12: =V10 -> 0 | Z12: 1 | AB12: ROM | AC12: FALSE
A13: 덤벨 플라이 | C13: 1 | D13: 0 | E13: 0 | H13: =iferror(C15*D15*(F13+F14+F15),0) -> 0 | I13: 2 | J13: 60 | K13: 자세 | L13: FALSE | R13: 케이블 크로스 오버 | T13: 1 | U13: 0 | V13: 0 | Y13: =iferror(T15*U15*(W13+W14+W15),0) -> 0 | Z13: 2 | AA13: 60 | AB13: 자세 | AC13: FALSE
C14: 2 | D14: =D13 -> 0 | E14: =E13 -> 0 | H14: =iferror(AVERAGE(F13:F15),0) -> 0 | I14: 1 | K14: 속도 | L14: FALSE | T14: 2 | U14: =U13 -> 0 | V14: =V13 -> 0 | Y14: =iferror(AVERAGE(W13:W15),0) -> 0 | Z14: 1 | AB14: 속도 | AC14: FALSE
A15: 10 | B15: 15 | C15: 3 | D15: =D13 -> 0 | E15: =E13 -> 0 | I15: 1 | K15: ROM | L15: FALSE | R15: 12 | S15: 20 | T15: 3 | U15: =U13 -> 0 | V15: =V13 -> 0 | Z15: 1 | AB15: ROM | AC15: FALSE
A16: 추가 가슴운동2 | C16: 1 | D16: 0 | E16: 0 | H16: =iferror(C18*D18*(F16+F17+F18),0) -> 0 | I16: 2 | J16: 60 | K16: 자세 | L16: FALSE | R16: 추가 가슴운동2 | T16: 1 | U16: 0 | V16: 0 | Y16: =iferror(T18*U18*(W16+W17+W18),0) -> 0 | Z16: 2 | AA16: 60 | AB16: 자세 | AC16: FALSE
C17: 2 | D17: =D16 -> 0 | E17: =E16 -> 0 | H17: =iferror(AVERAGE(F16:F18),0) -> 0 | I17: 1 | K17: 속도 | L17: FALSE | T17: 2 | U17: =U16 -> 0 | V17: =V16 -> 0 | Y17: =iferror(AVERAGE(W16:W18),0) -> 0 | Z17: 1 | AB17: 속도 | AC17: FALSE
A18: - | B18: - | C18: 3 | D18: =D16 -> 0 | E18: =E16 -> 0 | I18: 1 | K18: ROM | L18: FALSE | R18: - | S18: - | T18: 3 | U18: =U16 -> 0 | V18: =V16 -> 0 | Z18: 1 | AB18: ROM | AC18: FALSE
A19: 추가 가슴운동2 | C19: 1 | D19: 0 | E19: 0 | H19: =iferror(C21*D21*(F19+F20+F21),0) -> 0 | I19: 2 | J19: 60 | K19: 자세 | L19: FALSE | R19: 추가 가슴운동2 | T19: 1 | U19: 0 | V19: 0 | Y19: =iferror(T21*U21*(W19+W20+W21),0) -> 0 | Z19: 2 | AA19: 60 | AB19: 자세 | AC19: FALSE
C20: 2 | D20: =D19 -> 0 | E20: =E19 -> 0 | H20: =iferror(AVERAGE(F19:F21),0) -> 0 | I20: 0 | K20: 속도 | L20: FALSE | T20: 2 | U20: =U19 -> 0 | V20: =V19 -> 0 | Y20: =iferror(AVERAGE(W19:W21),0) -> 0 | Z20: 0 | AB20: 속도 | AC20: FALSE
A21: - | B21: - | C21: 3 | D21: =D19 -> 0 | E21: =E19 -> 0 | I21: 1 | K21: ROM | L21: FALSE | R21: - | S21: - | T21: 3 | U21: =U19 -> 0 | V21: =V19 -> 0 | Z21: 1 | AB21: ROM | AC21: FALSE
A22: 라트익 | C22: 1 | D22: 0 | E22: 0 | H22: =iferror(C24*D24*(F22+F23+F24),0) -> 0 | I22: 2 | J22: 60 | K22: 자세 | L22: FALSE | R22: 라트익 | T22: 1 | U22: 0 | V22: 0 | Y22: =iferror(T24*U24*(W22+W23+W24),0) -> 0 | Z22: 2 | AA22: 60 | AB22: 자세 | AC22: FALSE
C23: 2 | D23: =D22 -> 0 | E23: =E22 -> 0 | H23: =iferror(AVERAGE(F22:F24),0) -> 0 | I23: 0 | K23: 속도 | L23: FALSE | T23: 2 | U23: =U22 -> 0 | V23: =V22 -> 0 | Y23: =iferror(AVERAGE(W22:W24),0) -> 0 | Z23: 0 | AB23: 속도 | AC23: FALSE
A24: 6 | B24: 10 | C24: 3 | D24: =D22 -> 0 | E24: =E22 -> 0 | I24: 1 | K24: ROM | L24: FALSE | R24: 10 | S24: 15 | T24: 3 | U24: =U22 -> 0 | V24: =V22 -> 0 | Z24: 1 | AB24: ROM | AC24: FALSE
A25: 푸쉬다운 | C25: 1 | D25: 0 | E25: 0 | H25: =iferror(C27*D27*(F25+F26+F27),0) -> 0 | I25: 2 | J25: 60 | K25: 자세 | L25: FALSE | R25: 케이블 로프다운 | T25: 1 | U25: 0 | V25: 0 | Y25: =iferror(T27*U27*(W25+W26+W27),0) -> 0 | Z25: 2 | AA25: 60 | AB25: 자세 | AC25: FALSE
C26: 2 | D26: =D25 -> 0 | E26: =E25 -> 0 | H26: =iferror(AVERAGE(F25:F27),0) -> 0 | I26: 0 | K26: 속도 | L26: FALSE | T26: 2 | U26: =U25 -> 0 | V26: =V25 -> 0 | Y26: =iferror(AVERAGE(W25:W27),0) -> 0 | Z26: 0 | AB26: 속도 | AC26: FALSE
A27: 6 | B27: 10 | C27: 3 | D27: =D25 -> 0 | E27: =E25 -> 0 | I27: 1 | K27: ROM | L27: FALSE | R27: 10 | S27: 15 | T27: 3 | U27: =U25 -> 0 | V27: =V25 -> 0 | Z27: 1 | AB27: ROM | AC27: FALSE
A28: 추가 팔운동1 | C28: 1 | D28: 0 | E28: 0 | H28: =iferror(C30*D30*(F28+F29+F30),0) -> 0 | I28: 2 | J28: 60 | K28: 자세 | L28: FALSE | R28: 추가 팔운동1 | T28: 1 | U28: 0 | V28: 0 | Y28: =iferror(T30*U30*(W28+W29+W30),0) -> 0 | Z28: 2 | AA28: 60 | AB28: 자세 | AC28: FALSE
C29: 2 | D29: =D28 -> 0 | E29: =E28 -> 0 | H29: =iferror(AVERAGE(F28:F30),0) -> 0 | I29: 0 | K29: 속도 | L29: FALSE | T29: 2 | U29: =U28 -> 0 | V29: =V28 -> 0 | Y29: =iferror(AVERAGE(W28:W30),0) -> 0 | Z29: 0 | AB29: 속도 | AC29: FALSE
C30: 3 | D30: =D28 -> 0 | E30: =E28 -> 0 | I30: 1 | K30: ROM | L30: FALSE | T30: 3 | U30: =U28 -> 0 | V30: =V28 -> 0 | Z30: 1 | AB30: ROM | AC30: FALSE
C31: 1 | D31: 0 | E31: 0 | H31: =iferror(C33*D33*(F31+F32+F33),0) -> 0 | K31: 자세 | L31: FALSE | T31: 1 | U31: 0 | V31: 0 | Y31: =iferror(T33*U33*(W31+W32+W33),0) -> 0 | AB31: 자세 | AC31: FALSE
C32: 2 | D32: =D31 -> 0 | E32: =E31 -> 0 | H32: =iferror(AVERAGE(F31:F33),0) -> 0 | K32: 속도 | L32: FALSE | T32: 2 | U32: =U31 -> 0 | V32: =V31 -> 0 | Y32: =iferror(AVERAGE(W31:W33),0) -> 0 | AB32: 속도 | AC32: FALSE
C33: 3 | D33: =D31 -> 0 | E33: =E31 -> 0 | K33: ROM | L33: FALSE | T33: 3 | U33: =U31 -> 0 | V33: =V31 -> 0 | AB33: ROM | AC33: FALSE
C34: 1 | D34: 0 | E34: 0 | H34: =iferror(C36*D36*(F34+F35+F36),0) -> 0 | K34: 자세 | L34: FALSE | T34: 1 | U34: 0 | V34: 0 | Y34: =iferror(T36*U36*(W34+W35+W36),0) -> 0 | AB34: 자세 | AC34: FALSE
C35: 2 | D35: =D34 -> 0 | E35: =E34 -> 0 | H35: =iferror(AVERAGE(F34:F36),0) -> 0 | K35: 속도 | L35: FALSE | T35: 2 | U35: =U34 -> 0 | V35: =V34 -> 0 | Y35: =iferror(AVERAGE(W34:W36),0) -> 0 | AB35: 속도 | AC35: FALSE
C36: 3 | D36: =D34 -> 0 | E36: =E34 -> 0 | K36: ROM | L36: FALSE | T36: 3 | U36: =U34 -> 0 | V36: =V34 -> 0 | AB36: ROM | AC36: FALSE
C37: 1 | D37: 0 | E37: 0 | H37: =iferror(C39*D39*(F37+F38+F39),0) -> 0 | K37: 자세 | L37: FALSE | T37: 1 | U37: 0 | V37: 0 | Y37: =iferror(T39*U39*(W37+W38+W39),0) -> 0 | AB37: 자세 | AC37: FALSE
C38: 2 | D38: =D37 -> 0 | E38: =E37 -> 0 | H38: =iferror(AVERAGE(F37:F39),0) -> 0 | K38: 속도 | L38: FALSE | T38: 2 | U38: =U37 -> 0 | V38: =V37 -> 0 | Y38: =iferror(AVERAGE(W37:W39),0) -> 0 | AB38: 속도 | AC38: FALSE
C39: 3 | D39: =D37 -> 0 | E39: =E37 -> 0 | K39: ROM | L39: FALSE | T39: 3 | U39: =U37 -> 0 | V39: =V37 -> 0 | AB39: ROM | AC39: FALSE
A40: 수업 코멘트 | R40: 수업 코멘트

Sheet 3분할 프로그램(당기기)
A1: 3분할 당기기 A | C1: 특이사항 | E1: *작성 팁* 수업 전 체크해야할 회원님의 특이사항 / 해당 프로그램 사용 시 달성 목표를 기입 | R1: 3분할 당기기 B | T1: 특이사항 | V1: *작성 팁* 수업 전 체크해야할 회원님의 특이사항 / 해당 프로그램 사용 시 달성 목표를 기입
A2: 운동명/반복구간 | C2: 세트 | D2: 중량 | E2: 목표 | F2: 성공 | G2: RPE | H2: V/A | I2: 속도 | J2: 휴식 | K2: 체크리스트 | M2: 메모 | R2: 운동명/반복구간 | T2: 세트 | U2: 중량 | V2: 목표 | W2: 성공 | X2: RPE | Y2: V/A | Z2: 속도 | AA2: 휴식 | AB2: 체크리스트 | AD2: 메모
A3: 날짜 | B3: 46027 | C3: 당일 컨디션 | E3: 최상 | F3: FALSE | G3: 상 | H3: FALSE | I3: 중 | J3: FALSE | K3: 하 | L3: FALSE | M3: 수업 | N3: FALSE | O3: 과제 | P3: FALSE | R3: 날짜 | S3: 46027 | T3: 당일 컨디션 | V3: 최상 | W3: FALSE | X3: 상 | Y3: FALSE | Z3: 중 | AA3: FALSE | AB3: 하 | AC3: FALSE | AD3: 수업 | AE3: FALSE | AF3: 과제 | AG3: FALSE
A4: 바벨로우 | C4: 1 | D4: 0 | E4: 0 | H4: =iferror(C6*D6*(F4+F5+F6),0) -> 0 | I4: 2 | J4: 90 | K4: 자세 | L4: FALSE | M4: 줄 바꿈 = alt + enter | R4: 원암덤벨로우 | T4: 1 | U4: 0 | V4: 0 | Y4: =iferror(T6*U6*(W4+W5+W6),0) -> 0 | Z4: 2 | AA4: 60 | AB4: 자세 | AC4: FALSE | AD4: 줄 바꿈 = alt + enter
C5: 2 | D5: =D4 -> 0 | E5: =E4 -> 0 | H5: =iferror(AVERAGE(F4:F6),0) -> 0 | I5: 0 | K5: 속도 | L5: FALSE | T5: 2 | U5: =U4 -> 0 | V5: =V4 -> 0 | Y5: =iferror(AVERAGE(W4:W6),0) -> 0 | Z5: 0 | AB5: 속도 | AC5: FALSE
A6: 6 | B6: 10 | C6: 3 | D6: =D4 -> 0 | E6: =E4 -> 0 | I6: 1 | K6: ROM | L6: FALSE | R6: 8 | S6: 12 | T6: 3 | U6: =U4 -> 0 | V6: =V4 -> 0 | Z6: 1 | AB6: ROM | AC6: FALSE
A7: 랫풀다운 | C7: 1 | D7: 0 | E7: 0 | H7: =iferror(C9*D9*(F7+F8+F9),0) -> 0 | I7: 2 | J7: 60 | K7: 자세 | L7: FALSE | R7: 언더그립 랫풀다운 | T7: 1 | U7: 0 | V7: 0 | Y7: =iferror(T9*U9*(W7+W8+W9),0) -> 0 | Z7: 2 | AA7: 60 | AB7: 자세 | AC7: FALSE
C8: 2 | D8: =D7 -> 0 | E8: =E7 -> 0 | H8: =iferror(AVERAGE(F7:F9),0) -> 0 | I8: 0 | K8: 속도 | L8: FALSE | T8: 2 | U8: =U7 -> 0 | V8: =V7 -> 0 | Y8: =iferror(AVERAGE(W7:W9),0) -> 0 | Z8: 0 | AB8: 속도 | AC8: FALSE
A9: 6 | B9: 10 | C9: 3 | D9: =D7 -> 0 | E9: =E7 -> 0 | I9: 1 | K9: ROM | L9: FALSE | R9: 8 | S9: 12 | T9: 3 | U9: =U7 -> 0 | V9: =V7 -> 0 | Z9: 1 | AB9: ROM | AC9: FALSE
A10: 케이블로우 | C10: 1 | D10: 0 | E10: 0 | H10: =iferror(C12*D12*(F10+F11+F12),0) -> 0 | I10: 2 | J10: 60 | K10: 자세 | L10: FALSE | R10: 케이블 로우 | T10: 1 | U10: 0 | V10: 0 | Y10: =iferror(T12*U12*(W10+W11+W12),0) -> 0 | Z10: 2 | AA10: 60 | AB10: 자세 | AC10: FALSE
C11: 2 | D11: =D10 -> 0 | E11: =E10 -> 0 | H11: =iferror(AVERAGE(F10:F12),0) -> 0 | I11: 1 | K11: 속도 | L11: FALSE | T11: 2 | U11: =U10 -> 0 | V11: =V10 -> 0 | Y11: =iferror(AVERAGE(W10:W12),0) -> 0 | Z11: 1 | AB11: 속도 | AC11: FALSE
A12: 8 | B12: 12 | C12: 3 | D12: =D10 -> 0 | E12: =E10 -> 0 | I12: 1 | K12: ROM | L12: FALSE | R12: 8 | S12: 12 | T12: 3 | U12: =U10 -> 0 | V12: =V10 -> 0 | Z12: 1 | AB12: ROM | AC12: FALSE
A13: 암풀다운 | C13: 1 | D13: 0 | E13: 0 | H13: =iferror(C15*D15*(F13+F14+F15),0) -> 0 | I13: 2 | J13: 60 | K13: 자세 | L13: FALSE | R13: 암풀다운 | T13: 1 | U13: 0 | V13: 0 | Y13: =iferror(T15*U15*(W13+W14+W15),0) -> 0 | Z13: 2 | AA13: 60 | AB13: 자세 | AC13: FALSE
C14: 2 | D14: =D13 -> 0 | E14: =E13 -> 0 | H14: =iferror(AVERAGE(F13:F15),0) -> 0 | I14: 1 | K14: 속도 | L14: FALSE | T14: 2 | U14: =U13 -> 0 | V14: =V13 -> 0 | Y14: =iferror(AVERAGE(W13:W15),0) -> 0 | Z14: 1 | AB14: 속도 | AC14: FALSE
A15: 10 | B15: 15 | C15: 3 | D15: =D13 -> 0 | E15: =E13 -> 0 | I15: 1 | K15: ROM | L15: FALSE | R15: 10 | S15: 15 | T15: 3 | U15: =U13 -> 0 | V15: =V13 -> 0 | Z15: 1 | AB15: ROM | AC15: FALSE
A16: 추가 등운동2 | C16: 1 | D16: 0 | E16: 0 | H16: =iferror(C18*D18*(F16+F17+F18),0) -> 0 | I16: 2 | J16: 60 | K16: 자세 | L16: FALSE | R16: 추가 등운동2 | T16: 1 | U16: 0 | V16: 0 | Y16: =iferror(T18*U18*(W16+W17+W18),0) -> 0 | Z16: 2 | AA16: 60 | AB16: 자세 | AC16: FALSE
C17: 2 | D17: =D16 -> 0 | E17: =E16 -> 0 | H17: =iferror(AVERAGE(F16:F18),0) -> 0 | I17: 1 | K17: 속도 | L17: FALSE | T17: 2 | U17: =U16 -> 0 | V17: =V16 -> 0 | Y17: =iferror(AVERAGE(W16:W18),0) -> 0 | Z17: 1 | AB17: 속도 | AC17: FALSE
A18: - | B18: - | C18: 3 | D18: =D16 -> 0 | E18: =E16 -> 0 | I18: 1 | K18: ROM | L18: FALSE | R18: - | S18: - | T18: 3 | U18: =U16 -> 0 | V18: =V16 -> 0 | Z18: 1 | AB18: ROM | AC18: FALSE
A19: 추가 등운동2 | C19: 1 | D19: 0 | E19: 0 | H19: =iferror(C21*D21*(F19+F20+F21),0) -> 0 | I19: 2 | J19: 60 | K19: 자세 | L19: FALSE | R19: 추가 등운동2 | T19: 1 | U19: 0 | V19: 0 | Y19: =iferror(T21*U21*(W19+W20+W21),0) -> 0 | Z19: 2 | AA19: 60 | AB19: 자세 | AC19: FALSE
C20: 2 | D20: =D19 -> 0 | E20: =E19 -> 0 | H20: =iferror(AVERAGE(F19:F21),0) -> 0 | I20: 0 | K20: 속도 | L20: FALSE | T20: 2 | U20: =U19 -> 0 | V20: =V19 -> 0 | Y20: =iferror(AVERAGE(W19:W21),0) -> 0 | Z20: 0 | AB20: 속도 | AC20: FALSE
